2025-02-10 10:22:00,685 ERROR scheduler Exception in Enqueue Events for Site money.test
Traceback (most recent call last):
  File "/Users/saimanikanta/Desktop/ezapp/ez/frappe-bench/apps/frappe/frappe/utils/scheduler.py", line 105, in enqueue_events_for_site
    if is_scheduler_inactive():
       ~~~~~~~~~~~~~~~~~~~~~^^
  File "/Users/saimanikanta/Desktop/ezapp/ez/frappe-bench/apps/frappe/frappe/utils/scheduler.py", line 149, in is_scheduler_inactive
    if is_scheduler_disabled(verbose=verbose):
       ~~~~~~~~~~~~~~~~~~~~~^^^^^^^^^^^^^^^^^
  File "/Users/saimanikanta/Desktop/ezapp/ez/frappe-bench/apps/frappe/frappe/utils/scheduler.py", line 162, in is_scheduler_disabled
    frappe.db.get_single_value("System Settings", "enable_scheduler")
    ~~~~~~~~~~~~~~~~~~~~~~~~~~^^^^^^^^^^^^^^^^^^^^^^^^^^^^^^^^^^^^^^^
  File "/Users/saimanikanta/Desktop/ezapp/ez/frappe-bench/apps/frappe/frappe/database/database.py", line 869, in get_single_value
    ).run()
      ~~~^^
  File "/Users/saimanikanta/Desktop/ezapp/ez/frappe-bench/apps/frappe/frappe/query_builder/utils.py", line 84, in execute_query
    result = frappe.db.sql(query, params, *args, **kwargs)  # nosemgrep
  File "/Users/saimanikanta/Desktop/ezapp/ez/frappe-bench/apps/frappe/frappe/database/database.py", line 215, in sql
    self.connect()
    ~~~~~~~~~~~~^^
  File "/Users/saimanikanta/Desktop/ezapp/ez/frappe-bench/apps/frappe/frappe/database/database.py", line 120, in connect
    self._conn: MariadbConnection | PostgresConnection = self.get_connection()
                                                         ~~~~~~~~~~~~~~~~~~~^^
  File "/Users/saimanikanta/Desktop/ezapp/ez/frappe-bench/apps/frappe/frappe/database/mariadb/database.py", line 107, in get_connection
    conn = self._get_connection()
  File "/Users/saimanikanta/Desktop/ezapp/ez/frappe-bench/apps/frappe/frappe/database/mariadb/database.py", line 113, in _get_connection
    return self.create_connection()
           ~~~~~~~~~~~~~~~~~~~~~~^^
  File "/Users/saimanikanta/Desktop/ezapp/ez/frappe-bench/apps/frappe/frappe/database/mariadb/database.py", line 116, in create_connection
    return pymysql.connect(**self.get_connection_settings())
           ~~~~~~~~~~~~~~~^^^^^^^^^^^^^^^^^^^^^^^^^^^^^^^^^^
  File "/Users/saimanikanta/Desktop/ezapp/ez/frappe-bench/env/lib/python3.13/site-packages/pymysql/connections.py", line 361, in __init__
    self.connect()
    ~~~~~~~~~~~~^^
  File "/Users/saimanikanta/Desktop/ezapp/ez/frappe-bench/env/lib/python3.13/site-packages/pymysql/connections.py", line 669, in connect
    self._request_authentication()
    ~~~~~~~~~~~~~~~~~~~~~~~~~~~~^^
  File "/Users/saimanikanta/Desktop/ezapp/ez/frappe-bench/env/lib/python3.13/site-packages/pymysql/connections.py", line 957, in _request_authentication
    auth_packet = self._read_packet()
  File "/Users/saimanikanta/Desktop/ezapp/ez/frappe-bench/env/lib/python3.13/site-packages/pymysql/connections.py", line 775, in _read_packet
    packet.raise_for_error()
    ~~~~~~~~~~~~~~~~~~~~~~^^
  File "/Users/saimanikanta/Desktop/ezapp/ez/frappe-bench/env/lib/python3.13/site-packages/pymysql/protocol.py", line 219, in raise_for_error
    err.raise_mysql_exception(self._data)
    ~~~~~~~~~~~~~~~~~~~~~~~~~^^^^^^^^^^^^
  File "/Users/saimanikanta/Desktop/ezapp/ez/frappe-bench/env/lib/python3.13/site-packages/pymysql/err.py", line 150, in raise_mysql_exception
    raise errorclass(errno, errval)
pymysql.err.OperationalError: (1044, "Access denied for user '_7c5f4f77b0d74777'@'localhost' to database 'f77b0d74777_7c5f4'")
2025-02-10 10:26:00,686 ERROR scheduler Exception in Enqueue Events for Site money.test
Traceback (most recent call last):
  File "/Users/saimanikanta/Desktop/ezapp/ez/frappe-bench/apps/frappe/frappe/utils/scheduler.py", line 105, in enqueue_events_for_site
    if is_scheduler_inactive():
       ~~~~~~~~~~~~~~~~~~~~~^^
  File "/Users/saimanikanta/Desktop/ezapp/ez/frappe-bench/apps/frappe/frappe/utils/scheduler.py", line 149, in is_scheduler_inactive
    if is_scheduler_disabled(verbose=verbose):
       ~~~~~~~~~~~~~~~~~~~~~^^^^^^^^^^^^^^^^^
  File "/Users/saimanikanta/Desktop/ezapp/ez/frappe-bench/apps/frappe/frappe/utils/scheduler.py", line 162, in is_scheduler_disabled
    frappe.db.get_single_value("System Settings", "enable_scheduler")
    ~~~~~~~~~~~~~~~~~~~~~~~~~~^^^^^^^^^^^^^^^^^^^^^^^^^^^^^^^^^^^^^^^
  File "/Users/saimanikanta/Desktop/ezapp/ez/frappe-bench/apps/frappe/frappe/database/database.py", line 869, in get_single_value
    ).run()
      ~~~^^
  File "/Users/saimanikanta/Desktop/ezapp/ez/frappe-bench/apps/frappe/frappe/query_builder/utils.py", line 84, in execute_query
    result = frappe.db.sql(query, params, *args, **kwargs)  # nosemgrep
  File "/Users/saimanikanta/Desktop/ezapp/ez/frappe-bench/apps/frappe/frappe/database/database.py", line 215, in sql
    self.connect()
    ~~~~~~~~~~~~^^
  File "/Users/saimanikanta/Desktop/ezapp/ez/frappe-bench/apps/frappe/frappe/database/database.py", line 120, in connect
    self._conn: MariadbConnection | PostgresConnection = self.get_connection()
                                                         ~~~~~~~~~~~~~~~~~~~^^
  File "/Users/saimanikanta/Desktop/ezapp/ez/frappe-bench/apps/frappe/frappe/database/mariadb/database.py", line 107, in get_connection
    conn = self._get_connection()
  File "/Users/saimanikanta/Desktop/ezapp/ez/frappe-bench/apps/frappe/frappe/database/mariadb/database.py", line 113, in _get_connection
    return self.create_connection()
           ~~~~~~~~~~~~~~~~~~~~~~^^
  File "/Users/saimanikanta/Desktop/ezapp/ez/frappe-bench/apps/frappe/frappe/database/mariadb/database.py", line 116, in create_connection
    return pymysql.connect(**self.get_connection_settings())
           ~~~~~~~~~~~~~~~^^^^^^^^^^^^^^^^^^^^^^^^^^^^^^^^^^
  File "/Users/saimanikanta/Desktop/ezapp/ez/frappe-bench/env/lib/python3.13/site-packages/pymysql/connections.py", line 361, in __init__
    self.connect()
    ~~~~~~~~~~~~^^
  File "/Users/saimanikanta/Desktop/ezapp/ez/frappe-bench/env/lib/python3.13/site-packages/pymysql/connections.py", line 669, in connect
    self._request_authentication()
    ~~~~~~~~~~~~~~~~~~~~~~~~~~~~^^
  File "/Users/saimanikanta/Desktop/ezapp/ez/frappe-bench/env/lib/python3.13/site-packages/pymysql/connections.py", line 957, in _request_authentication
    auth_packet = self._read_packet()
  File "/Users/saimanikanta/Desktop/ezapp/ez/frappe-bench/env/lib/python3.13/site-packages/pymysql/connections.py", line 775, in _read_packet
    packet.raise_for_error()
    ~~~~~~~~~~~~~~~~~~~~~~^^
  File "/Users/saimanikanta/Desktop/ezapp/ez/frappe-bench/env/lib/python3.13/site-packages/pymysql/protocol.py", line 219, in raise_for_error
    err.raise_mysql_exception(self._data)
    ~~~~~~~~~~~~~~~~~~~~~~~~~^^^^^^^^^^^^
  File "/Users/saimanikanta/Desktop/ezapp/ez/frappe-bench/env/lib/python3.13/site-packages/pymysql/err.py", line 150, in raise_mysql_exception
    raise errorclass(errno, errval)
pymysql.err.OperationalError: (1044, "Access denied for user '_7c5f4f77b0d74777'@'localhost' to database 'f77b0d74777_7c5f4'")
2025-02-10 10:30:00,815 ERROR scheduler Exception in Enqueue Events for Site money.test
Traceback (most recent call last):
  File "/Users/saimanikanta/Desktop/ezapp/ez/frappe-bench/apps/frappe/frappe/utils/scheduler.py", line 105, in enqueue_events_for_site
    if is_scheduler_inactive():
       ~~~~~~~~~~~~~~~~~~~~~^^
  File "/Users/saimanikanta/Desktop/ezapp/ez/frappe-bench/apps/frappe/frappe/utils/scheduler.py", line 149, in is_scheduler_inactive
    if is_scheduler_disabled(verbose=verbose):
       ~~~~~~~~~~~~~~~~~~~~~^^^^^^^^^^^^^^^^^
  File "/Users/saimanikanta/Desktop/ezapp/ez/frappe-bench/apps/frappe/frappe/utils/scheduler.py", line 162, in is_scheduler_disabled
    frappe.db.get_single_value("System Settings", "enable_scheduler")
    ~~~~~~~~~~~~~~~~~~~~~~~~~~^^^^^^^^^^^^^^^^^^^^^^^^^^^^^^^^^^^^^^^
  File "/Users/saimanikanta/Desktop/ezapp/ez/frappe-bench/apps/frappe/frappe/database/database.py", line 869, in get_single_value
    ).run()
      ~~~^^
  File "/Users/saimanikanta/Desktop/ezapp/ez/frappe-bench/apps/frappe/frappe/query_builder/utils.py", line 84, in execute_query
    result = frappe.db.sql(query, params, *args, **kwargs)  # nosemgrep
  File "/Users/saimanikanta/Desktop/ezapp/ez/frappe-bench/apps/frappe/frappe/database/database.py", line 215, in sql
    self.connect()
    ~~~~~~~~~~~~^^
  File "/Users/saimanikanta/Desktop/ezapp/ez/frappe-bench/apps/frappe/frappe/database/database.py", line 120, in connect
    self._conn: MariadbConnection | PostgresConnection = self.get_connection()
                                                         ~~~~~~~~~~~~~~~~~~~^^
  File "/Users/saimanikanta/Desktop/ezapp/ez/frappe-bench/apps/frappe/frappe/database/mariadb/database.py", line 107, in get_connection
    conn = self._get_connection()
  File "/Users/saimanikanta/Desktop/ezapp/ez/frappe-bench/apps/frappe/frappe/database/mariadb/database.py", line 113, in _get_connection
    return self.create_connection()
           ~~~~~~~~~~~~~~~~~~~~~~^^
  File "/Users/saimanikanta/Desktop/ezapp/ez/frappe-bench/apps/frappe/frappe/database/mariadb/database.py", line 116, in create_connection
    return pymysql.connect(**self.get_connection_settings())
           ~~~~~~~~~~~~~~~^^^^^^^^^^^^^^^^^^^^^^^^^^^^^^^^^^
  File "/Users/saimanikanta/Desktop/ezapp/ez/frappe-bench/env/lib/python3.13/site-packages/pymysql/connections.py", line 361, in __init__
    self.connect()
    ~~~~~~~~~~~~^^
  File "/Users/saimanikanta/Desktop/ezapp/ez/frappe-bench/env/lib/python3.13/site-packages/pymysql/connections.py", line 669, in connect
    self._request_authentication()
    ~~~~~~~~~~~~~~~~~~~~~~~~~~~~^^
  File "/Users/saimanikanta/Desktop/ezapp/ez/frappe-bench/env/lib/python3.13/site-packages/pymysql/connections.py", line 957, in _request_authentication
    auth_packet = self._read_packet()
  File "/Users/saimanikanta/Desktop/ezapp/ez/frappe-bench/env/lib/python3.13/site-packages/pymysql/connections.py", line 775, in _read_packet
    packet.raise_for_error()
    ~~~~~~~~~~~~~~~~~~~~~~^^
  File "/Users/saimanikanta/Desktop/ezapp/ez/frappe-bench/env/lib/python3.13/site-packages/pymysql/protocol.py", line 219, in raise_for_error
    err.raise_mysql_exception(self._data)
    ~~~~~~~~~~~~~~~~~~~~~~~~~^^^^^^^^^^^^
  File "/Users/saimanikanta/Desktop/ezapp/ez/frappe-bench/env/lib/python3.13/site-packages/pymysql/err.py", line 150, in raise_mysql_exception
    raise errorclass(errno, errval)
pymysql.err.OperationalError: (1044, "Access denied for user '_7c5f4f77b0d74777'@'localhost' to database 'f77b0d74777_7c5f4'")
2025-02-10 10:34:00,883 ERROR scheduler Exception in Enqueue Events for Site money.test
Traceback (most recent call last):
  File "/Users/saimanikanta/Desktop/ezapp/ez/frappe-bench/apps/frappe/frappe/utils/scheduler.py", line 105, in enqueue_events_for_site
    if is_scheduler_inactive():
       ~~~~~~~~~~~~~~~~~~~~~^^
  File "/Users/saimanikanta/Desktop/ezapp/ez/frappe-bench/apps/frappe/frappe/utils/scheduler.py", line 149, in is_scheduler_inactive
    if is_scheduler_disabled(verbose=verbose):
       ~~~~~~~~~~~~~~~~~~~~~^^^^^^^^^^^^^^^^^
  File "/Users/saimanikanta/Desktop/ezapp/ez/frappe-bench/apps/frappe/frappe/utils/scheduler.py", line 162, in is_scheduler_disabled
    frappe.db.get_single_value("System Settings", "enable_scheduler")
    ~~~~~~~~~~~~~~~~~~~~~~~~~~^^^^^^^^^^^^^^^^^^^^^^^^^^^^^^^^^^^^^^^
  File "/Users/saimanikanta/Desktop/ezapp/ez/frappe-bench/apps/frappe/frappe/database/database.py", line 869, in get_single_value
    ).run()
      ~~~^^
  File "/Users/saimanikanta/Desktop/ezapp/ez/frappe-bench/apps/frappe/frappe/query_builder/utils.py", line 84, in execute_query
    result = frappe.db.sql(query, params, *args, **kwargs)  # nosemgrep
  File "/Users/saimanikanta/Desktop/ezapp/ez/frappe-bench/apps/frappe/frappe/database/database.py", line 215, in sql
    self.connect()
    ~~~~~~~~~~~~^^
  File "/Users/saimanikanta/Desktop/ezapp/ez/frappe-bench/apps/frappe/frappe/database/database.py", line 120, in connect
    self._conn: MariadbConnection | PostgresConnection = self.get_connection()
                                                         ~~~~~~~~~~~~~~~~~~~^^
  File "/Users/saimanikanta/Desktop/ezapp/ez/frappe-bench/apps/frappe/frappe/database/mariadb/database.py", line 107, in get_connection
    conn = self._get_connection()
  File "/Users/saimanikanta/Desktop/ezapp/ez/frappe-bench/apps/frappe/frappe/database/mariadb/database.py", line 113, in _get_connection
    return self.create_connection()
           ~~~~~~~~~~~~~~~~~~~~~~^^
  File "/Users/saimanikanta/Desktop/ezapp/ez/frappe-bench/apps/frappe/frappe/database/mariadb/database.py", line 116, in create_connection
    return pymysql.connect(**self.get_connection_settings())
           ~~~~~~~~~~~~~~~^^^^^^^^^^^^^^^^^^^^^^^^^^^^^^^^^^
  File "/Users/saimanikanta/Desktop/ezapp/ez/frappe-bench/env/lib/python3.13/site-packages/pymysql/connections.py", line 361, in __init__
    self.connect()
    ~~~~~~~~~~~~^^
  File "/Users/saimanikanta/Desktop/ezapp/ez/frappe-bench/env/lib/python3.13/site-packages/pymysql/connections.py", line 669, in connect
    self._request_authentication()
    ~~~~~~~~~~~~~~~~~~~~~~~~~~~~^^
  File "/Users/saimanikanta/Desktop/ezapp/ez/frappe-bench/env/lib/python3.13/site-packages/pymysql/connections.py", line 957, in _request_authentication
    auth_packet = self._read_packet()
  File "/Users/saimanikanta/Desktop/ezapp/ez/frappe-bench/env/lib/python3.13/site-packages/pymysql/connections.py", line 775, in _read_packet
    packet.raise_for_error()
    ~~~~~~~~~~~~~~~~~~~~~~^^
  File "/Users/saimanikanta/Desktop/ezapp/ez/frappe-bench/env/lib/python3.13/site-packages/pymysql/protocol.py", line 219, in raise_for_error
    err.raise_mysql_exception(self._data)
    ~~~~~~~~~~~~~~~~~~~~~~~~~^^^^^^^^^^^^
  File "/Users/saimanikanta/Desktop/ezapp/ez/frappe-bench/env/lib/python3.13/site-packages/pymysql/err.py", line 150, in raise_mysql_exception
    raise errorclass(errno, errval)
pymysql.err.OperationalError: (1044, "Access denied for user '_7c5f4f77b0d74777'@'localhost' to database 'f77b0d74777_7c5f4'")
2025-02-10 10:38:00,892 ERROR scheduler Exception in Enqueue Events for Site money.test
Traceback (most recent call last):
  File "/Users/saimanikanta/Desktop/ezapp/ez/frappe-bench/apps/frappe/frappe/utils/scheduler.py", line 105, in enqueue_events_for_site
    if is_scheduler_inactive():
       ~~~~~~~~~~~~~~~~~~~~~^^
  File "/Users/saimanikanta/Desktop/ezapp/ez/frappe-bench/apps/frappe/frappe/utils/scheduler.py", line 149, in is_scheduler_inactive
    if is_scheduler_disabled(verbose=verbose):
       ~~~~~~~~~~~~~~~~~~~~~^^^^^^^^^^^^^^^^^
  File "/Users/saimanikanta/Desktop/ezapp/ez/frappe-bench/apps/frappe/frappe/utils/scheduler.py", line 162, in is_scheduler_disabled
    frappe.db.get_single_value("System Settings", "enable_scheduler")
    ~~~~~~~~~~~~~~~~~~~~~~~~~~^^^^^^^^^^^^^^^^^^^^^^^^^^^^^^^^^^^^^^^
  File "/Users/saimanikanta/Desktop/ezapp/ez/frappe-bench/apps/frappe/frappe/database/database.py", line 869, in get_single_value
    ).run()
      ~~~^^
  File "/Users/saimanikanta/Desktop/ezapp/ez/frappe-bench/apps/frappe/frappe/query_builder/utils.py", line 84, in execute_query
    result = frappe.db.sql(query, params, *args, **kwargs)  # nosemgrep
  File "/Users/saimanikanta/Desktop/ezapp/ez/frappe-bench/apps/frappe/frappe/database/database.py", line 215, in sql
    self.connect()
    ~~~~~~~~~~~~^^
  File "/Users/saimanikanta/Desktop/ezapp/ez/frappe-bench/apps/frappe/frappe/database/database.py", line 120, in connect
    self._conn: MariadbConnection | PostgresConnection = self.get_connection()
                                                         ~~~~~~~~~~~~~~~~~~~^^
  File "/Users/saimanikanta/Desktop/ezapp/ez/frappe-bench/apps/frappe/frappe/database/mariadb/database.py", line 107, in get_connection
    conn = self._get_connection()
  File "/Users/saimanikanta/Desktop/ezapp/ez/frappe-bench/apps/frappe/frappe/database/mariadb/database.py", line 113, in _get_connection
    return self.create_connection()
           ~~~~~~~~~~~~~~~~~~~~~~^^
  File "/Users/saimanikanta/Desktop/ezapp/ez/frappe-bench/apps/frappe/frappe/database/mariadb/database.py", line 116, in create_connection
    return pymysql.connect(**self.get_connection_settings())
           ~~~~~~~~~~~~~~~^^^^^^^^^^^^^^^^^^^^^^^^^^^^^^^^^^
  File "/Users/saimanikanta/Desktop/ezapp/ez/frappe-bench/env/lib/python3.13/site-packages/pymysql/connections.py", line 361, in __init__
    self.connect()
    ~~~~~~~~~~~~^^
  File "/Users/saimanikanta/Desktop/ezapp/ez/frappe-bench/env/lib/python3.13/site-packages/pymysql/connections.py", line 669, in connect
    self._request_authentication()
    ~~~~~~~~~~~~~~~~~~~~~~~~~~~~^^
  File "/Users/saimanikanta/Desktop/ezapp/ez/frappe-bench/env/lib/python3.13/site-packages/pymysql/connections.py", line 957, in _request_authentication
    auth_packet = self._read_packet()
  File "/Users/saimanikanta/Desktop/ezapp/ez/frappe-bench/env/lib/python3.13/site-packages/pymysql/connections.py", line 775, in _read_packet
    packet.raise_for_error()
    ~~~~~~~~~~~~~~~~~~~~~~^^
  File "/Users/saimanikanta/Desktop/ezapp/ez/frappe-bench/env/lib/python3.13/site-packages/pymysql/protocol.py", line 219, in raise_for_error
    err.raise_mysql_exception(self._data)
    ~~~~~~~~~~~~~~~~~~~~~~~~~^^^^^^^^^^^^
  File "/Users/saimanikanta/Desktop/ezapp/ez/frappe-bench/env/lib/python3.13/site-packages/pymysql/err.py", line 150, in raise_mysql_exception
    raise errorclass(errno, errval)
pymysql.err.OperationalError: (1044, "Access denied for user '_7c5f4f77b0d74777'@'localhost' to database 'f77b0d74777_7c5f4'")
2025-02-10 10:42:00,961 ERROR scheduler Exception in Enqueue Events for Site money.test
Traceback (most recent call last):
  File "/Users/saimanikanta/Desktop/ezapp/ez/frappe-bench/apps/frappe/frappe/utils/scheduler.py", line 105, in enqueue_events_for_site
    if is_scheduler_inactive():
       ~~~~~~~~~~~~~~~~~~~~~^^
  File "/Users/saimanikanta/Desktop/ezapp/ez/frappe-bench/apps/frappe/frappe/utils/scheduler.py", line 149, in is_scheduler_inactive
    if is_scheduler_disabled(verbose=verbose):
       ~~~~~~~~~~~~~~~~~~~~~^^^^^^^^^^^^^^^^^
  File "/Users/saimanikanta/Desktop/ezapp/ez/frappe-bench/apps/frappe/frappe/utils/scheduler.py", line 162, in is_scheduler_disabled
    frappe.db.get_single_value("System Settings", "enable_scheduler")
    ~~~~~~~~~~~~~~~~~~~~~~~~~~^^^^^^^^^^^^^^^^^^^^^^^^^^^^^^^^^^^^^^^
  File "/Users/saimanikanta/Desktop/ezapp/ez/frappe-bench/apps/frappe/frappe/database/database.py", line 869, in get_single_value
    ).run()
      ~~~^^
  File "/Users/saimanikanta/Desktop/ezapp/ez/frappe-bench/apps/frappe/frappe/query_builder/utils.py", line 84, in execute_query
    result = frappe.db.sql(query, params, *args, **kwargs)  # nosemgrep
  File "/Users/saimanikanta/Desktop/ezapp/ez/frappe-bench/apps/frappe/frappe/database/database.py", line 215, in sql
    self.connect()
    ~~~~~~~~~~~~^^
  File "/Users/saimanikanta/Desktop/ezapp/ez/frappe-bench/apps/frappe/frappe/database/database.py", line 120, in connect
    self._conn: MariadbConnection | PostgresConnection = self.get_connection()
                                                         ~~~~~~~~~~~~~~~~~~~^^
  File "/Users/saimanikanta/Desktop/ezapp/ez/frappe-bench/apps/frappe/frappe/database/mariadb/database.py", line 107, in get_connection
    conn = self._get_connection()
  File "/Users/saimanikanta/Desktop/ezapp/ez/frappe-bench/apps/frappe/frappe/database/mariadb/database.py", line 113, in _get_connection
    return self.create_connection()
           ~~~~~~~~~~~~~~~~~~~~~~^^
  File "/Users/saimanikanta/Desktop/ezapp/ez/frappe-bench/apps/frappe/frappe/database/mariadb/database.py", line 116, in create_connection
    return pymysql.connect(**self.get_connection_settings())
           ~~~~~~~~~~~~~~~^^^^^^^^^^^^^^^^^^^^^^^^^^^^^^^^^^
  File "/Users/saimanikanta/Desktop/ezapp/ez/frappe-bench/env/lib/python3.13/site-packages/pymysql/connections.py", line 361, in __init__
    self.connect()
    ~~~~~~~~~~~~^^
  File "/Users/saimanikanta/Desktop/ezapp/ez/frappe-bench/env/lib/python3.13/site-packages/pymysql/connections.py", line 669, in connect
    self._request_authentication()
    ~~~~~~~~~~~~~~~~~~~~~~~~~~~~^^
  File "/Users/saimanikanta/Desktop/ezapp/ez/frappe-bench/env/lib/python3.13/site-packages/pymysql/connections.py", line 957, in _request_authentication
    auth_packet = self._read_packet()
  File "/Users/saimanikanta/Desktop/ezapp/ez/frappe-bench/env/lib/python3.13/site-packages/pymysql/connections.py", line 775, in _read_packet
    packet.raise_for_error()
    ~~~~~~~~~~~~~~~~~~~~~~^^
  File "/Users/saimanikanta/Desktop/ezapp/ez/frappe-bench/env/lib/python3.13/site-packages/pymysql/protocol.py", line 219, in raise_for_error
    err.raise_mysql_exception(self._data)
    ~~~~~~~~~~~~~~~~~~~~~~~~~^^^^^^^^^^^^
  File "/Users/saimanikanta/Desktop/ezapp/ez/frappe-bench/env/lib/python3.13/site-packages/pymysql/err.py", line 150, in raise_mysql_exception
    raise errorclass(errno, errval)
pymysql.err.OperationalError: (1044, "Access denied for user '_7c5f4f77b0d74777'@'localhost' to database 'f77b0d74777_7c5f4'")
2025-02-10 10:46:00,095 ERROR scheduler Exception in Enqueue Events for Site money.test
Traceback (most recent call last):
  File "/Users/saimanikanta/Desktop/ezapp/ez/frappe-bench/apps/frappe/frappe/utils/scheduler.py", line 105, in enqueue_events_for_site
    if is_scheduler_inactive():
       ~~~~~~~~~~~~~~~~~~~~~^^
  File "/Users/saimanikanta/Desktop/ezapp/ez/frappe-bench/apps/frappe/frappe/utils/scheduler.py", line 149, in is_scheduler_inactive
    if is_scheduler_disabled(verbose=verbose):
       ~~~~~~~~~~~~~~~~~~~~~^^^^^^^^^^^^^^^^^
  File "/Users/saimanikanta/Desktop/ezapp/ez/frappe-bench/apps/frappe/frappe/utils/scheduler.py", line 162, in is_scheduler_disabled
    frappe.db.get_single_value("System Settings", "enable_scheduler")
    ~~~~~~~~~~~~~~~~~~~~~~~~~~^^^^^^^^^^^^^^^^^^^^^^^^^^^^^^^^^^^^^^^
  File "/Users/saimanikanta/Desktop/ezapp/ez/frappe-bench/apps/frappe/frappe/database/database.py", line 869, in get_single_value
    ).run()
      ~~~^^
  File "/Users/saimanikanta/Desktop/ezapp/ez/frappe-bench/apps/frappe/frappe/query_builder/utils.py", line 84, in execute_query
    result = frappe.db.sql(query, params, *args, **kwargs)  # nosemgrep
  File "/Users/saimanikanta/Desktop/ezapp/ez/frappe-bench/apps/frappe/frappe/database/database.py", line 215, in sql
    self.connect()
    ~~~~~~~~~~~~^^
  File "/Users/saimanikanta/Desktop/ezapp/ez/frappe-bench/apps/frappe/frappe/database/database.py", line 120, in connect
    self._conn: MariadbConnection | PostgresConnection = self.get_connection()
                                                         ~~~~~~~~~~~~~~~~~~~^^
  File "/Users/saimanikanta/Desktop/ezapp/ez/frappe-bench/apps/frappe/frappe/database/mariadb/database.py", line 107, in get_connection
    conn = self._get_connection()
  File "/Users/saimanikanta/Desktop/ezapp/ez/frappe-bench/apps/frappe/frappe/database/mariadb/database.py", line 113, in _get_connection
    return self.create_connection()
           ~~~~~~~~~~~~~~~~~~~~~~^^
  File "/Users/saimanikanta/Desktop/ezapp/ez/frappe-bench/apps/frappe/frappe/database/mariadb/database.py", line 116, in create_connection
    return pymysql.connect(**self.get_connection_settings())
           ~~~~~~~~~~~~~~~^^^^^^^^^^^^^^^^^^^^^^^^^^^^^^^^^^
  File "/Users/saimanikanta/Desktop/ezapp/ez/frappe-bench/env/lib/python3.13/site-packages/pymysql/connections.py", line 361, in __init__
    self.connect()
    ~~~~~~~~~~~~^^
  File "/Users/saimanikanta/Desktop/ezapp/ez/frappe-bench/env/lib/python3.13/site-packages/pymysql/connections.py", line 669, in connect
    self._request_authentication()
    ~~~~~~~~~~~~~~~~~~~~~~~~~~~~^^
  File "/Users/saimanikanta/Desktop/ezapp/ez/frappe-bench/env/lib/python3.13/site-packages/pymysql/connections.py", line 957, in _request_authentication
    auth_packet = self._read_packet()
  File "/Users/saimanikanta/Desktop/ezapp/ez/frappe-bench/env/lib/python3.13/site-packages/pymysql/connections.py", line 775, in _read_packet
    packet.raise_for_error()
    ~~~~~~~~~~~~~~~~~~~~~~^^
  File "/Users/saimanikanta/Desktop/ezapp/ez/frappe-bench/env/lib/python3.13/site-packages/pymysql/protocol.py", line 219, in raise_for_error
    err.raise_mysql_exception(self._data)
    ~~~~~~~~~~~~~~~~~~~~~~~~~^^^^^^^^^^^^
  File "/Users/saimanikanta/Desktop/ezapp/ez/frappe-bench/env/lib/python3.13/site-packages/pymysql/err.py", line 150, in raise_mysql_exception
    raise errorclass(errno, errval)
pymysql.err.OperationalError: (1044, "Access denied for user '_7c5f4f77b0d74777'@'localhost' to database 'f77b0d74777_7c5f4'")
2025-02-10 10:50:00,098 ERROR scheduler Exception in Enqueue Events for Site money.test
Traceback (most recent call last):
  File "/Users/saimanikanta/Desktop/ezapp/ez/frappe-bench/apps/frappe/frappe/utils/scheduler.py", line 105, in enqueue_events_for_site
    if is_scheduler_inactive():
       ~~~~~~~~~~~~~~~~~~~~~^^
  File "/Users/saimanikanta/Desktop/ezapp/ez/frappe-bench/apps/frappe/frappe/utils/scheduler.py", line 149, in is_scheduler_inactive
    if is_scheduler_disabled(verbose=verbose):
       ~~~~~~~~~~~~~~~~~~~~~^^^^^^^^^^^^^^^^^
  File "/Users/saimanikanta/Desktop/ezapp/ez/frappe-bench/apps/frappe/frappe/utils/scheduler.py", line 162, in is_scheduler_disabled
    frappe.db.get_single_value("System Settings", "enable_scheduler")
    ~~~~~~~~~~~~~~~~~~~~~~~~~~^^^^^^^^^^^^^^^^^^^^^^^^^^^^^^^^^^^^^^^
  File "/Users/saimanikanta/Desktop/ezapp/ez/frappe-bench/apps/frappe/frappe/database/database.py", line 869, in get_single_value
    ).run()
      ~~~^^
  File "/Users/saimanikanta/Desktop/ezapp/ez/frappe-bench/apps/frappe/frappe/query_builder/utils.py", line 84, in execute_query
    result = frappe.db.sql(query, params, *args, **kwargs)  # nosemgrep
  File "/Users/saimanikanta/Desktop/ezapp/ez/frappe-bench/apps/frappe/frappe/database/database.py", line 215, in sql
    self.connect()
    ~~~~~~~~~~~~^^
  File "/Users/saimanikanta/Desktop/ezapp/ez/frappe-bench/apps/frappe/frappe/database/database.py", line 120, in connect
    self._conn: MariadbConnection | PostgresConnection = self.get_connection()
                                                         ~~~~~~~~~~~~~~~~~~~^^
  File "/Users/saimanikanta/Desktop/ezapp/ez/frappe-bench/apps/frappe/frappe/database/mariadb/database.py", line 107, in get_connection
    conn = self._get_connection()
  File "/Users/saimanikanta/Desktop/ezapp/ez/frappe-bench/apps/frappe/frappe/database/mariadb/database.py", line 113, in _get_connection
    return self.create_connection()
           ~~~~~~~~~~~~~~~~~~~~~~^^
  File "/Users/saimanikanta/Desktop/ezapp/ez/frappe-bench/apps/frappe/frappe/database/mariadb/database.py", line 116, in create_connection
    return pymysql.connect(**self.get_connection_settings())
           ~~~~~~~~~~~~~~~^^^^^^^^^^^^^^^^^^^^^^^^^^^^^^^^^^
  File "/Users/saimanikanta/Desktop/ezapp/ez/frappe-bench/env/lib/python3.13/site-packages/pymysql/connections.py", line 361, in __init__
    self.connect()
    ~~~~~~~~~~~~^^
  File "/Users/saimanikanta/Desktop/ezapp/ez/frappe-bench/env/lib/python3.13/site-packages/pymysql/connections.py", line 669, in connect
    self._request_authentication()
    ~~~~~~~~~~~~~~~~~~~~~~~~~~~~^^
  File "/Users/saimanikanta/Desktop/ezapp/ez/frappe-bench/env/lib/python3.13/site-packages/pymysql/connections.py", line 957, in _request_authentication
    auth_packet = self._read_packet()
  File "/Users/saimanikanta/Desktop/ezapp/ez/frappe-bench/env/lib/python3.13/site-packages/pymysql/connections.py", line 775, in _read_packet
    packet.raise_for_error()
    ~~~~~~~~~~~~~~~~~~~~~~^^
  File "/Users/saimanikanta/Desktop/ezapp/ez/frappe-bench/env/lib/python3.13/site-packages/pymysql/protocol.py", line 219, in raise_for_error
    err.raise_mysql_exception(self._data)
    ~~~~~~~~~~~~~~~~~~~~~~~~~^^^^^^^^^^^^
  File "/Users/saimanikanta/Desktop/ezapp/ez/frappe-bench/env/lib/python3.13/site-packages/pymysql/err.py", line 150, in raise_mysql_exception
    raise errorclass(errno, errval)
pymysql.err.OperationalError: (1044, "Access denied for user '_7c5f4f77b0d74777'@'localhost' to database 'f77b0d74777_7c5f4'")
2025-02-10 10:54:00,218 ERROR scheduler Exception in Enqueue Events for Site money.test
Traceback (most recent call last):
  File "/Users/saimanikanta/Desktop/ezapp/ez/frappe-bench/apps/frappe/frappe/utils/scheduler.py", line 105, in enqueue_events_for_site
    if is_scheduler_inactive():
       ~~~~~~~~~~~~~~~~~~~~~^^
  File "/Users/saimanikanta/Desktop/ezapp/ez/frappe-bench/apps/frappe/frappe/utils/scheduler.py", line 149, in is_scheduler_inactive
    if is_scheduler_disabled(verbose=verbose):
       ~~~~~~~~~~~~~~~~~~~~~^^^^^^^^^^^^^^^^^
  File "/Users/saimanikanta/Desktop/ezapp/ez/frappe-bench/apps/frappe/frappe/utils/scheduler.py", line 162, in is_scheduler_disabled
    frappe.db.get_single_value("System Settings", "enable_scheduler")
    ~~~~~~~~~~~~~~~~~~~~~~~~~~^^^^^^^^^^^^^^^^^^^^^^^^^^^^^^^^^^^^^^^
  File "/Users/saimanikanta/Desktop/ezapp/ez/frappe-bench/apps/frappe/frappe/database/database.py", line 869, in get_single_value
    ).run()
      ~~~^^
  File "/Users/saimanikanta/Desktop/ezapp/ez/frappe-bench/apps/frappe/frappe/query_builder/utils.py", line 84, in execute_query
    result = frappe.db.sql(query, params, *args, **kwargs)  # nosemgrep
  File "/Users/saimanikanta/Desktop/ezapp/ez/frappe-bench/apps/frappe/frappe/database/database.py", line 215, in sql
    self.connect()
    ~~~~~~~~~~~~^^
  File "/Users/saimanikanta/Desktop/ezapp/ez/frappe-bench/apps/frappe/frappe/database/database.py", line 120, in connect
    self._conn: MariadbConnection | PostgresConnection = self.get_connection()
                                                         ~~~~~~~~~~~~~~~~~~~^^
  File "/Users/saimanikanta/Desktop/ezapp/ez/frappe-bench/apps/frappe/frappe/database/mariadb/database.py", line 107, in get_connection
    conn = self._get_connection()
  File "/Users/saimanikanta/Desktop/ezapp/ez/frappe-bench/apps/frappe/frappe/database/mariadb/database.py", line 113, in _get_connection
    return self.create_connection()
           ~~~~~~~~~~~~~~~~~~~~~~^^
  File "/Users/saimanikanta/Desktop/ezapp/ez/frappe-bench/apps/frappe/frappe/database/mariadb/database.py", line 116, in create_connection
    return pymysql.connect(**self.get_connection_settings())
           ~~~~~~~~~~~~~~~^^^^^^^^^^^^^^^^^^^^^^^^^^^^^^^^^^
  File "/Users/saimanikanta/Desktop/ezapp/ez/frappe-bench/env/lib/python3.13/site-packages/pymysql/connections.py", line 361, in __init__
    self.connect()
    ~~~~~~~~~~~~^^
  File "/Users/saimanikanta/Desktop/ezapp/ez/frappe-bench/env/lib/python3.13/site-packages/pymysql/connections.py", line 669, in connect
    self._request_authentication()
    ~~~~~~~~~~~~~~~~~~~~~~~~~~~~^^
  File "/Users/saimanikanta/Desktop/ezapp/ez/frappe-bench/env/lib/python3.13/site-packages/pymysql/connections.py", line 957, in _request_authentication
    auth_packet = self._read_packet()
  File "/Users/saimanikanta/Desktop/ezapp/ez/frappe-bench/env/lib/python3.13/site-packages/pymysql/connections.py", line 775, in _read_packet
    packet.raise_for_error()
    ~~~~~~~~~~~~~~~~~~~~~~^^
  File "/Users/saimanikanta/Desktop/ezapp/ez/frappe-bench/env/lib/python3.13/site-packages/pymysql/protocol.py", line 219, in raise_for_error
    err.raise_mysql_exception(self._data)
    ~~~~~~~~~~~~~~~~~~~~~~~~~^^^^^^^^^^^^
  File "/Users/saimanikanta/Desktop/ezapp/ez/frappe-bench/env/lib/python3.13/site-packages/pymysql/err.py", line 150, in raise_mysql_exception
    raise errorclass(errno, errval)
pymysql.err.OperationalError: (1044, "Access denied for user '_7c5f4f77b0d74777'@'localhost' to database 'f77b0d74777_7c5f4'")
2025-02-10 10:58:00,227 ERROR scheduler Exception in Enqueue Events for Site money.test
Traceback (most recent call last):
  File "/Users/saimanikanta/Desktop/ezapp/ez/frappe-bench/apps/frappe/frappe/utils/scheduler.py", line 105, in enqueue_events_for_site
    if is_scheduler_inactive():
       ~~~~~~~~~~~~~~~~~~~~~^^
  File "/Users/saimanikanta/Desktop/ezapp/ez/frappe-bench/apps/frappe/frappe/utils/scheduler.py", line 149, in is_scheduler_inactive
    if is_scheduler_disabled(verbose=verbose):
       ~~~~~~~~~~~~~~~~~~~~~^^^^^^^^^^^^^^^^^
  File "/Users/saimanikanta/Desktop/ezapp/ez/frappe-bench/apps/frappe/frappe/utils/scheduler.py", line 162, in is_scheduler_disabled
    frappe.db.get_single_value("System Settings", "enable_scheduler")
    ~~~~~~~~~~~~~~~~~~~~~~~~~~^^^^^^^^^^^^^^^^^^^^^^^^^^^^^^^^^^^^^^^
  File "/Users/saimanikanta/Desktop/ezapp/ez/frappe-bench/apps/frappe/frappe/database/database.py", line 869, in get_single_value
    ).run()
      ~~~^^
  File "/Users/saimanikanta/Desktop/ezapp/ez/frappe-bench/apps/frappe/frappe/query_builder/utils.py", line 84, in execute_query
    result = frappe.db.sql(query, params, *args, **kwargs)  # nosemgrep
  File "/Users/saimanikanta/Desktop/ezapp/ez/frappe-bench/apps/frappe/frappe/database/database.py", line 215, in sql
    self.connect()
    ~~~~~~~~~~~~^^
  File "/Users/saimanikanta/Desktop/ezapp/ez/frappe-bench/apps/frappe/frappe/database/database.py", line 120, in connect
    self._conn: MariadbConnection | PostgresConnection = self.get_connection()
                                                         ~~~~~~~~~~~~~~~~~~~^^
  File "/Users/saimanikanta/Desktop/ezapp/ez/frappe-bench/apps/frappe/frappe/database/mariadb/database.py", line 107, in get_connection
    conn = self._get_connection()
  File "/Users/saimanikanta/Desktop/ezapp/ez/frappe-bench/apps/frappe/frappe/database/mariadb/database.py", line 113, in _get_connection
    return self.create_connection()
           ~~~~~~~~~~~~~~~~~~~~~~^^
  File "/Users/saimanikanta/Desktop/ezapp/ez/frappe-bench/apps/frappe/frappe/database/mariadb/database.py", line 116, in create_connection
    return pymysql.connect(**self.get_connection_settings())
           ~~~~~~~~~~~~~~~^^^^^^^^^^^^^^^^^^^^^^^^^^^^^^^^^^
  File "/Users/saimanikanta/Desktop/ezapp/ez/frappe-bench/env/lib/python3.13/site-packages/pymysql/connections.py", line 361, in __init__
    self.connect()
    ~~~~~~~~~~~~^^
  File "/Users/saimanikanta/Desktop/ezapp/ez/frappe-bench/env/lib/python3.13/site-packages/pymysql/connections.py", line 669, in connect
    self._request_authentication()
    ~~~~~~~~~~~~~~~~~~~~~~~~~~~~^^
  File "/Users/saimanikanta/Desktop/ezapp/ez/frappe-bench/env/lib/python3.13/site-packages/pymysql/connections.py", line 957, in _request_authentication
    auth_packet = self._read_packet()
  File "/Users/saimanikanta/Desktop/ezapp/ez/frappe-bench/env/lib/python3.13/site-packages/pymysql/connections.py", line 775, in _read_packet
    packet.raise_for_error()
    ~~~~~~~~~~~~~~~~~~~~~~^^
  File "/Users/saimanikanta/Desktop/ezapp/ez/frappe-bench/env/lib/python3.13/site-packages/pymysql/protocol.py", line 219, in raise_for_error
    err.raise_mysql_exception(self._data)
    ~~~~~~~~~~~~~~~~~~~~~~~~~^^^^^^^^^^^^
  File "/Users/saimanikanta/Desktop/ezapp/ez/frappe-bench/env/lib/python3.13/site-packages/pymysql/err.py", line 150, in raise_mysql_exception
    raise errorclass(errno, errval)
pymysql.err.OperationalError: (1044, "Access denied for user '_7c5f4f77b0d74777'@'localhost' to database 'f77b0d74777_7c5f4'")
2025-02-10 11:02:00,307 ERROR scheduler Exception in Enqueue Events for Site money.test
Traceback (most recent call last):
  File "/Users/saimanikanta/Desktop/ezapp/ez/frappe-bench/apps/frappe/frappe/utils/scheduler.py", line 105, in enqueue_events_for_site
    if is_scheduler_inactive():
       ~~~~~~~~~~~~~~~~~~~~~^^
  File "/Users/saimanikanta/Desktop/ezapp/ez/frappe-bench/apps/frappe/frappe/utils/scheduler.py", line 149, in is_scheduler_inactive
    if is_scheduler_disabled(verbose=verbose):
       ~~~~~~~~~~~~~~~~~~~~~^^^^^^^^^^^^^^^^^
  File "/Users/saimanikanta/Desktop/ezapp/ez/frappe-bench/apps/frappe/frappe/utils/scheduler.py", line 162, in is_scheduler_disabled
    frappe.db.get_single_value("System Settings", "enable_scheduler")
    ~~~~~~~~~~~~~~~~~~~~~~~~~~^^^^^^^^^^^^^^^^^^^^^^^^^^^^^^^^^^^^^^^
  File "/Users/saimanikanta/Desktop/ezapp/ez/frappe-bench/apps/frappe/frappe/database/database.py", line 869, in get_single_value
    ).run()
      ~~~^^
  File "/Users/saimanikanta/Desktop/ezapp/ez/frappe-bench/apps/frappe/frappe/query_builder/utils.py", line 84, in execute_query
    result = frappe.db.sql(query, params, *args, **kwargs)  # nosemgrep
  File "/Users/saimanikanta/Desktop/ezapp/ez/frappe-bench/apps/frappe/frappe/database/database.py", line 215, in sql
    self.connect()
    ~~~~~~~~~~~~^^
  File "/Users/saimanikanta/Desktop/ezapp/ez/frappe-bench/apps/frappe/frappe/database/database.py", line 120, in connect
    self._conn: MariadbConnection | PostgresConnection = self.get_connection()
                                                         ~~~~~~~~~~~~~~~~~~~^^
  File "/Users/saimanikanta/Desktop/ezapp/ez/frappe-bench/apps/frappe/frappe/database/mariadb/database.py", line 107, in get_connection
    conn = self._get_connection()
  File "/Users/saimanikanta/Desktop/ezapp/ez/frappe-bench/apps/frappe/frappe/database/mariadb/database.py", line 113, in _get_connection
    return self.create_connection()
           ~~~~~~~~~~~~~~~~~~~~~~^^
  File "/Users/saimanikanta/Desktop/ezapp/ez/frappe-bench/apps/frappe/frappe/database/mariadb/database.py", line 116, in create_connection
    return pymysql.connect(**self.get_connection_settings())
           ~~~~~~~~~~~~~~~^^^^^^^^^^^^^^^^^^^^^^^^^^^^^^^^^^
  File "/Users/saimanikanta/Desktop/ezapp/ez/frappe-bench/env/lib/python3.13/site-packages/pymysql/connections.py", line 361, in __init__
    self.connect()
    ~~~~~~~~~~~~^^
  File "/Users/saimanikanta/Desktop/ezapp/ez/frappe-bench/env/lib/python3.13/site-packages/pymysql/connections.py", line 669, in connect
    self._request_authentication()
    ~~~~~~~~~~~~~~~~~~~~~~~~~~~~^^
  File "/Users/saimanikanta/Desktop/ezapp/ez/frappe-bench/env/lib/python3.13/site-packages/pymysql/connections.py", line 957, in _request_authentication
    auth_packet = self._read_packet()
  File "/Users/saimanikanta/Desktop/ezapp/ez/frappe-bench/env/lib/python3.13/site-packages/pymysql/connections.py", line 775, in _read_packet
    packet.raise_for_error()
    ~~~~~~~~~~~~~~~~~~~~~~^^
  File "/Users/saimanikanta/Desktop/ezapp/ez/frappe-bench/env/lib/python3.13/site-packages/pymysql/protocol.py", line 219, in raise_for_error
    err.raise_mysql_exception(self._data)
    ~~~~~~~~~~~~~~~~~~~~~~~~~^^^^^^^^^^^^
  File "/Users/saimanikanta/Desktop/ezapp/ez/frappe-bench/env/lib/python3.13/site-packages/pymysql/err.py", line 150, in raise_mysql_exception
    raise errorclass(errno, errval)
pymysql.err.OperationalError: (1044, "Access denied for user '_7c5f4f77b0d74777'@'localhost' to database 'f77b0d74777_7c5f4'")
2025-02-10 11:06:00,447 ERROR scheduler Exception in Enqueue Events for Site money.test
Traceback (most recent call last):
  File "/Users/saimanikanta/Desktop/ezapp/ez/frappe-bench/apps/frappe/frappe/utils/scheduler.py", line 105, in enqueue_events_for_site
    if is_scheduler_inactive():
       ~~~~~~~~~~~~~~~~~~~~~^^
  File "/Users/saimanikanta/Desktop/ezapp/ez/frappe-bench/apps/frappe/frappe/utils/scheduler.py", line 149, in is_scheduler_inactive
    if is_scheduler_disabled(verbose=verbose):
       ~~~~~~~~~~~~~~~~~~~~~^^^^^^^^^^^^^^^^^
  File "/Users/saimanikanta/Desktop/ezapp/ez/frappe-bench/apps/frappe/frappe/utils/scheduler.py", line 162, in is_scheduler_disabled
    frappe.db.get_single_value("System Settings", "enable_scheduler")
    ~~~~~~~~~~~~~~~~~~~~~~~~~~^^^^^^^^^^^^^^^^^^^^^^^^^^^^^^^^^^^^^^^
  File "/Users/saimanikanta/Desktop/ezapp/ez/frappe-bench/apps/frappe/frappe/database/database.py", line 869, in get_single_value
    ).run()
      ~~~^^
  File "/Users/saimanikanta/Desktop/ezapp/ez/frappe-bench/apps/frappe/frappe/query_builder/utils.py", line 84, in execute_query
    result = frappe.db.sql(query, params, *args, **kwargs)  # nosemgrep
  File "/Users/saimanikanta/Desktop/ezapp/ez/frappe-bench/apps/frappe/frappe/database/database.py", line 215, in sql
    self.connect()
    ~~~~~~~~~~~~^^
  File "/Users/saimanikanta/Desktop/ezapp/ez/frappe-bench/apps/frappe/frappe/database/database.py", line 120, in connect
    self._conn: MariadbConnection | PostgresConnection = self.get_connection()
                                                         ~~~~~~~~~~~~~~~~~~~^^
  File "/Users/saimanikanta/Desktop/ezapp/ez/frappe-bench/apps/frappe/frappe/database/mariadb/database.py", line 107, in get_connection
    conn = self._get_connection()
  File "/Users/saimanikanta/Desktop/ezapp/ez/frappe-bench/apps/frappe/frappe/database/mariadb/database.py", line 113, in _get_connection
    return self.create_connection()
           ~~~~~~~~~~~~~~~~~~~~~~^^
  File "/Users/saimanikanta/Desktop/ezapp/ez/frappe-bench/apps/frappe/frappe/database/mariadb/database.py", line 116, in create_connection
    return pymysql.connect(**self.get_connection_settings())
           ~~~~~~~~~~~~~~~^^^^^^^^^^^^^^^^^^^^^^^^^^^^^^^^^^
  File "/Users/saimanikanta/Desktop/ezapp/ez/frappe-bench/env/lib/python3.13/site-packages/pymysql/connections.py", line 361, in __init__
    self.connect()
    ~~~~~~~~~~~~^^
  File "/Users/saimanikanta/Desktop/ezapp/ez/frappe-bench/env/lib/python3.13/site-packages/pymysql/connections.py", line 669, in connect
    self._request_authentication()
    ~~~~~~~~~~~~~~~~~~~~~~~~~~~~^^
  File "/Users/saimanikanta/Desktop/ezapp/ez/frappe-bench/env/lib/python3.13/site-packages/pymysql/connections.py", line 957, in _request_authentication
    auth_packet = self._read_packet()
  File "/Users/saimanikanta/Desktop/ezapp/ez/frappe-bench/env/lib/python3.13/site-packages/pymysql/connections.py", line 775, in _read_packet
    packet.raise_for_error()
    ~~~~~~~~~~~~~~~~~~~~~~^^
  File "/Users/saimanikanta/Desktop/ezapp/ez/frappe-bench/env/lib/python3.13/site-packages/pymysql/protocol.py", line 219, in raise_for_error
    err.raise_mysql_exception(self._data)
    ~~~~~~~~~~~~~~~~~~~~~~~~~^^^^^^^^^^^^
  File "/Users/saimanikanta/Desktop/ezapp/ez/frappe-bench/env/lib/python3.13/site-packages/pymysql/err.py", line 150, in raise_mysql_exception
    raise errorclass(errno, errval)
pymysql.err.OperationalError: (1044, "Access denied for user '_7c5f4f77b0d74777'@'localhost' to database 'f77b0d74777_7c5f4'")
2025-02-10 11:10:00,486 ERROR scheduler Exception in Enqueue Events for Site money.test
Traceback (most recent call last):
  File "/Users/saimanikanta/Desktop/ezapp/ez/frappe-bench/apps/frappe/frappe/utils/scheduler.py", line 105, in enqueue_events_for_site
    if is_scheduler_inactive():
       ~~~~~~~~~~~~~~~~~~~~~^^
  File "/Users/saimanikanta/Desktop/ezapp/ez/frappe-bench/apps/frappe/frappe/utils/scheduler.py", line 149, in is_scheduler_inactive
    if is_scheduler_disabled(verbose=verbose):
       ~~~~~~~~~~~~~~~~~~~~~^^^^^^^^^^^^^^^^^
  File "/Users/saimanikanta/Desktop/ezapp/ez/frappe-bench/apps/frappe/frappe/utils/scheduler.py", line 162, in is_scheduler_disabled
    frappe.db.get_single_value("System Settings", "enable_scheduler")
    ~~~~~~~~~~~~~~~~~~~~~~~~~~^^^^^^^^^^^^^^^^^^^^^^^^^^^^^^^^^^^^^^^
  File "/Users/saimanikanta/Desktop/ezapp/ez/frappe-bench/apps/frappe/frappe/database/database.py", line 869, in get_single_value
    ).run()
      ~~~^^
  File "/Users/saimanikanta/Desktop/ezapp/ez/frappe-bench/apps/frappe/frappe/query_builder/utils.py", line 84, in execute_query
    result = frappe.db.sql(query, params, *args, **kwargs)  # nosemgrep
  File "/Users/saimanikanta/Desktop/ezapp/ez/frappe-bench/apps/frappe/frappe/database/database.py", line 215, in sql
    self.connect()
    ~~~~~~~~~~~~^^
  File "/Users/saimanikanta/Desktop/ezapp/ez/frappe-bench/apps/frappe/frappe/database/database.py", line 120, in connect
    self._conn: MariadbConnection | PostgresConnection = self.get_connection()
                                                         ~~~~~~~~~~~~~~~~~~~^^
  File "/Users/saimanikanta/Desktop/ezapp/ez/frappe-bench/apps/frappe/frappe/database/mariadb/database.py", line 107, in get_connection
    conn = self._get_connection()
  File "/Users/saimanikanta/Desktop/ezapp/ez/frappe-bench/apps/frappe/frappe/database/mariadb/database.py", line 113, in _get_connection
    return self.create_connection()
           ~~~~~~~~~~~~~~~~~~~~~~^^
  File "/Users/saimanikanta/Desktop/ezapp/ez/frappe-bench/apps/frappe/frappe/database/mariadb/database.py", line 116, in create_connection
    return pymysql.connect(**self.get_connection_settings())
           ~~~~~~~~~~~~~~~^^^^^^^^^^^^^^^^^^^^^^^^^^^^^^^^^^
  File "/Users/saimanikanta/Desktop/ezapp/ez/frappe-bench/env/lib/python3.13/site-packages/pymysql/connections.py", line 361, in __init__
    self.connect()
    ~~~~~~~~~~~~^^
  File "/Users/saimanikanta/Desktop/ezapp/ez/frappe-bench/env/lib/python3.13/site-packages/pymysql/connections.py", line 669, in connect
    self._request_authentication()
    ~~~~~~~~~~~~~~~~~~~~~~~~~~~~^^
  File "/Users/saimanikanta/Desktop/ezapp/ez/frappe-bench/env/lib/python3.13/site-packages/pymysql/connections.py", line 957, in _request_authentication
    auth_packet = self._read_packet()
  File "/Users/saimanikanta/Desktop/ezapp/ez/frappe-bench/env/lib/python3.13/site-packages/pymysql/connections.py", line 775, in _read_packet
    packet.raise_for_error()
    ~~~~~~~~~~~~~~~~~~~~~~^^
  File "/Users/saimanikanta/Desktop/ezapp/ez/frappe-bench/env/lib/python3.13/site-packages/pymysql/protocol.py", line 219, in raise_for_error
    err.raise_mysql_exception(self._data)
    ~~~~~~~~~~~~~~~~~~~~~~~~~^^^^^^^^^^^^
  File "/Users/saimanikanta/Desktop/ezapp/ez/frappe-bench/env/lib/python3.13/site-packages/pymysql/err.py", line 150, in raise_mysql_exception
    raise errorclass(errno, errval)
pymysql.err.OperationalError: (1044, "Access denied for user '_7c5f4f77b0d74777'@'localhost' to database 'f77b0d74777_7c5f4'")
2025-02-10 11:14:00,563 ERROR scheduler Exception in Enqueue Events for Site money.test
Traceback (most recent call last):
  File "/Users/saimanikanta/Desktop/ezapp/ez/frappe-bench/apps/frappe/frappe/utils/scheduler.py", line 105, in enqueue_events_for_site
    if is_scheduler_inactive():
       ~~~~~~~~~~~~~~~~~~~~~^^
  File "/Users/saimanikanta/Desktop/ezapp/ez/frappe-bench/apps/frappe/frappe/utils/scheduler.py", line 149, in is_scheduler_inactive
    if is_scheduler_disabled(verbose=verbose):
       ~~~~~~~~~~~~~~~~~~~~~^^^^^^^^^^^^^^^^^
  File "/Users/saimanikanta/Desktop/ezapp/ez/frappe-bench/apps/frappe/frappe/utils/scheduler.py", line 162, in is_scheduler_disabled
    frappe.db.get_single_value("System Settings", "enable_scheduler")
    ~~~~~~~~~~~~~~~~~~~~~~~~~~^^^^^^^^^^^^^^^^^^^^^^^^^^^^^^^^^^^^^^^
  File "/Users/saimanikanta/Desktop/ezapp/ez/frappe-bench/apps/frappe/frappe/database/database.py", line 869, in get_single_value
    ).run()
      ~~~^^
  File "/Users/saimanikanta/Desktop/ezapp/ez/frappe-bench/apps/frappe/frappe/query_builder/utils.py", line 84, in execute_query
    result = frappe.db.sql(query, params, *args, **kwargs)  # nosemgrep
  File "/Users/saimanikanta/Desktop/ezapp/ez/frappe-bench/apps/frappe/frappe/database/database.py", line 215, in sql
    self.connect()
    ~~~~~~~~~~~~^^
  File "/Users/saimanikanta/Desktop/ezapp/ez/frappe-bench/apps/frappe/frappe/database/database.py", line 120, in connect
    self._conn: MariadbConnection | PostgresConnection = self.get_connection()
                                                         ~~~~~~~~~~~~~~~~~~~^^
  File "/Users/saimanikanta/Desktop/ezapp/ez/frappe-bench/apps/frappe/frappe/database/mariadb/database.py", line 107, in get_connection
    conn = self._get_connection()
  File "/Users/saimanikanta/Desktop/ezapp/ez/frappe-bench/apps/frappe/frappe/database/mariadb/database.py", line 113, in _get_connection
    return self.create_connection()
           ~~~~~~~~~~~~~~~~~~~~~~^^
  File "/Users/saimanikanta/Desktop/ezapp/ez/frappe-bench/apps/frappe/frappe/database/mariadb/database.py", line 116, in create_connection
    return pymysql.connect(**self.get_connection_settings())
           ~~~~~~~~~~~~~~~^^^^^^^^^^^^^^^^^^^^^^^^^^^^^^^^^^
  File "/Users/saimanikanta/Desktop/ezapp/ez/frappe-bench/env/lib/python3.13/site-packages/pymysql/connections.py", line 361, in __init__
    self.connect()
    ~~~~~~~~~~~~^^
  File "/Users/saimanikanta/Desktop/ezapp/ez/frappe-bench/env/lib/python3.13/site-packages/pymysql/connections.py", line 669, in connect
    self._request_authentication()
    ~~~~~~~~~~~~~~~~~~~~~~~~~~~~^^
  File "/Users/saimanikanta/Desktop/ezapp/ez/frappe-bench/env/lib/python3.13/site-packages/pymysql/connections.py", line 957, in _request_authentication
    auth_packet = self._read_packet()
  File "/Users/saimanikanta/Desktop/ezapp/ez/frappe-bench/env/lib/python3.13/site-packages/pymysql/connections.py", line 775, in _read_packet
    packet.raise_for_error()
    ~~~~~~~~~~~~~~~~~~~~~~^^
  File "/Users/saimanikanta/Desktop/ezapp/ez/frappe-bench/env/lib/python3.13/site-packages/pymysql/protocol.py", line 219, in raise_for_error
    err.raise_mysql_exception(self._data)
    ~~~~~~~~~~~~~~~~~~~~~~~~~^^^^^^^^^^^^
  File "/Users/saimanikanta/Desktop/ezapp/ez/frappe-bench/env/lib/python3.13/site-packages/pymysql/err.py", line 150, in raise_mysql_exception
    raise errorclass(errno, errval)
pymysql.err.OperationalError: (1044, "Access denied for user '_7c5f4f77b0d74777'@'localhost' to database 'f77b0d74777_7c5f4'")
2025-02-10 11:18:00,661 ERROR scheduler Exception in Enqueue Events for Site money.test
Traceback (most recent call last):
  File "/Users/saimanikanta/Desktop/ezapp/ez/frappe-bench/apps/frappe/frappe/utils/scheduler.py", line 105, in enqueue_events_for_site
    if is_scheduler_inactive():
       ~~~~~~~~~~~~~~~~~~~~~^^
  File "/Users/saimanikanta/Desktop/ezapp/ez/frappe-bench/apps/frappe/frappe/utils/scheduler.py", line 149, in is_scheduler_inactive
    if is_scheduler_disabled(verbose=verbose):
       ~~~~~~~~~~~~~~~~~~~~~^^^^^^^^^^^^^^^^^
  File "/Users/saimanikanta/Desktop/ezapp/ez/frappe-bench/apps/frappe/frappe/utils/scheduler.py", line 162, in is_scheduler_disabled
    frappe.db.get_single_value("System Settings", "enable_scheduler")
    ~~~~~~~~~~~~~~~~~~~~~~~~~~^^^^^^^^^^^^^^^^^^^^^^^^^^^^^^^^^^^^^^^
  File "/Users/saimanikanta/Desktop/ezapp/ez/frappe-bench/apps/frappe/frappe/database/database.py", line 869, in get_single_value
    ).run()
      ~~~^^
  File "/Users/saimanikanta/Desktop/ezapp/ez/frappe-bench/apps/frappe/frappe/query_builder/utils.py", line 84, in execute_query
    result = frappe.db.sql(query, params, *args, **kwargs)  # nosemgrep
  File "/Users/saimanikanta/Desktop/ezapp/ez/frappe-bench/apps/frappe/frappe/database/database.py", line 215, in sql
    self.connect()
    ~~~~~~~~~~~~^^
  File "/Users/saimanikanta/Desktop/ezapp/ez/frappe-bench/apps/frappe/frappe/database/database.py", line 120, in connect
    self._conn: MariadbConnection | PostgresConnection = self.get_connection()
                                                         ~~~~~~~~~~~~~~~~~~~^^
  File "/Users/saimanikanta/Desktop/ezapp/ez/frappe-bench/apps/frappe/frappe/database/mariadb/database.py", line 107, in get_connection
    conn = self._get_connection()
  File "/Users/saimanikanta/Desktop/ezapp/ez/frappe-bench/apps/frappe/frappe/database/mariadb/database.py", line 113, in _get_connection
    return self.create_connection()
           ~~~~~~~~~~~~~~~~~~~~~~^^
  File "/Users/saimanikanta/Desktop/ezapp/ez/frappe-bench/apps/frappe/frappe/database/mariadb/database.py", line 116, in create_connection
    return pymysql.connect(**self.get_connection_settings())
           ~~~~~~~~~~~~~~~^^^^^^^^^^^^^^^^^^^^^^^^^^^^^^^^^^
  File "/Users/saimanikanta/Desktop/ezapp/ez/frappe-bench/env/lib/python3.13/site-packages/pymysql/connections.py", line 361, in __init__
    self.connect()
    ~~~~~~~~~~~~^^
  File "/Users/saimanikanta/Desktop/ezapp/ez/frappe-bench/env/lib/python3.13/site-packages/pymysql/connections.py", line 669, in connect
    self._request_authentication()
    ~~~~~~~~~~~~~~~~~~~~~~~~~~~~^^
  File "/Users/saimanikanta/Desktop/ezapp/ez/frappe-bench/env/lib/python3.13/site-packages/pymysql/connections.py", line 957, in _request_authentication
    auth_packet = self._read_packet()
  File "/Users/saimanikanta/Desktop/ezapp/ez/frappe-bench/env/lib/python3.13/site-packages/pymysql/connections.py", line 775, in _read_packet
    packet.raise_for_error()
    ~~~~~~~~~~~~~~~~~~~~~~^^
  File "/Users/saimanikanta/Desktop/ezapp/ez/frappe-bench/env/lib/python3.13/site-packages/pymysql/protocol.py", line 219, in raise_for_error
    err.raise_mysql_exception(self._data)
    ~~~~~~~~~~~~~~~~~~~~~~~~~^^^^^^^^^^^^
  File "/Users/saimanikanta/Desktop/ezapp/ez/frappe-bench/env/lib/python3.13/site-packages/pymysql/err.py", line 150, in raise_mysql_exception
    raise errorclass(errno, errval)
pymysql.err.OperationalError: (1044, "Access denied for user '_7c5f4f77b0d74777'@'localhost' to database 'f77b0d74777_7c5f4'")
2025-02-10 11:22:00,733 ERROR scheduler Exception in Enqueue Events for Site money.test
Traceback (most recent call last):
  File "/Users/saimanikanta/Desktop/ezapp/ez/frappe-bench/apps/frappe/frappe/utils/scheduler.py", line 105, in enqueue_events_for_site
    if is_scheduler_inactive():
       ~~~~~~~~~~~~~~~~~~~~~^^
  File "/Users/saimanikanta/Desktop/ezapp/ez/frappe-bench/apps/frappe/frappe/utils/scheduler.py", line 149, in is_scheduler_inactive
    if is_scheduler_disabled(verbose=verbose):
       ~~~~~~~~~~~~~~~~~~~~~^^^^^^^^^^^^^^^^^
  File "/Users/saimanikanta/Desktop/ezapp/ez/frappe-bench/apps/frappe/frappe/utils/scheduler.py", line 162, in is_scheduler_disabled
    frappe.db.get_single_value("System Settings", "enable_scheduler")
    ~~~~~~~~~~~~~~~~~~~~~~~~~~^^^^^^^^^^^^^^^^^^^^^^^^^^^^^^^^^^^^^^^
  File "/Users/saimanikanta/Desktop/ezapp/ez/frappe-bench/apps/frappe/frappe/database/database.py", line 869, in get_single_value
    ).run()
      ~~~^^
  File "/Users/saimanikanta/Desktop/ezapp/ez/frappe-bench/apps/frappe/frappe/query_builder/utils.py", line 84, in execute_query
    result = frappe.db.sql(query, params, *args, **kwargs)  # nosemgrep
  File "/Users/saimanikanta/Desktop/ezapp/ez/frappe-bench/apps/frappe/frappe/database/database.py", line 215, in sql
    self.connect()
    ~~~~~~~~~~~~^^
  File "/Users/saimanikanta/Desktop/ezapp/ez/frappe-bench/apps/frappe/frappe/database/database.py", line 120, in connect
    self._conn: MariadbConnection | PostgresConnection = self.get_connection()
                                                         ~~~~~~~~~~~~~~~~~~~^^
  File "/Users/saimanikanta/Desktop/ezapp/ez/frappe-bench/apps/frappe/frappe/database/mariadb/database.py", line 107, in get_connection
    conn = self._get_connection()
  File "/Users/saimanikanta/Desktop/ezapp/ez/frappe-bench/apps/frappe/frappe/database/mariadb/database.py", line 113, in _get_connection
    return self.create_connection()
           ~~~~~~~~~~~~~~~~~~~~~~^^
  File "/Users/saimanikanta/Desktop/ezapp/ez/frappe-bench/apps/frappe/frappe/database/mariadb/database.py", line 116, in create_connection
    return pymysql.connect(**self.get_connection_settings())
           ~~~~~~~~~~~~~~~^^^^^^^^^^^^^^^^^^^^^^^^^^^^^^^^^^
  File "/Users/saimanikanta/Desktop/ezapp/ez/frappe-bench/env/lib/python3.13/site-packages/pymysql/connections.py", line 361, in __init__
    self.connect()
    ~~~~~~~~~~~~^^
  File "/Users/saimanikanta/Desktop/ezapp/ez/frappe-bench/env/lib/python3.13/site-packages/pymysql/connections.py", line 669, in connect
    self._request_authentication()
    ~~~~~~~~~~~~~~~~~~~~~~~~~~~~^^
  File "/Users/saimanikanta/Desktop/ezapp/ez/frappe-bench/env/lib/python3.13/site-packages/pymysql/connections.py", line 957, in _request_authentication
    auth_packet = self._read_packet()
  File "/Users/saimanikanta/Desktop/ezapp/ez/frappe-bench/env/lib/python3.13/site-packages/pymysql/connections.py", line 775, in _read_packet
    packet.raise_for_error()
    ~~~~~~~~~~~~~~~~~~~~~~^^
  File "/Users/saimanikanta/Desktop/ezapp/ez/frappe-bench/env/lib/python3.13/site-packages/pymysql/protocol.py", line 219, in raise_for_error
    err.raise_mysql_exception(self._data)
    ~~~~~~~~~~~~~~~~~~~~~~~~~^^^^^^^^^^^^
  File "/Users/saimanikanta/Desktop/ezapp/ez/frappe-bench/env/lib/python3.13/site-packages/pymysql/err.py", line 150, in raise_mysql_exception
    raise errorclass(errno, errval)
pymysql.err.OperationalError: (1044, "Access denied for user '_7c5f4f77b0d74777'@'localhost' to database 'f77b0d74777_7c5f4'")
2025-02-10 11:26:00,892 ERROR scheduler Exception in Enqueue Events for Site money.test
Traceback (most recent call last):
  File "/Users/saimanikanta/Desktop/ezapp/ez/frappe-bench/apps/frappe/frappe/utils/scheduler.py", line 105, in enqueue_events_for_site
    if is_scheduler_inactive():
       ~~~~~~~~~~~~~~~~~~~~~^^
  File "/Users/saimanikanta/Desktop/ezapp/ez/frappe-bench/apps/frappe/frappe/utils/scheduler.py", line 149, in is_scheduler_inactive
    if is_scheduler_disabled(verbose=verbose):
       ~~~~~~~~~~~~~~~~~~~~~^^^^^^^^^^^^^^^^^
  File "/Users/saimanikanta/Desktop/ezapp/ez/frappe-bench/apps/frappe/frappe/utils/scheduler.py", line 162, in is_scheduler_disabled
    frappe.db.get_single_value("System Settings", "enable_scheduler")
    ~~~~~~~~~~~~~~~~~~~~~~~~~~^^^^^^^^^^^^^^^^^^^^^^^^^^^^^^^^^^^^^^^
  File "/Users/saimanikanta/Desktop/ezapp/ez/frappe-bench/apps/frappe/frappe/database/database.py", line 869, in get_single_value
    ).run()
      ~~~^^
  File "/Users/saimanikanta/Desktop/ezapp/ez/frappe-bench/apps/frappe/frappe/query_builder/utils.py", line 84, in execute_query
    result = frappe.db.sql(query, params, *args, **kwargs)  # nosemgrep
  File "/Users/saimanikanta/Desktop/ezapp/ez/frappe-bench/apps/frappe/frappe/database/database.py", line 215, in sql
    self.connect()
    ~~~~~~~~~~~~^^
  File "/Users/saimanikanta/Desktop/ezapp/ez/frappe-bench/apps/frappe/frappe/database/database.py", line 120, in connect
    self._conn: MariadbConnection | PostgresConnection = self.get_connection()
                                                         ~~~~~~~~~~~~~~~~~~~^^
  File "/Users/saimanikanta/Desktop/ezapp/ez/frappe-bench/apps/frappe/frappe/database/mariadb/database.py", line 107, in get_connection
    conn = self._get_connection()
  File "/Users/saimanikanta/Desktop/ezapp/ez/frappe-bench/apps/frappe/frappe/database/mariadb/database.py", line 113, in _get_connection
    return self.create_connection()
           ~~~~~~~~~~~~~~~~~~~~~~^^
  File "/Users/saimanikanta/Desktop/ezapp/ez/frappe-bench/apps/frappe/frappe/database/mariadb/database.py", line 116, in create_connection
    return pymysql.connect(**self.get_connection_settings())
           ~~~~~~~~~~~~~~~^^^^^^^^^^^^^^^^^^^^^^^^^^^^^^^^^^
  File "/Users/saimanikanta/Desktop/ezapp/ez/frappe-bench/env/lib/python3.13/site-packages/pymysql/connections.py", line 361, in __init__
    self.connect()
    ~~~~~~~~~~~~^^
  File "/Users/saimanikanta/Desktop/ezapp/ez/frappe-bench/env/lib/python3.13/site-packages/pymysql/connections.py", line 669, in connect
    self._request_authentication()
    ~~~~~~~~~~~~~~~~~~~~~~~~~~~~^^
  File "/Users/saimanikanta/Desktop/ezapp/ez/frappe-bench/env/lib/python3.13/site-packages/pymysql/connections.py", line 957, in _request_authentication
    auth_packet = self._read_packet()
  File "/Users/saimanikanta/Desktop/ezapp/ez/frappe-bench/env/lib/python3.13/site-packages/pymysql/connections.py", line 775, in _read_packet
    packet.raise_for_error()
    ~~~~~~~~~~~~~~~~~~~~~~^^
  File "/Users/saimanikanta/Desktop/ezapp/ez/frappe-bench/env/lib/python3.13/site-packages/pymysql/protocol.py", line 219, in raise_for_error
    err.raise_mysql_exception(self._data)
    ~~~~~~~~~~~~~~~~~~~~~~~~~^^^^^^^^^^^^
  File "/Users/saimanikanta/Desktop/ezapp/ez/frappe-bench/env/lib/python3.13/site-packages/pymysql/err.py", line 150, in raise_mysql_exception
    raise errorclass(errno, errval)
pymysql.err.OperationalError: (1044, "Access denied for user '_7c5f4f77b0d74777'@'localhost' to database 'f77b0d74777_7c5f4'")
2025-02-10 11:30:00,904 ERROR scheduler Exception in Enqueue Events for Site money.test
Traceback (most recent call last):
  File "/Users/saimanikanta/Desktop/ezapp/ez/frappe-bench/apps/frappe/frappe/utils/scheduler.py", line 105, in enqueue_events_for_site
    if is_scheduler_inactive():
       ~~~~~~~~~~~~~~~~~~~~~^^
  File "/Users/saimanikanta/Desktop/ezapp/ez/frappe-bench/apps/frappe/frappe/utils/scheduler.py", line 149, in is_scheduler_inactive
    if is_scheduler_disabled(verbose=verbose):
       ~~~~~~~~~~~~~~~~~~~~~^^^^^^^^^^^^^^^^^
  File "/Users/saimanikanta/Desktop/ezapp/ez/frappe-bench/apps/frappe/frappe/utils/scheduler.py", line 162, in is_scheduler_disabled
    frappe.db.get_single_value("System Settings", "enable_scheduler")
    ~~~~~~~~~~~~~~~~~~~~~~~~~~^^^^^^^^^^^^^^^^^^^^^^^^^^^^^^^^^^^^^^^
  File "/Users/saimanikanta/Desktop/ezapp/ez/frappe-bench/apps/frappe/frappe/database/database.py", line 869, in get_single_value
    ).run()
      ~~~^^
  File "/Users/saimanikanta/Desktop/ezapp/ez/frappe-bench/apps/frappe/frappe/query_builder/utils.py", line 84, in execute_query
    result = frappe.db.sql(query, params, *args, **kwargs)  # nosemgrep
  File "/Users/saimanikanta/Desktop/ezapp/ez/frappe-bench/apps/frappe/frappe/database/database.py", line 215, in sql
    self.connect()
    ~~~~~~~~~~~~^^
  File "/Users/saimanikanta/Desktop/ezapp/ez/frappe-bench/apps/frappe/frappe/database/database.py", line 120, in connect
    self._conn: MariadbConnection | PostgresConnection = self.get_connection()
                                                         ~~~~~~~~~~~~~~~~~~~^^
  File "/Users/saimanikanta/Desktop/ezapp/ez/frappe-bench/apps/frappe/frappe/database/mariadb/database.py", line 107, in get_connection
    conn = self._get_connection()
  File "/Users/saimanikanta/Desktop/ezapp/ez/frappe-bench/apps/frappe/frappe/database/mariadb/database.py", line 113, in _get_connection
    return self.create_connection()
           ~~~~~~~~~~~~~~~~~~~~~~^^
  File "/Users/saimanikanta/Desktop/ezapp/ez/frappe-bench/apps/frappe/frappe/database/mariadb/database.py", line 116, in create_connection
    return pymysql.connect(**self.get_connection_settings())
           ~~~~~~~~~~~~~~~^^^^^^^^^^^^^^^^^^^^^^^^^^^^^^^^^^
  File "/Users/saimanikanta/Desktop/ezapp/ez/frappe-bench/env/lib/python3.13/site-packages/pymysql/connections.py", line 361, in __init__
    self.connect()
    ~~~~~~~~~~~~^^
  File "/Users/saimanikanta/Desktop/ezapp/ez/frappe-bench/env/lib/python3.13/site-packages/pymysql/connections.py", line 669, in connect
    self._request_authentication()
    ~~~~~~~~~~~~~~~~~~~~~~~~~~~~^^
  File "/Users/saimanikanta/Desktop/ezapp/ez/frappe-bench/env/lib/python3.13/site-packages/pymysql/connections.py", line 957, in _request_authentication
    auth_packet = self._read_packet()
  File "/Users/saimanikanta/Desktop/ezapp/ez/frappe-bench/env/lib/python3.13/site-packages/pymysql/connections.py", line 775, in _read_packet
    packet.raise_for_error()
    ~~~~~~~~~~~~~~~~~~~~~~^^
  File "/Users/saimanikanta/Desktop/ezapp/ez/frappe-bench/env/lib/python3.13/site-packages/pymysql/protocol.py", line 219, in raise_for_error
    err.raise_mysql_exception(self._data)
    ~~~~~~~~~~~~~~~~~~~~~~~~~^^^^^^^^^^^^
  File "/Users/saimanikanta/Desktop/ezapp/ez/frappe-bench/env/lib/python3.13/site-packages/pymysql/err.py", line 150, in raise_mysql_exception
    raise errorclass(errno, errval)
pymysql.err.OperationalError: (1044, "Access denied for user '_7c5f4f77b0d74777'@'localhost' to database 'f77b0d74777_7c5f4'")
2025-02-10 11:34:00,970 ERROR scheduler Exception in Enqueue Events for Site money.test
Traceback (most recent call last):
  File "/Users/saimanikanta/Desktop/ezapp/ez/frappe-bench/apps/frappe/frappe/utils/scheduler.py", line 105, in enqueue_events_for_site
    if is_scheduler_inactive():
       ~~~~~~~~~~~~~~~~~~~~~^^
  File "/Users/saimanikanta/Desktop/ezapp/ez/frappe-bench/apps/frappe/frappe/utils/scheduler.py", line 149, in is_scheduler_inactive
    if is_scheduler_disabled(verbose=verbose):
       ~~~~~~~~~~~~~~~~~~~~~^^^^^^^^^^^^^^^^^
  File "/Users/saimanikanta/Desktop/ezapp/ez/frappe-bench/apps/frappe/frappe/utils/scheduler.py", line 162, in is_scheduler_disabled
    frappe.db.get_single_value("System Settings", "enable_scheduler")
    ~~~~~~~~~~~~~~~~~~~~~~~~~~^^^^^^^^^^^^^^^^^^^^^^^^^^^^^^^^^^^^^^^
  File "/Users/saimanikanta/Desktop/ezapp/ez/frappe-bench/apps/frappe/frappe/database/database.py", line 869, in get_single_value
    ).run()
      ~~~^^
  File "/Users/saimanikanta/Desktop/ezapp/ez/frappe-bench/apps/frappe/frappe/query_builder/utils.py", line 84, in execute_query
    result = frappe.db.sql(query, params, *args, **kwargs)  # nosemgrep
  File "/Users/saimanikanta/Desktop/ezapp/ez/frappe-bench/apps/frappe/frappe/database/database.py", line 215, in sql
    self.connect()
    ~~~~~~~~~~~~^^
  File "/Users/saimanikanta/Desktop/ezapp/ez/frappe-bench/apps/frappe/frappe/database/database.py", line 120, in connect
    self._conn: MariadbConnection | PostgresConnection = self.get_connection()
                                                         ~~~~~~~~~~~~~~~~~~~^^
  File "/Users/saimanikanta/Desktop/ezapp/ez/frappe-bench/apps/frappe/frappe/database/mariadb/database.py", line 107, in get_connection
    conn = self._get_connection()
  File "/Users/saimanikanta/Desktop/ezapp/ez/frappe-bench/apps/frappe/frappe/database/mariadb/database.py", line 113, in _get_connection
    return self.create_connection()
           ~~~~~~~~~~~~~~~~~~~~~~^^
  File "/Users/saimanikanta/Desktop/ezapp/ez/frappe-bench/apps/frappe/frappe/database/mariadb/database.py", line 116, in create_connection
    return pymysql.connect(**self.get_connection_settings())
           ~~~~~~~~~~~~~~~^^^^^^^^^^^^^^^^^^^^^^^^^^^^^^^^^^
  File "/Users/saimanikanta/Desktop/ezapp/ez/frappe-bench/env/lib/python3.13/site-packages/pymysql/connections.py", line 361, in __init__
    self.connect()
    ~~~~~~~~~~~~^^
  File "/Users/saimanikanta/Desktop/ezapp/ez/frappe-bench/env/lib/python3.13/site-packages/pymysql/connections.py", line 669, in connect
    self._request_authentication()
    ~~~~~~~~~~~~~~~~~~~~~~~~~~~~^^
  File "/Users/saimanikanta/Desktop/ezapp/ez/frappe-bench/env/lib/python3.13/site-packages/pymysql/connections.py", line 957, in _request_authentication
    auth_packet = self._read_packet()
  File "/Users/saimanikanta/Desktop/ezapp/ez/frappe-bench/env/lib/python3.13/site-packages/pymysql/connections.py", line 775, in _read_packet
    packet.raise_for_error()
    ~~~~~~~~~~~~~~~~~~~~~~^^
  File "/Users/saimanikanta/Desktop/ezapp/ez/frappe-bench/env/lib/python3.13/site-packages/pymysql/protocol.py", line 219, in raise_for_error
    err.raise_mysql_exception(self._data)
    ~~~~~~~~~~~~~~~~~~~~~~~~~^^^^^^^^^^^^
  File "/Users/saimanikanta/Desktop/ezapp/ez/frappe-bench/env/lib/python3.13/site-packages/pymysql/err.py", line 150, in raise_mysql_exception
    raise errorclass(errno, errval)
pymysql.err.OperationalError: (1044, "Access denied for user '_7c5f4f77b0d74777'@'localhost' to database 'f77b0d74777_7c5f4'")
2025-02-10 11:38:00,088 ERROR scheduler Exception in Enqueue Events for Site money.test
Traceback (most recent call last):
  File "/Users/saimanikanta/Desktop/ezapp/ez/frappe-bench/apps/frappe/frappe/utils/scheduler.py", line 105, in enqueue_events_for_site
    if is_scheduler_inactive():
       ~~~~~~~~~~~~~~~~~~~~~^^
  File "/Users/saimanikanta/Desktop/ezapp/ez/frappe-bench/apps/frappe/frappe/utils/scheduler.py", line 149, in is_scheduler_inactive
    if is_scheduler_disabled(verbose=verbose):
       ~~~~~~~~~~~~~~~~~~~~~^^^^^^^^^^^^^^^^^
  File "/Users/saimanikanta/Desktop/ezapp/ez/frappe-bench/apps/frappe/frappe/utils/scheduler.py", line 162, in is_scheduler_disabled
    frappe.db.get_single_value("System Settings", "enable_scheduler")
    ~~~~~~~~~~~~~~~~~~~~~~~~~~^^^^^^^^^^^^^^^^^^^^^^^^^^^^^^^^^^^^^^^
  File "/Users/saimanikanta/Desktop/ezapp/ez/frappe-bench/apps/frappe/frappe/database/database.py", line 869, in get_single_value
    ).run()
      ~~~^^
  File "/Users/saimanikanta/Desktop/ezapp/ez/frappe-bench/apps/frappe/frappe/query_builder/utils.py", line 84, in execute_query
    result = frappe.db.sql(query, params, *args, **kwargs)  # nosemgrep
  File "/Users/saimanikanta/Desktop/ezapp/ez/frappe-bench/apps/frappe/frappe/database/database.py", line 215, in sql
    self.connect()
    ~~~~~~~~~~~~^^
  File "/Users/saimanikanta/Desktop/ezapp/ez/frappe-bench/apps/frappe/frappe/database/database.py", line 120, in connect
    self._conn: MariadbConnection | PostgresConnection = self.get_connection()
                                                         ~~~~~~~~~~~~~~~~~~~^^
  File "/Users/saimanikanta/Desktop/ezapp/ez/frappe-bench/apps/frappe/frappe/database/mariadb/database.py", line 107, in get_connection
    conn = self._get_connection()
  File "/Users/saimanikanta/Desktop/ezapp/ez/frappe-bench/apps/frappe/frappe/database/mariadb/database.py", line 113, in _get_connection
    return self.create_connection()
           ~~~~~~~~~~~~~~~~~~~~~~^^
  File "/Users/saimanikanta/Desktop/ezapp/ez/frappe-bench/apps/frappe/frappe/database/mariadb/database.py", line 116, in create_connection
    return pymysql.connect(**self.get_connection_settings())
           ~~~~~~~~~~~~~~~^^^^^^^^^^^^^^^^^^^^^^^^^^^^^^^^^^
  File "/Users/saimanikanta/Desktop/ezapp/ez/frappe-bench/env/lib/python3.13/site-packages/pymysql/connections.py", line 361, in __init__
    self.connect()
    ~~~~~~~~~~~~^^
  File "/Users/saimanikanta/Desktop/ezapp/ez/frappe-bench/env/lib/python3.13/site-packages/pymysql/connections.py", line 669, in connect
    self._request_authentication()
    ~~~~~~~~~~~~~~~~~~~~~~~~~~~~^^
  File "/Users/saimanikanta/Desktop/ezapp/ez/frappe-bench/env/lib/python3.13/site-packages/pymysql/connections.py", line 957, in _request_authentication
    auth_packet = self._read_packet()
  File "/Users/saimanikanta/Desktop/ezapp/ez/frappe-bench/env/lib/python3.13/site-packages/pymysql/connections.py", line 775, in _read_packet
    packet.raise_for_error()
    ~~~~~~~~~~~~~~~~~~~~~~^^
  File "/Users/saimanikanta/Desktop/ezapp/ez/frappe-bench/env/lib/python3.13/site-packages/pymysql/protocol.py", line 219, in raise_for_error
    err.raise_mysql_exception(self._data)
    ~~~~~~~~~~~~~~~~~~~~~~~~~^^^^^^^^^^^^
  File "/Users/saimanikanta/Desktop/ezapp/ez/frappe-bench/env/lib/python3.13/site-packages/pymysql/err.py", line 150, in raise_mysql_exception
    raise errorclass(errno, errval)
pymysql.err.OperationalError: (1044, "Access denied for user '_7c5f4f77b0d74777'@'localhost' to database 'f77b0d74777_7c5f4'")
2025-02-10 11:42:00,190 ERROR scheduler Exception in Enqueue Events for Site money.test
Traceback (most recent call last):
  File "/Users/saimanikanta/Desktop/ezapp/ez/frappe-bench/apps/frappe/frappe/utils/scheduler.py", line 105, in enqueue_events_for_site
    if is_scheduler_inactive():
       ~~~~~~~~~~~~~~~~~~~~~^^
  File "/Users/saimanikanta/Desktop/ezapp/ez/frappe-bench/apps/frappe/frappe/utils/scheduler.py", line 149, in is_scheduler_inactive
    if is_scheduler_disabled(verbose=verbose):
       ~~~~~~~~~~~~~~~~~~~~~^^^^^^^^^^^^^^^^^
  File "/Users/saimanikanta/Desktop/ezapp/ez/frappe-bench/apps/frappe/frappe/utils/scheduler.py", line 162, in is_scheduler_disabled
    frappe.db.get_single_value("System Settings", "enable_scheduler")
    ~~~~~~~~~~~~~~~~~~~~~~~~~~^^^^^^^^^^^^^^^^^^^^^^^^^^^^^^^^^^^^^^^
  File "/Users/saimanikanta/Desktop/ezapp/ez/frappe-bench/apps/frappe/frappe/database/database.py", line 869, in get_single_value
    ).run()
      ~~~^^
  File "/Users/saimanikanta/Desktop/ezapp/ez/frappe-bench/apps/frappe/frappe/query_builder/utils.py", line 84, in execute_query
    result = frappe.db.sql(query, params, *args, **kwargs)  # nosemgrep
  File "/Users/saimanikanta/Desktop/ezapp/ez/frappe-bench/apps/frappe/frappe/database/database.py", line 215, in sql
    self.connect()
    ~~~~~~~~~~~~^^
  File "/Users/saimanikanta/Desktop/ezapp/ez/frappe-bench/apps/frappe/frappe/database/database.py", line 120, in connect
    self._conn: MariadbConnection | PostgresConnection = self.get_connection()
                                                         ~~~~~~~~~~~~~~~~~~~^^
  File "/Users/saimanikanta/Desktop/ezapp/ez/frappe-bench/apps/frappe/frappe/database/mariadb/database.py", line 107, in get_connection
    conn = self._get_connection()
  File "/Users/saimanikanta/Desktop/ezapp/ez/frappe-bench/apps/frappe/frappe/database/mariadb/database.py", line 113, in _get_connection
    return self.create_connection()
           ~~~~~~~~~~~~~~~~~~~~~~^^
  File "/Users/saimanikanta/Desktop/ezapp/ez/frappe-bench/apps/frappe/frappe/database/mariadb/database.py", line 116, in create_connection
    return pymysql.connect(**self.get_connection_settings())
           ~~~~~~~~~~~~~~~^^^^^^^^^^^^^^^^^^^^^^^^^^^^^^^^^^
  File "/Users/saimanikanta/Desktop/ezapp/ez/frappe-bench/env/lib/python3.13/site-packages/pymysql/connections.py", line 361, in __init__
    self.connect()
    ~~~~~~~~~~~~^^
  File "/Users/saimanikanta/Desktop/ezapp/ez/frappe-bench/env/lib/python3.13/site-packages/pymysql/connections.py", line 669, in connect
    self._request_authentication()
    ~~~~~~~~~~~~~~~~~~~~~~~~~~~~^^
  File "/Users/saimanikanta/Desktop/ezapp/ez/frappe-bench/env/lib/python3.13/site-packages/pymysql/connections.py", line 957, in _request_authentication
    auth_packet = self._read_packet()
  File "/Users/saimanikanta/Desktop/ezapp/ez/frappe-bench/env/lib/python3.13/site-packages/pymysql/connections.py", line 775, in _read_packet
    packet.raise_for_error()
    ~~~~~~~~~~~~~~~~~~~~~~^^
  File "/Users/saimanikanta/Desktop/ezapp/ez/frappe-bench/env/lib/python3.13/site-packages/pymysql/protocol.py", line 219, in raise_for_error
    err.raise_mysql_exception(self._data)
    ~~~~~~~~~~~~~~~~~~~~~~~~~^^^^^^^^^^^^
  File "/Users/saimanikanta/Desktop/ezapp/ez/frappe-bench/env/lib/python3.13/site-packages/pymysql/err.py", line 150, in raise_mysql_exception
    raise errorclass(errno, errval)
pymysql.err.OperationalError: (1044, "Access denied for user '_7c5f4f77b0d74777'@'localhost' to database 'f77b0d74777_7c5f4'")
2025-02-10 11:46:00,220 ERROR scheduler Exception in Enqueue Events for Site money.test
Traceback (most recent call last):
  File "/Users/saimanikanta/Desktop/ezapp/ez/frappe-bench/apps/frappe/frappe/utils/scheduler.py", line 105, in enqueue_events_for_site
    if is_scheduler_inactive():
       ~~~~~~~~~~~~~~~~~~~~~^^
  File "/Users/saimanikanta/Desktop/ezapp/ez/frappe-bench/apps/frappe/frappe/utils/scheduler.py", line 149, in is_scheduler_inactive
    if is_scheduler_disabled(verbose=verbose):
       ~~~~~~~~~~~~~~~~~~~~~^^^^^^^^^^^^^^^^^
  File "/Users/saimanikanta/Desktop/ezapp/ez/frappe-bench/apps/frappe/frappe/utils/scheduler.py", line 162, in is_scheduler_disabled
    frappe.db.get_single_value("System Settings", "enable_scheduler")
    ~~~~~~~~~~~~~~~~~~~~~~~~~~^^^^^^^^^^^^^^^^^^^^^^^^^^^^^^^^^^^^^^^
  File "/Users/saimanikanta/Desktop/ezapp/ez/frappe-bench/apps/frappe/frappe/database/database.py", line 869, in get_single_value
    ).run()
      ~~~^^
  File "/Users/saimanikanta/Desktop/ezapp/ez/frappe-bench/apps/frappe/frappe/query_builder/utils.py", line 84, in execute_query
    result = frappe.db.sql(query, params, *args, **kwargs)  # nosemgrep
  File "/Users/saimanikanta/Desktop/ezapp/ez/frappe-bench/apps/frappe/frappe/database/database.py", line 215, in sql
    self.connect()
    ~~~~~~~~~~~~^^
  File "/Users/saimanikanta/Desktop/ezapp/ez/frappe-bench/apps/frappe/frappe/database/database.py", line 120, in connect
    self._conn: MariadbConnection | PostgresConnection = self.get_connection()
                                                         ~~~~~~~~~~~~~~~~~~~^^
  File "/Users/saimanikanta/Desktop/ezapp/ez/frappe-bench/apps/frappe/frappe/database/mariadb/database.py", line 107, in get_connection
    conn = self._get_connection()
  File "/Users/saimanikanta/Desktop/ezapp/ez/frappe-bench/apps/frappe/frappe/database/mariadb/database.py", line 113, in _get_connection
    return self.create_connection()
           ~~~~~~~~~~~~~~~~~~~~~~^^
  File "/Users/saimanikanta/Desktop/ezapp/ez/frappe-bench/apps/frappe/frappe/database/mariadb/database.py", line 116, in create_connection
    return pymysql.connect(**self.get_connection_settings())
           ~~~~~~~~~~~~~~~^^^^^^^^^^^^^^^^^^^^^^^^^^^^^^^^^^
  File "/Users/saimanikanta/Desktop/ezapp/ez/frappe-bench/env/lib/python3.13/site-packages/pymysql/connections.py", line 361, in __init__
    self.connect()
    ~~~~~~~~~~~~^^
  File "/Users/saimanikanta/Desktop/ezapp/ez/frappe-bench/env/lib/python3.13/site-packages/pymysql/connections.py", line 669, in connect
    self._request_authentication()
    ~~~~~~~~~~~~~~~~~~~~~~~~~~~~^^
  File "/Users/saimanikanta/Desktop/ezapp/ez/frappe-bench/env/lib/python3.13/site-packages/pymysql/connections.py", line 957, in _request_authentication
    auth_packet = self._read_packet()
  File "/Users/saimanikanta/Desktop/ezapp/ez/frappe-bench/env/lib/python3.13/site-packages/pymysql/connections.py", line 775, in _read_packet
    packet.raise_for_error()
    ~~~~~~~~~~~~~~~~~~~~~~^^
  File "/Users/saimanikanta/Desktop/ezapp/ez/frappe-bench/env/lib/python3.13/site-packages/pymysql/protocol.py", line 219, in raise_for_error
    err.raise_mysql_exception(self._data)
    ~~~~~~~~~~~~~~~~~~~~~~~~~^^^^^^^^^^^^
  File "/Users/saimanikanta/Desktop/ezapp/ez/frappe-bench/env/lib/python3.13/site-packages/pymysql/err.py", line 150, in raise_mysql_exception
    raise errorclass(errno, errval)
pymysql.err.OperationalError: (1044, "Access denied for user '_7c5f4f77b0d74777'@'localhost' to database 'f77b0d74777_7c5f4'")
2025-02-10 11:50:00,290 ERROR scheduler Exception in Enqueue Events for Site money.test
Traceback (most recent call last):
  File "/Users/saimanikanta/Desktop/ezapp/ez/frappe-bench/apps/frappe/frappe/utils/scheduler.py", line 105, in enqueue_events_for_site
    if is_scheduler_inactive():
       ~~~~~~~~~~~~~~~~~~~~~^^
  File "/Users/saimanikanta/Desktop/ezapp/ez/frappe-bench/apps/frappe/frappe/utils/scheduler.py", line 149, in is_scheduler_inactive
    if is_scheduler_disabled(verbose=verbose):
       ~~~~~~~~~~~~~~~~~~~~~^^^^^^^^^^^^^^^^^
  File "/Users/saimanikanta/Desktop/ezapp/ez/frappe-bench/apps/frappe/frappe/utils/scheduler.py", line 162, in is_scheduler_disabled
    frappe.db.get_single_value("System Settings", "enable_scheduler")
    ~~~~~~~~~~~~~~~~~~~~~~~~~~^^^^^^^^^^^^^^^^^^^^^^^^^^^^^^^^^^^^^^^
  File "/Users/saimanikanta/Desktop/ezapp/ez/frappe-bench/apps/frappe/frappe/database/database.py", line 869, in get_single_value
    ).run()
      ~~~^^
  File "/Users/saimanikanta/Desktop/ezapp/ez/frappe-bench/apps/frappe/frappe/query_builder/utils.py", line 84, in execute_query
    result = frappe.db.sql(query, params, *args, **kwargs)  # nosemgrep
  File "/Users/saimanikanta/Desktop/ezapp/ez/frappe-bench/apps/frappe/frappe/database/database.py", line 215, in sql
    self.connect()
    ~~~~~~~~~~~~^^
  File "/Users/saimanikanta/Desktop/ezapp/ez/frappe-bench/apps/frappe/frappe/database/database.py", line 120, in connect
    self._conn: MariadbConnection | PostgresConnection = self.get_connection()
                                                         ~~~~~~~~~~~~~~~~~~~^^
  File "/Users/saimanikanta/Desktop/ezapp/ez/frappe-bench/apps/frappe/frappe/database/mariadb/database.py", line 107, in get_connection
    conn = self._get_connection()
  File "/Users/saimanikanta/Desktop/ezapp/ez/frappe-bench/apps/frappe/frappe/database/mariadb/database.py", line 113, in _get_connection
    return self.create_connection()
           ~~~~~~~~~~~~~~~~~~~~~~^^
  File "/Users/saimanikanta/Desktop/ezapp/ez/frappe-bench/apps/frappe/frappe/database/mariadb/database.py", line 116, in create_connection
    return pymysql.connect(**self.get_connection_settings())
           ~~~~~~~~~~~~~~~^^^^^^^^^^^^^^^^^^^^^^^^^^^^^^^^^^
  File "/Users/saimanikanta/Desktop/ezapp/ez/frappe-bench/env/lib/python3.13/site-packages/pymysql/connections.py", line 361, in __init__
    self.connect()
    ~~~~~~~~~~~~^^
  File "/Users/saimanikanta/Desktop/ezapp/ez/frappe-bench/env/lib/python3.13/site-packages/pymysql/connections.py", line 669, in connect
    self._request_authentication()
    ~~~~~~~~~~~~~~~~~~~~~~~~~~~~^^
  File "/Users/saimanikanta/Desktop/ezapp/ez/frappe-bench/env/lib/python3.13/site-packages/pymysql/connections.py", line 957, in _request_authentication
    auth_packet = self._read_packet()
  File "/Users/saimanikanta/Desktop/ezapp/ez/frappe-bench/env/lib/python3.13/site-packages/pymysql/connections.py", line 775, in _read_packet
    packet.raise_for_error()
    ~~~~~~~~~~~~~~~~~~~~~~^^
  File "/Users/saimanikanta/Desktop/ezapp/ez/frappe-bench/env/lib/python3.13/site-packages/pymysql/protocol.py", line 219, in raise_for_error
    err.raise_mysql_exception(self._data)
    ~~~~~~~~~~~~~~~~~~~~~~~~~^^^^^^^^^^^^
  File "/Users/saimanikanta/Desktop/ezapp/ez/frappe-bench/env/lib/python3.13/site-packages/pymysql/err.py", line 150, in raise_mysql_exception
    raise errorclass(errno, errval)
pymysql.err.OperationalError: (1044, "Access denied for user '_7c5f4f77b0d74777'@'localhost' to database 'f77b0d74777_7c5f4'")
2025-02-10 11:54:00,359 ERROR scheduler Exception in Enqueue Events for Site money.test
Traceback (most recent call last):
  File "/Users/saimanikanta/Desktop/ezapp/ez/frappe-bench/apps/frappe/frappe/utils/scheduler.py", line 105, in enqueue_events_for_site
    if is_scheduler_inactive():
       ~~~~~~~~~~~~~~~~~~~~~^^
  File "/Users/saimanikanta/Desktop/ezapp/ez/frappe-bench/apps/frappe/frappe/utils/scheduler.py", line 149, in is_scheduler_inactive
    if is_scheduler_disabled(verbose=verbose):
       ~~~~~~~~~~~~~~~~~~~~~^^^^^^^^^^^^^^^^^
  File "/Users/saimanikanta/Desktop/ezapp/ez/frappe-bench/apps/frappe/frappe/utils/scheduler.py", line 162, in is_scheduler_disabled
    frappe.db.get_single_value("System Settings", "enable_scheduler")
    ~~~~~~~~~~~~~~~~~~~~~~~~~~^^^^^^^^^^^^^^^^^^^^^^^^^^^^^^^^^^^^^^^
  File "/Users/saimanikanta/Desktop/ezapp/ez/frappe-bench/apps/frappe/frappe/database/database.py", line 869, in get_single_value
    ).run()
      ~~~^^
  File "/Users/saimanikanta/Desktop/ezapp/ez/frappe-bench/apps/frappe/frappe/query_builder/utils.py", line 84, in execute_query
    result = frappe.db.sql(query, params, *args, **kwargs)  # nosemgrep
  File "/Users/saimanikanta/Desktop/ezapp/ez/frappe-bench/apps/frappe/frappe/database/database.py", line 215, in sql
    self.connect()
    ~~~~~~~~~~~~^^
  File "/Users/saimanikanta/Desktop/ezapp/ez/frappe-bench/apps/frappe/frappe/database/database.py", line 120, in connect
    self._conn: MariadbConnection | PostgresConnection = self.get_connection()
                                                         ~~~~~~~~~~~~~~~~~~~^^
  File "/Users/saimanikanta/Desktop/ezapp/ez/frappe-bench/apps/frappe/frappe/database/mariadb/database.py", line 107, in get_connection
    conn = self._get_connection()
  File "/Users/saimanikanta/Desktop/ezapp/ez/frappe-bench/apps/frappe/frappe/database/mariadb/database.py", line 113, in _get_connection
    return self.create_connection()
           ~~~~~~~~~~~~~~~~~~~~~~^^
  File "/Users/saimanikanta/Desktop/ezapp/ez/frappe-bench/apps/frappe/frappe/database/mariadb/database.py", line 116, in create_connection
    return pymysql.connect(**self.get_connection_settings())
           ~~~~~~~~~~~~~~~^^^^^^^^^^^^^^^^^^^^^^^^^^^^^^^^^^
  File "/Users/saimanikanta/Desktop/ezapp/ez/frappe-bench/env/lib/python3.13/site-packages/pymysql/connections.py", line 361, in __init__
    self.connect()
    ~~~~~~~~~~~~^^
  File "/Users/saimanikanta/Desktop/ezapp/ez/frappe-bench/env/lib/python3.13/site-packages/pymysql/connections.py", line 669, in connect
    self._request_authentication()
    ~~~~~~~~~~~~~~~~~~~~~~~~~~~~^^
  File "/Users/saimanikanta/Desktop/ezapp/ez/frappe-bench/env/lib/python3.13/site-packages/pymysql/connections.py", line 957, in _request_authentication
    auth_packet = self._read_packet()
  File "/Users/saimanikanta/Desktop/ezapp/ez/frappe-bench/env/lib/python3.13/site-packages/pymysql/connections.py", line 775, in _read_packet
    packet.raise_for_error()
    ~~~~~~~~~~~~~~~~~~~~~~^^
  File "/Users/saimanikanta/Desktop/ezapp/ez/frappe-bench/env/lib/python3.13/site-packages/pymysql/protocol.py", line 219, in raise_for_error
    err.raise_mysql_exception(self._data)
    ~~~~~~~~~~~~~~~~~~~~~~~~~^^^^^^^^^^^^
  File "/Users/saimanikanta/Desktop/ezapp/ez/frappe-bench/env/lib/python3.13/site-packages/pymysql/err.py", line 150, in raise_mysql_exception
    raise errorclass(errno, errval)
pymysql.err.OperationalError: (1044, "Access denied for user '_7c5f4f77b0d74777'@'localhost' to database 'f77b0d74777_7c5f4'")
2025-02-10 11:58:00,421 ERROR scheduler Exception in Enqueue Events for Site money.test
Traceback (most recent call last):
  File "/Users/saimanikanta/Desktop/ezapp/ez/frappe-bench/apps/frappe/frappe/utils/scheduler.py", line 105, in enqueue_events_for_site
    if is_scheduler_inactive():
       ~~~~~~~~~~~~~~~~~~~~~^^
  File "/Users/saimanikanta/Desktop/ezapp/ez/frappe-bench/apps/frappe/frappe/utils/scheduler.py", line 149, in is_scheduler_inactive
    if is_scheduler_disabled(verbose=verbose):
       ~~~~~~~~~~~~~~~~~~~~~^^^^^^^^^^^^^^^^^
  File "/Users/saimanikanta/Desktop/ezapp/ez/frappe-bench/apps/frappe/frappe/utils/scheduler.py", line 162, in is_scheduler_disabled
    frappe.db.get_single_value("System Settings", "enable_scheduler")
    ~~~~~~~~~~~~~~~~~~~~~~~~~~^^^^^^^^^^^^^^^^^^^^^^^^^^^^^^^^^^^^^^^
  File "/Users/saimanikanta/Desktop/ezapp/ez/frappe-bench/apps/frappe/frappe/database/database.py", line 869, in get_single_value
    ).run()
      ~~~^^
  File "/Users/saimanikanta/Desktop/ezapp/ez/frappe-bench/apps/frappe/frappe/query_builder/utils.py", line 84, in execute_query
    result = frappe.db.sql(query, params, *args, **kwargs)  # nosemgrep
  File "/Users/saimanikanta/Desktop/ezapp/ez/frappe-bench/apps/frappe/frappe/database/database.py", line 215, in sql
    self.connect()
    ~~~~~~~~~~~~^^
  File "/Users/saimanikanta/Desktop/ezapp/ez/frappe-bench/apps/frappe/frappe/database/database.py", line 120, in connect
    self._conn: MariadbConnection | PostgresConnection = self.get_connection()
                                                         ~~~~~~~~~~~~~~~~~~~^^
  File "/Users/saimanikanta/Desktop/ezapp/ez/frappe-bench/apps/frappe/frappe/database/mariadb/database.py", line 107, in get_connection
    conn = self._get_connection()
  File "/Users/saimanikanta/Desktop/ezapp/ez/frappe-bench/apps/frappe/frappe/database/mariadb/database.py", line 113, in _get_connection
    return self.create_connection()
           ~~~~~~~~~~~~~~~~~~~~~~^^
  File "/Users/saimanikanta/Desktop/ezapp/ez/frappe-bench/apps/frappe/frappe/database/mariadb/database.py", line 116, in create_connection
    return pymysql.connect(**self.get_connection_settings())
           ~~~~~~~~~~~~~~~^^^^^^^^^^^^^^^^^^^^^^^^^^^^^^^^^^
  File "/Users/saimanikanta/Desktop/ezapp/ez/frappe-bench/env/lib/python3.13/site-packages/pymysql/connections.py", line 361, in __init__
    self.connect()
    ~~~~~~~~~~~~^^
  File "/Users/saimanikanta/Desktop/ezapp/ez/frappe-bench/env/lib/python3.13/site-packages/pymysql/connections.py", line 669, in connect
    self._request_authentication()
    ~~~~~~~~~~~~~~~~~~~~~~~~~~~~^^
  File "/Users/saimanikanta/Desktop/ezapp/ez/frappe-bench/env/lib/python3.13/site-packages/pymysql/connections.py", line 957, in _request_authentication
    auth_packet = self._read_packet()
  File "/Users/saimanikanta/Desktop/ezapp/ez/frappe-bench/env/lib/python3.13/site-packages/pymysql/connections.py", line 775, in _read_packet
    packet.raise_for_error()
    ~~~~~~~~~~~~~~~~~~~~~~^^
  File "/Users/saimanikanta/Desktop/ezapp/ez/frappe-bench/env/lib/python3.13/site-packages/pymysql/protocol.py", line 219, in raise_for_error
    err.raise_mysql_exception(self._data)
    ~~~~~~~~~~~~~~~~~~~~~~~~~^^^^^^^^^^^^
  File "/Users/saimanikanta/Desktop/ezapp/ez/frappe-bench/env/lib/python3.13/site-packages/pymysql/err.py", line 150, in raise_mysql_exception
    raise errorclass(errno, errval)
pymysql.err.OperationalError: (1044, "Access denied for user '_7c5f4f77b0d74777'@'localhost' to database 'f77b0d74777_7c5f4'")
2025-02-10 12:02:00,493 ERROR scheduler Exception in Enqueue Events for Site money.test
Traceback (most recent call last):
  File "/Users/saimanikanta/Desktop/ezapp/ez/frappe-bench/apps/frappe/frappe/utils/scheduler.py", line 105, in enqueue_events_for_site
    if is_scheduler_inactive():
       ~~~~~~~~~~~~~~~~~~~~~^^
  File "/Users/saimanikanta/Desktop/ezapp/ez/frappe-bench/apps/frappe/frappe/utils/scheduler.py", line 149, in is_scheduler_inactive
    if is_scheduler_disabled(verbose=verbose):
       ~~~~~~~~~~~~~~~~~~~~~^^^^^^^^^^^^^^^^^
  File "/Users/saimanikanta/Desktop/ezapp/ez/frappe-bench/apps/frappe/frappe/utils/scheduler.py", line 162, in is_scheduler_disabled
    frappe.db.get_single_value("System Settings", "enable_scheduler")
    ~~~~~~~~~~~~~~~~~~~~~~~~~~^^^^^^^^^^^^^^^^^^^^^^^^^^^^^^^^^^^^^^^
  File "/Users/saimanikanta/Desktop/ezapp/ez/frappe-bench/apps/frappe/frappe/database/database.py", line 869, in get_single_value
    ).run()
      ~~~^^
  File "/Users/saimanikanta/Desktop/ezapp/ez/frappe-bench/apps/frappe/frappe/query_builder/utils.py", line 84, in execute_query
    result = frappe.db.sql(query, params, *args, **kwargs)  # nosemgrep
  File "/Users/saimanikanta/Desktop/ezapp/ez/frappe-bench/apps/frappe/frappe/database/database.py", line 215, in sql
    self.connect()
    ~~~~~~~~~~~~^^
  File "/Users/saimanikanta/Desktop/ezapp/ez/frappe-bench/apps/frappe/frappe/database/database.py", line 120, in connect
    self._conn: MariadbConnection | PostgresConnection = self.get_connection()
                                                         ~~~~~~~~~~~~~~~~~~~^^
  File "/Users/saimanikanta/Desktop/ezapp/ez/frappe-bench/apps/frappe/frappe/database/mariadb/database.py", line 107, in get_connection
    conn = self._get_connection()
  File "/Users/saimanikanta/Desktop/ezapp/ez/frappe-bench/apps/frappe/frappe/database/mariadb/database.py", line 113, in _get_connection
    return self.create_connection()
           ~~~~~~~~~~~~~~~~~~~~~~^^
  File "/Users/saimanikanta/Desktop/ezapp/ez/frappe-bench/apps/frappe/frappe/database/mariadb/database.py", line 116, in create_connection
    return pymysql.connect(**self.get_connection_settings())
           ~~~~~~~~~~~~~~~^^^^^^^^^^^^^^^^^^^^^^^^^^^^^^^^^^
  File "/Users/saimanikanta/Desktop/ezapp/ez/frappe-bench/env/lib/python3.13/site-packages/pymysql/connections.py", line 361, in __init__
    self.connect()
    ~~~~~~~~~~~~^^
  File "/Users/saimanikanta/Desktop/ezapp/ez/frappe-bench/env/lib/python3.13/site-packages/pymysql/connections.py", line 669, in connect
    self._request_authentication()
    ~~~~~~~~~~~~~~~~~~~~~~~~~~~~^^
  File "/Users/saimanikanta/Desktop/ezapp/ez/frappe-bench/env/lib/python3.13/site-packages/pymysql/connections.py", line 957, in _request_authentication
    auth_packet = self._read_packet()
  File "/Users/saimanikanta/Desktop/ezapp/ez/frappe-bench/env/lib/python3.13/site-packages/pymysql/connections.py", line 775, in _read_packet
    packet.raise_for_error()
    ~~~~~~~~~~~~~~~~~~~~~~^^
  File "/Users/saimanikanta/Desktop/ezapp/ez/frappe-bench/env/lib/python3.13/site-packages/pymysql/protocol.py", line 219, in raise_for_error
    err.raise_mysql_exception(self._data)
    ~~~~~~~~~~~~~~~~~~~~~~~~~^^^^^^^^^^^^
  File "/Users/saimanikanta/Desktop/ezapp/ez/frappe-bench/env/lib/python3.13/site-packages/pymysql/err.py", line 150, in raise_mysql_exception
    raise errorclass(errno, errval)
pymysql.err.OperationalError: (1044, "Access denied for user '_7c5f4f77b0d74777'@'localhost' to database 'f77b0d74777_7c5f4'")
2025-02-10 12:06:00,572 ERROR scheduler Exception in Enqueue Events for Site money.test
Traceback (most recent call last):
  File "/Users/saimanikanta/Desktop/ezapp/ez/frappe-bench/apps/frappe/frappe/utils/scheduler.py", line 105, in enqueue_events_for_site
    if is_scheduler_inactive():
       ~~~~~~~~~~~~~~~~~~~~~^^
  File "/Users/saimanikanta/Desktop/ezapp/ez/frappe-bench/apps/frappe/frappe/utils/scheduler.py", line 149, in is_scheduler_inactive
    if is_scheduler_disabled(verbose=verbose):
       ~~~~~~~~~~~~~~~~~~~~~^^^^^^^^^^^^^^^^^
  File "/Users/saimanikanta/Desktop/ezapp/ez/frappe-bench/apps/frappe/frappe/utils/scheduler.py", line 162, in is_scheduler_disabled
    frappe.db.get_single_value("System Settings", "enable_scheduler")
    ~~~~~~~~~~~~~~~~~~~~~~~~~~^^^^^^^^^^^^^^^^^^^^^^^^^^^^^^^^^^^^^^^
  File "/Users/saimanikanta/Desktop/ezapp/ez/frappe-bench/apps/frappe/frappe/database/database.py", line 869, in get_single_value
    ).run()
      ~~~^^
  File "/Users/saimanikanta/Desktop/ezapp/ez/frappe-bench/apps/frappe/frappe/query_builder/utils.py", line 84, in execute_query
    result = frappe.db.sql(query, params, *args, **kwargs)  # nosemgrep
  File "/Users/saimanikanta/Desktop/ezapp/ez/frappe-bench/apps/frappe/frappe/database/database.py", line 215, in sql
    self.connect()
    ~~~~~~~~~~~~^^
  File "/Users/saimanikanta/Desktop/ezapp/ez/frappe-bench/apps/frappe/frappe/database/database.py", line 120, in connect
    self._conn: MariadbConnection | PostgresConnection = self.get_connection()
                                                         ~~~~~~~~~~~~~~~~~~~^^
  File "/Users/saimanikanta/Desktop/ezapp/ez/frappe-bench/apps/frappe/frappe/database/mariadb/database.py", line 107, in get_connection
    conn = self._get_connection()
  File "/Users/saimanikanta/Desktop/ezapp/ez/frappe-bench/apps/frappe/frappe/database/mariadb/database.py", line 113, in _get_connection
    return self.create_connection()
           ~~~~~~~~~~~~~~~~~~~~~~^^
  File "/Users/saimanikanta/Desktop/ezapp/ez/frappe-bench/apps/frappe/frappe/database/mariadb/database.py", line 116, in create_connection
    return pymysql.connect(**self.get_connection_settings())
           ~~~~~~~~~~~~~~~^^^^^^^^^^^^^^^^^^^^^^^^^^^^^^^^^^
  File "/Users/saimanikanta/Desktop/ezapp/ez/frappe-bench/env/lib/python3.13/site-packages/pymysql/connections.py", line 361, in __init__
    self.connect()
    ~~~~~~~~~~~~^^
  File "/Users/saimanikanta/Desktop/ezapp/ez/frappe-bench/env/lib/python3.13/site-packages/pymysql/connections.py", line 669, in connect
    self._request_authentication()
    ~~~~~~~~~~~~~~~~~~~~~~~~~~~~^^
  File "/Users/saimanikanta/Desktop/ezapp/ez/frappe-bench/env/lib/python3.13/site-packages/pymysql/connections.py", line 957, in _request_authentication
    auth_packet = self._read_packet()
  File "/Users/saimanikanta/Desktop/ezapp/ez/frappe-bench/env/lib/python3.13/site-packages/pymysql/connections.py", line 775, in _read_packet
    packet.raise_for_error()
    ~~~~~~~~~~~~~~~~~~~~~~^^
  File "/Users/saimanikanta/Desktop/ezapp/ez/frappe-bench/env/lib/python3.13/site-packages/pymysql/protocol.py", line 219, in raise_for_error
    err.raise_mysql_exception(self._data)
    ~~~~~~~~~~~~~~~~~~~~~~~~~^^^^^^^^^^^^
  File "/Users/saimanikanta/Desktop/ezapp/ez/frappe-bench/env/lib/python3.13/site-packages/pymysql/err.py", line 150, in raise_mysql_exception
    raise errorclass(errno, errval)
pymysql.err.OperationalError: (1044, "Access denied for user '_7c5f4f77b0d74777'@'localhost' to database 'f77b0d74777_7c5f4'")
2025-02-10 12:10:00,649 ERROR scheduler Exception in Enqueue Events for Site money.test
Traceback (most recent call last):
  File "/Users/saimanikanta/Desktop/ezapp/ez/frappe-bench/apps/frappe/frappe/utils/scheduler.py", line 105, in enqueue_events_for_site
    if is_scheduler_inactive():
       ~~~~~~~~~~~~~~~~~~~~~^^
  File "/Users/saimanikanta/Desktop/ezapp/ez/frappe-bench/apps/frappe/frappe/utils/scheduler.py", line 149, in is_scheduler_inactive
    if is_scheduler_disabled(verbose=verbose):
       ~~~~~~~~~~~~~~~~~~~~~^^^^^^^^^^^^^^^^^
  File "/Users/saimanikanta/Desktop/ezapp/ez/frappe-bench/apps/frappe/frappe/utils/scheduler.py", line 162, in is_scheduler_disabled
    frappe.db.get_single_value("System Settings", "enable_scheduler")
    ~~~~~~~~~~~~~~~~~~~~~~~~~~^^^^^^^^^^^^^^^^^^^^^^^^^^^^^^^^^^^^^^^
  File "/Users/saimanikanta/Desktop/ezapp/ez/frappe-bench/apps/frappe/frappe/database/database.py", line 869, in get_single_value
    ).run()
      ~~~^^
  File "/Users/saimanikanta/Desktop/ezapp/ez/frappe-bench/apps/frappe/frappe/query_builder/utils.py", line 84, in execute_query
    result = frappe.db.sql(query, params, *args, **kwargs)  # nosemgrep
  File "/Users/saimanikanta/Desktop/ezapp/ez/frappe-bench/apps/frappe/frappe/database/database.py", line 215, in sql
    self.connect()
    ~~~~~~~~~~~~^^
  File "/Users/saimanikanta/Desktop/ezapp/ez/frappe-bench/apps/frappe/frappe/database/database.py", line 120, in connect
    self._conn: MariadbConnection | PostgresConnection = self.get_connection()
                                                         ~~~~~~~~~~~~~~~~~~~^^
  File "/Users/saimanikanta/Desktop/ezapp/ez/frappe-bench/apps/frappe/frappe/database/mariadb/database.py", line 107, in get_connection
    conn = self._get_connection()
  File "/Users/saimanikanta/Desktop/ezapp/ez/frappe-bench/apps/frappe/frappe/database/mariadb/database.py", line 113, in _get_connection
    return self.create_connection()
           ~~~~~~~~~~~~~~~~~~~~~~^^
  File "/Users/saimanikanta/Desktop/ezapp/ez/frappe-bench/apps/frappe/frappe/database/mariadb/database.py", line 116, in create_connection
    return pymysql.connect(**self.get_connection_settings())
           ~~~~~~~~~~~~~~~^^^^^^^^^^^^^^^^^^^^^^^^^^^^^^^^^^
  File "/Users/saimanikanta/Desktop/ezapp/ez/frappe-bench/env/lib/python3.13/site-packages/pymysql/connections.py", line 361, in __init__
    self.connect()
    ~~~~~~~~~~~~^^
  File "/Users/saimanikanta/Desktop/ezapp/ez/frappe-bench/env/lib/python3.13/site-packages/pymysql/connections.py", line 669, in connect
    self._request_authentication()
    ~~~~~~~~~~~~~~~~~~~~~~~~~~~~^^
  File "/Users/saimanikanta/Desktop/ezapp/ez/frappe-bench/env/lib/python3.13/site-packages/pymysql/connections.py", line 957, in _request_authentication
    auth_packet = self._read_packet()
  File "/Users/saimanikanta/Desktop/ezapp/ez/frappe-bench/env/lib/python3.13/site-packages/pymysql/connections.py", line 775, in _read_packet
    packet.raise_for_error()
    ~~~~~~~~~~~~~~~~~~~~~~^^
  File "/Users/saimanikanta/Desktop/ezapp/ez/frappe-bench/env/lib/python3.13/site-packages/pymysql/protocol.py", line 219, in raise_for_error
    err.raise_mysql_exception(self._data)
    ~~~~~~~~~~~~~~~~~~~~~~~~~^^^^^^^^^^^^
  File "/Users/saimanikanta/Desktop/ezapp/ez/frappe-bench/env/lib/python3.13/site-packages/pymysql/err.py", line 150, in raise_mysql_exception
    raise errorclass(errno, errval)
pymysql.err.OperationalError: (1044, "Access denied for user '_7c5f4f77b0d74777'@'localhost' to database 'f77b0d74777_7c5f4'")
