2025-02-05 16:51:18,773 ERROR scheduler Skipped queueing frappe.automation.doctype.reminder.reminder.send_reminders because it was found in queue for mysite.test
2025-02-05 16:51:18,777 ERROR scheduler Skipped queueing frappe.oauth.delete_oauth2_data because it was found in queue for mysite.test
2025-02-05 16:51:18,783 ERROR scheduler Skipped queueing frappe.deferred_insert.save_to_db because it was found in queue for mysite.test
2025-02-05 17:22:00,580 ERROR scheduler Skipped queueing frappe.twofactor.delete_all_barcodes_for_users because it was found in queue for mysite.test
2025-02-05 17:22:00,593 ERROR scheduler Skipped queueing frappe.automation.doctype.reminder.reminder.send_reminders because it was found in queue for mysite.test
2025-02-05 17:22:00,598 ERROR scheduler Skipped queueing frappe.deferred_insert.save_to_db because it was found in queue for mysite.test
2025-02-05 17:22:00,608 ERROR scheduler Skipped queueing frappe.oauth.delete_oauth2_data because it was found in queue for mysite.test
2025-02-05 17:22:00,614 ERROR scheduler Skipped queueing frappe.email.doctype.email_account.email_account.notify_unreplied because it was found in queue for mysite.test
2025-02-05 17:22:00,618 ERROR scheduler Skipped queueing frappe.website.doctype.web_page.web_page.check_publish_status because it was found in queue for mysite.test
2025-02-05 17:22:00,620 ERROR scheduler Skipped queueing frappe.monitor.flush because it was found in queue for mysite.test
2025-02-05 17:22:00,621 ERROR scheduler Skipped queueing frappe.utils.global_search.sync_global_search because it was found in queue for mysite.test
2025-02-05 17:26:00,658 ERROR scheduler Skipped queueing frappe.email.doctype.email_account.email_account.pull because it was found in queue for mysite.test
2025-02-05 17:26:00,671 ERROR scheduler Skipped queueing frappe.twofactor.delete_all_barcodes_for_users because it was found in queue for mysite.test
2025-02-05 17:26:00,678 ERROR scheduler Skipped queueing frappe.automation.doctype.reminder.reminder.send_reminders because it was found in queue for mysite.test
2025-02-05 17:26:00,683 ERROR scheduler Skipped queueing frappe.email.doctype.notification.notification.trigger_offset_alerts because it was found in queue for mysite.test
2025-02-05 17:26:00,690 ERROR scheduler Skipped queueing frappe.website.doctype.web_page.web_page.check_publish_status because it was found in queue for mysite.test
2025-02-05 17:26:00,704 ERROR scheduler Skipped queueing frappe.email.queue.flush because it was found in queue for mysite.test
2025-02-05 17:30:00,853 ERROR scheduler Skipped queueing frappe.monitor.flush because it was found in queue for mysite.test
2025-02-05 17:30:00,859 ERROR scheduler Skipped queueing frappe.website.doctype.web_page.web_page.check_publish_status because it was found in queue for mysite.test
2025-02-05 17:30:00,865 ERROR scheduler Skipped queueing frappe.email.doctype.email_account.email_account.pull because it was found in queue for mysite.test
2025-02-05 17:30:00,869 ERROR scheduler Skipped queueing frappe.automation.doctype.reminder.reminder.send_reminders because it was found in queue for mysite.test
2025-02-05 17:30:00,883 ERROR scheduler Skipped queueing frappe.twofactor.delete_all_barcodes_for_users because it was found in queue for mysite.test
2025-02-05 17:30:00,888 ERROR scheduler Skipped queueing frappe.deferred_insert.save_to_db because it was found in queue for mysite.test
2025-02-05 17:34:00,912 ERROR scheduler Skipped queueing frappe.email.doctype.email_account.email_account.notify_unreplied because it was found in queue for mysite.test
2025-02-05 17:34:00,927 ERROR scheduler Skipped queueing frappe.deferred_insert.save_to_db because it was found in queue for mysite.test
2025-02-05 17:34:00,932 ERROR scheduler Skipped queueing frappe.email.doctype.email_account.email_account.pull because it was found in queue for mysite.test
2025-02-05 17:34:00,940 ERROR scheduler Skipped queueing frappe.email.doctype.notification.notification.trigger_offset_alerts because it was found in queue for mysite.test
2025-02-05 17:34:00,953 ERROR scheduler Skipped queueing frappe.utils.global_search.sync_global_search because it was found in queue for mysite.test
2025-02-05 17:34:00,956 ERROR scheduler Skipped queueing frappe.core.doctype.prepared_report.prepared_report.expire_stalled_report because it was found in queue for mysite.test
2025-02-05 17:34:00,958 ERROR scheduler Skipped queueing frappe.email.queue.flush because it was found in queue for mysite.test
2025-02-05 17:34:00,963 ERROR scheduler Skipped queueing frappe.oauth.delete_oauth2_data because it was found in queue for mysite.test
2025-02-05 18:06:00,721 ERROR scheduler Skipped queueing frappe.desk.form.document_follow.send_hourly_updates because it was found in queue for mysite.test
2025-02-05 18:06:00,728 ERROR scheduler Skipped queueing frappe.email.doctype.email_account.email_account.pull because it was found in queue for mysite.test
2025-02-05 18:06:00,735 ERROR scheduler Skipped queueing frappe.model.utils.user_settings.sync_user_settings because it was found in queue for mysite.test
2025-02-05 18:06:00,748 ERROR scheduler Skipped queueing frappe.email.queue.flush because it was found in queue for mysite.test
2025-02-05 18:06:00,750 ERROR scheduler Skipped queueing frappe.email.doctype.newsletter.newsletter.send_scheduled_email because it was found in queue for mysite.test
2025-02-05 18:06:00,757 ERROR scheduler Skipped queueing frappe.oauth.delete_oauth2_data because it was found in queue for mysite.test
2025-02-05 18:06:00,758 ERROR scheduler Skipped queueing frappe.website.doctype.web_page.web_page.check_publish_status because it was found in queue for mysite.test
2025-02-05 18:06:00,760 ERROR scheduler Skipped queueing frappe.website.doctype.personal_data_deletion_request.personal_data_deletion_request.process_data_deletion_request because it was found in queue for mysite.test
2025-02-05 18:06:00,762 ERROR scheduler Skipped queueing frappe.deferred_insert.save_to_db because it was found in queue for mysite.test
2025-02-05 18:06:00,766 ERROR scheduler Skipped queueing frappe.monitor.flush because it was found in queue for mysite.test
2025-02-05 18:06:00,769 ERROR scheduler Skipped queueing frappe.utils.global_search.sync_global_search because it was found in queue for mysite.test
2025-02-05 18:06:00,771 ERROR scheduler Skipped queueing frappe.automation.doctype.reminder.reminder.send_reminders because it was found in queue for mysite.test
2025-02-05 18:06:00,772 ERROR scheduler Skipped queueing frappe.desk.page.backups.backups.delete_downloadable_backups because it was found in queue for mysite.test
2025-02-05 18:06:00,774 ERROR scheduler Skipped queueing frappe.email.doctype.notification.notification.trigger_offset_alerts because it was found in queue for mysite.test
2025-02-05 18:06:00,776 ERROR scheduler Skipped queueing frappe.twofactor.delete_all_barcodes_for_users because it was found in queue for mysite.test
2025-02-05 18:06:00,780 ERROR scheduler Skipped queueing frappe.integrations.doctype.google_calendar.google_calendar.sync because it was found in queue for mysite.test
2025-02-05 18:06:00,781 ERROR scheduler Skipped queueing frappe.email.doctype.email_account.email_account.notify_unreplied because it was found in queue for mysite.test
2025-02-05 18:06:00,785 ERROR scheduler Skipped queueing frappe.model.utils.link_count.update_link_count because it was found in queue for mysite.test
2025-02-05 18:22:00,138 ERROR scheduler Skipped queueing frappe.email.queue.flush because it was found in queue for mysite.test
2025-02-05 18:26:00,290 ERROR scheduler Skipped queueing frappe.monitor.flush because it was found in queue for mysite.test
2025-02-05 18:26:00,302 ERROR scheduler Skipped queueing frappe.email.doctype.email_account.email_account.pull because it was found in queue for mysite.test
2025-02-05 18:30:00,372 ERROR scheduler Skipped queueing frappe.email.doctype.email_account.email_account.pull because it was found in queue for mysite.test
2025-02-05 18:30:00,383 ERROR scheduler Skipped queueing frappe.email.doctype.notification.notification.trigger_offset_alerts because it was found in queue for mysite.test
2025-02-05 18:34:00,511 ERROR scheduler Skipped queueing frappe.email.doctype.notification.notification.trigger_offset_alerts because it was found in queue for mysite.test
2025-02-05 18:34:00,514 ERROR scheduler Skipped queueing frappe.deferred_insert.save_to_db because it was found in queue for mysite.test
2025-02-05 18:34:00,520 ERROR scheduler Skipped queueing frappe.utils.global_search.sync_global_search because it was found in queue for mysite.test
2025-02-05 18:34:00,535 ERROR scheduler Skipped queueing frappe.oauth.delete_oauth2_data because it was found in queue for mysite.test
2025-02-05 18:34:00,539 ERROR scheduler Skipped queueing frappe.twofactor.delete_all_barcodes_for_users because it was found in queue for mysite.test
2025-02-05 18:34:00,540 ERROR scheduler Skipped queueing frappe.email.queue.flush because it was found in queue for mysite.test
2025-02-05 18:34:00,543 ERROR scheduler Skipped queueing frappe.automation.doctype.reminder.reminder.send_reminders because it was found in queue for mysite.test
2025-02-05 18:34:00,547 ERROR scheduler Skipped queueing frappe.monitor.flush because it was found in queue for mysite.test
2025-02-05 18:34:00,555 ERROR scheduler Skipped queueing frappe.website.doctype.web_page.web_page.check_publish_status because it was found in queue for mysite.test
2025-02-05 18:34:00,556 ERROR scheduler Skipped queueing frappe.email.doctype.email_account.email_account.notify_unreplied because it was found in queue for mysite.test
2025-02-05 18:34:00,561 ERROR scheduler Skipped queueing frappe.email.doctype.email_account.email_account.pull because it was found in queue for mysite.test
2025-02-05 18:34:00,562 ERROR scheduler Skipped queueing frappe.core.doctype.prepared_report.prepared_report.expire_stalled_report because it was found in queue for mysite.test
2025-02-07 10:34:00,615 ERROR scheduler Skipped queueing frappe.utils.global_search.sync_global_search because it was found in queue for mysite.test
2025-02-07 10:34:00,616 ERROR scheduler Skipped queueing frappe.integrations.doctype.google_contacts.google_contacts.sync because it was found in queue for mysite.test
2025-02-07 10:34:00,617 ERROR scheduler Skipped queueing frappe.integrations.doctype.dropbox_settings.dropbox_settings.take_backups_daily because it was found in queue for mysite.test
2025-02-07 10:34:00,617 ERROR scheduler Skipped queueing frappe.website.doctype.personal_data_deletion_request.personal_data_deletion_request.remove_unverified_record because it was found in queue for mysite.test
2025-02-07 10:34:00,619 ERROR scheduler Skipped queueing frappe.desk.page.backups.backups.delete_downloadable_backups because it was found in queue for mysite.test
2025-02-07 10:34:00,620 ERROR scheduler Skipped queueing frappe.twofactor.delete_all_barcodes_for_users because it was found in queue for mysite.test
2025-02-07 10:34:00,621 ERROR scheduler Skipped queueing frappe.automation.doctype.auto_repeat.auto_repeat.make_auto_repeat_entry because it was found in queue for mysite.test
2025-02-07 10:34:00,622 ERROR scheduler Skipped queueing frappe.core.doctype.prepared_report.prepared_report.expire_stalled_report because it was found in queue for mysite.test
2025-02-07 10:34:00,623 ERROR scheduler Skipped queueing frappe.desk.notifications.clear_notifications because it was found in queue for mysite.test
2025-02-07 10:34:00,624 ERROR scheduler Skipped queueing frappe.monitor.flush because it was found in queue for mysite.test
2025-02-07 10:34:00,625 ERROR scheduler Skipped queueing frappe.email.doctype.email_account.email_account.notify_unreplied because it was found in queue for mysite.test
2025-02-07 10:34:00,626 ERROR scheduler Skipped queueing frappe.sessions.clear_expired_sessions because it was found in queue for mysite.test
2025-02-07 10:34:00,629 ERROR scheduler Skipped queueing frappe.website.doctype.personal_data_deletion_request.personal_data_deletion_request.process_data_deletion_request because it was found in queue for mysite.test
2025-02-07 10:34:00,630 ERROR scheduler Skipped queueing frappe.core.doctype.log_settings.log_settings.run_log_clean_up because it was found in queue for mysite.test
2025-02-07 10:34:00,631 ERROR scheduler Skipped queueing frappe.email.doctype.email_account.email_account.pull because it was found in queue for mysite.test
2025-02-07 10:34:00,632 ERROR scheduler Skipped queueing frappe.email.doctype.notification.notification.trigger_daily_alerts because it was found in queue for mysite.test
2025-02-07 10:34:00,633 ERROR scheduler Skipped queueing frappe.automation.doctype.reminder.reminder.send_reminders because it was found in queue for mysite.test
2025-02-07 10:34:00,633 ERROR scheduler Skipped queueing frappe.oauth.delete_oauth2_data because it was found in queue for mysite.test
2025-02-07 10:34:00,634 ERROR scheduler Skipped queueing frappe.website.doctype.web_page.web_page.check_publish_status because it was found in queue for mysite.test
2025-02-07 10:34:00,635 ERROR scheduler Skipped queueing frappe.email.doctype.newsletter.newsletter.send_scheduled_email because it was found in queue for mysite.test
2025-02-07 10:34:00,636 ERROR scheduler Skipped queueing frappe.model.utils.link_count.update_link_count because it was found in queue for mysite.test
2025-02-07 10:34:00,637 ERROR scheduler Skipped queueing frappe.automation.doctype.auto_repeat.auto_repeat.set_auto_repeat_as_completed because it was found in queue for mysite.test
2025-02-07 10:34:00,638 ERROR scheduler Skipped queueing frappe.email.doctype.notification.notification.trigger_offset_alerts because it was found in queue for mysite.test
2025-02-07 10:34:00,639 ERROR scheduler Skipped queueing frappe.integrations.doctype.google_drive.google_drive.daily_backup because it was found in queue for mysite.test
2025-02-07 10:34:00,640 ERROR scheduler Skipped queueing frappe.deferred_insert.save_to_db because it was found in queue for mysite.test
2025-02-07 10:34:00,641 ERROR scheduler Skipped queueing frappe.integrations.doctype.google_calendar.google_calendar.sync because it was found in queue for mysite.test
2025-02-07 10:34:00,642 ERROR scheduler Skipped queueing frappe.desk.doctype.event.event.send_event_digest because it was found in queue for mysite.test
2025-02-07 10:34:00,643 ERROR scheduler Skipped queueing frappe.desk.form.document_follow.send_hourly_updates because it was found in queue for mysite.test
2025-02-07 10:34:00,644 ERROR scheduler Skipped queueing frappe.integrations.doctype.s3_backup_settings.s3_backup_settings.take_backups_daily because it was found in queue for mysite.test
2025-02-07 10:34:00,645 ERROR scheduler Skipped queueing frappe.social.doctype.energy_point_settings.energy_point_settings.allocate_review_points because it was found in queue for mysite.test
2025-02-07 10:34:00,646 ERROR scheduler Skipped queueing frappe.email.queue.flush because it was found in queue for mysite.test
2025-02-07 10:34:00,647 ERROR scheduler Skipped queueing frappe.email.doctype.auto_email_report.auto_email_report.send_daily because it was found in queue for mysite.test
2025-02-07 10:34:00,648 ERROR scheduler Skipped queueing frappe.desk.form.document_follow.send_daily_updates because it was found in queue for mysite.test
2025-02-07 10:34:00,648 ERROR scheduler Skipped queueing frappe.model.utils.user_settings.sync_user_settings because it was found in queue for mysite.test
2025-02-07 12:30:00,511 ERROR scheduler Skipped queueing frappe.deferred_insert.save_to_db because it was found in queue for mysite.test
2025-02-07 14:26:01,146 ERROR scheduler Exception in Enqueue Events for Site mysite.test
Traceback (most recent call last):
  File "/Users/saimanikanta/Desktop/ezapp/ez/frappe-bench/env/lib/python3.13/site-packages/redis/connection.py", line 357, in connect
    sock = self.retry.call_with_retry(
        lambda: self._connect(), lambda error: self.disconnect(error)
    )
  File "/Users/saimanikanta/Desktop/ezapp/ez/frappe-bench/env/lib/python3.13/site-packages/redis/retry.py", line 62, in call_with_retry
    return do()
  File "/Users/saimanikanta/Desktop/ezapp/ez/frappe-bench/env/lib/python3.13/site-packages/redis/connection.py", line 358, in <lambda>
    lambda: self._connect(), lambda error: self.disconnect(error)
            ~~~~~~~~~~~~~^^
  File "/Users/saimanikanta/Desktop/ezapp/ez/frappe-bench/env/lib/python3.13/site-packages/redis/connection.py", line 730, in _connect
    raise err
  File "/Users/saimanikanta/Desktop/ezapp/ez/frappe-bench/env/lib/python3.13/site-packages/redis/connection.py", line 718, in _connect
    sock.connect(socket_address)
    ~~~~~~~~~~~~^^^^^^^^^^^^^^^^
ConnectionRefusedError: [Errno 61] Connection refused

During handling of the above exception, another exception occurred:

Traceback (most recent call last):
  File "/Users/saimanikanta/Desktop/ezapp/ez/frappe-bench/apps/frappe/frappe/utils/scheduler.py", line 108, in enqueue_events_for_site
    enqueue_events()
    ~~~~~~~~~~~~~~^^
  File "/Users/saimanikanta/Desktop/ezapp/ez/frappe-bench/apps/frappe/frappe/utils/scheduler.py", line 128, in enqueue_events
    if job_type.enqueue():
       ~~~~~~~~~~~~~~~~^^
  File "/Users/saimanikanta/Desktop/ezapp/ez/frappe-bench/apps/frappe/frappe/core/doctype/scheduled_job_type/scheduled_job_type.py", line 71, in enqueue
    if not self.is_job_in_queue():
           ~~~~~~~~~~~~~~~~~~~~^^
  File "/Users/saimanikanta/Desktop/ezapp/ez/frappe-bench/apps/frappe/frappe/core/doctype/scheduled_job_type/scheduled_job_type.py", line 93, in is_job_in_queue
    return is_job_enqueued(self.rq_job_id)
  File "/Users/saimanikanta/Desktop/ezapp/ez/frappe-bench/apps/frappe/frappe/utils/background_jobs.py", line 618, in is_job_enqueued
    return get_job_status(job_id) in (JobStatus.QUEUED, JobStatus.STARTED)
           ~~~~~~~~~~~~~~^^^^^^^^
  File "/Users/saimanikanta/Desktop/ezapp/ez/frappe-bench/apps/frappe/frappe/utils/background_jobs.py", line 623, in get_job_status
    if job := get_job(job_id):
              ~~~~~~~^^^^^^^^
  File "/Users/saimanikanta/Desktop/ezapp/ez/frappe-bench/apps/frappe/frappe/utils/background_jobs.py", line 629, in get_job
    return Job.fetch(create_job_id(job_id), connection=get_redis_conn())
           ~~~~~~~~~^^^^^^^^^^^^^^^^^^^^^^^^^^^^^^^^^^^^^^^^^^^^^^^^^^^^
  File "/Users/saimanikanta/Desktop/ezapp/ez/frappe-bench/env/lib/python3.13/site-packages/rq/job.py", line 591, in fetch
    job.refresh()
    ~~~~~~~~~~~^^
  File "/Users/saimanikanta/Desktop/ezapp/ez/frappe-bench/env/lib/python3.13/site-packages/rq/job.py", line 991, in refresh
    data = self.connection.hgetall(self.key)
  File "/Users/saimanikanta/Desktop/ezapp/ez/frappe-bench/env/lib/python3.13/site-packages/redis/commands/core.py", line 4978, in hgetall
    return self.execute_command("HGETALL", name, keys=[name])
           ~~~~~~~~~~~~~~~~~~~~^^^^^^^^^^^^^^^^^^^^^^^^^^^^^^
  File "/Users/saimanikanta/Desktop/ezapp/ez/frappe-bench/env/lib/python3.13/site-packages/redis/client.py", line 559, in execute_command
    return self._execute_command(*args, **options)
           ~~~~~~~~~~~~~~~~~~~~~^^^^^^^^^^^^^^^^^^
  File "/Users/saimanikanta/Desktop/ezapp/ez/frappe-bench/env/lib/python3.13/site-packages/redis/client.py", line 565, in _execute_command
    conn = self.connection or pool.get_connection(command_name, **options)
                              ~~~~~~~~~~~~~~~~~~~^^^^^^^^^^^^^^^^^^^^^^^^^
  File "/Users/saimanikanta/Desktop/ezapp/ez/frappe-bench/env/lib/python3.13/site-packages/redis/connection.py", line 1422, in get_connection
    connection.connect()
    ~~~~~~~~~~~~~~~~~~^^
  File "/Users/saimanikanta/Desktop/ezapp/ez/frappe-bench/env/lib/python3.13/site-packages/redis/connection.py", line 363, in connect
    raise ConnectionError(self._error_message(e))
redis.exceptions.ConnectionError: Error 61 connecting to 127.0.0.1:11000. Connection refused.
2025-02-10 14:58:00,614 ERROR scheduler Exception in Enqueue Events for Site mysite.test
Traceback (most recent call last):
  File "/Users/saimanikanta/Desktop/ezapp/ez/frappe-bench/env/lib/python3.13/site-packages/redis/connection.py", line 1428, in get_connection
    if connection.can_read() and self.cache is None:
       ~~~~~~~~~~~~~~~~~~~^^
  File "/Users/saimanikanta/Desktop/ezapp/ez/frappe-bench/env/lib/python3.13/site-packages/redis/connection.py", line 570, in can_read
    return self._parser.can_read(timeout)
           ~~~~~~~~~~~~~~~~~~~~~^^^^^^^^^
  File "/Users/saimanikanta/Desktop/ezapp/ez/frappe-bench/env/lib/python3.13/site-packages/redis/_parsers/hiredis.py", line 79, in can_read
    return self.read_from_socket(timeout=timeout, raise_on_timeout=False)
           ~~~~~~~~~~~~~~~~~~~~~^^^^^^^^^^^^^^^^^^^^^^^^^^^^^^^^^^^^^^^^^
  File "/Users/saimanikanta/Desktop/ezapp/ez/frappe-bench/env/lib/python3.13/site-packages/redis/_parsers/hiredis.py", line 90, in read_from_socket
    raise ConnectionError(SERVER_CLOSED_CONNECTION_ERROR)
redis.exceptions.ConnectionError: Connection closed by server.

During handling of the above exception, another exception occurred:

Traceback (most recent call last):
  File "/Users/saimanikanta/Desktop/ezapp/ez/frappe-bench/env/lib/python3.13/site-packages/redis/connection.py", line 357, in connect
    sock = self.retry.call_with_retry(
        lambda: self._connect(), lambda error: self.disconnect(error)
    )
  File "/Users/saimanikanta/Desktop/ezapp/ez/frappe-bench/env/lib/python3.13/site-packages/redis/retry.py", line 62, in call_with_retry
    return do()
  File "/Users/saimanikanta/Desktop/ezapp/ez/frappe-bench/env/lib/python3.13/site-packages/redis/connection.py", line 358, in <lambda>
    lambda: self._connect(), lambda error: self.disconnect(error)
            ~~~~~~~~~~~~~^^
  File "/Users/saimanikanta/Desktop/ezapp/ez/frappe-bench/env/lib/python3.13/site-packages/redis/connection.py", line 730, in _connect
    raise err
  File "/Users/saimanikanta/Desktop/ezapp/ez/frappe-bench/env/lib/python3.13/site-packages/redis/connection.py", line 718, in _connect
    sock.connect(socket_address)
    ~~~~~~~~~~~~^^^^^^^^^^^^^^^^
ConnectionRefusedError: [Errno 61] Connection refused

During handling of the above exception, another exception occurred:

Traceback (most recent call last):
  File "/Users/saimanikanta/Desktop/ezapp/ez/frappe-bench/apps/frappe/frappe/utils/scheduler.py", line 108, in enqueue_events_for_site
    enqueue_events()
    ~~~~~~~~~~~~~~^^
  File "/Users/saimanikanta/Desktop/ezapp/ez/frappe-bench/apps/frappe/frappe/utils/scheduler.py", line 128, in enqueue_events
    if job_type.enqueue():
       ~~~~~~~~~~~~~~~~^^
  File "/Users/saimanikanta/Desktop/ezapp/ez/frappe-bench/apps/frappe/frappe/core/doctype/scheduled_job_type/scheduled_job_type.py", line 71, in enqueue
    if not self.is_job_in_queue():
           ~~~~~~~~~~~~~~~~~~~~^^
  File "/Users/saimanikanta/Desktop/ezapp/ez/frappe-bench/apps/frappe/frappe/core/doctype/scheduled_job_type/scheduled_job_type.py", line 93, in is_job_in_queue
    return is_job_enqueued(self.rq_job_id)
  File "/Users/saimanikanta/Desktop/ezapp/ez/frappe-bench/apps/frappe/frappe/utils/background_jobs.py", line 618, in is_job_enqueued
    return get_job_status(job_id) in (JobStatus.QUEUED, JobStatus.STARTED)
           ~~~~~~~~~~~~~~^^^^^^^^
  File "/Users/saimanikanta/Desktop/ezapp/ez/frappe-bench/apps/frappe/frappe/utils/background_jobs.py", line 623, in get_job_status
    if job := get_job(job_id):
              ~~~~~~~^^^^^^^^
  File "/Users/saimanikanta/Desktop/ezapp/ez/frappe-bench/apps/frappe/frappe/utils/background_jobs.py", line 629, in get_job
    return Job.fetch(create_job_id(job_id), connection=get_redis_conn())
           ~~~~~~~~~^^^^^^^^^^^^^^^^^^^^^^^^^^^^^^^^^^^^^^^^^^^^^^^^^^^^
  File "/Users/saimanikanta/Desktop/ezapp/ez/frappe-bench/env/lib/python3.13/site-packages/rq/job.py", line 591, in fetch
    job.refresh()
    ~~~~~~~~~~~^^
  File "/Users/saimanikanta/Desktop/ezapp/ez/frappe-bench/env/lib/python3.13/site-packages/rq/job.py", line 991, in refresh
    data = self.connection.hgetall(self.key)
  File "/Users/saimanikanta/Desktop/ezapp/ez/frappe-bench/env/lib/python3.13/site-packages/redis/commands/core.py", line 4978, in hgetall
    return self.execute_command("HGETALL", name, keys=[name])
           ~~~~~~~~~~~~~~~~~~~~^^^^^^^^^^^^^^^^^^^^^^^^^^^^^^
  File "/Users/saimanikanta/Desktop/ezapp/ez/frappe-bench/env/lib/python3.13/site-packages/redis/client.py", line 559, in execute_command
    return self._execute_command(*args, **options)
           ~~~~~~~~~~~~~~~~~~~~~^^^^^^^^^^^^^^^^^^
  File "/Users/saimanikanta/Desktop/ezapp/ez/frappe-bench/env/lib/python3.13/site-packages/redis/client.py", line 565, in _execute_command
    conn = self.connection or pool.get_connection(command_name, **options)
                              ~~~~~~~~~~~~~~~~~~~^^^^^^^^^^^^^^^^^^^^^^^^^
  File "/Users/saimanikanta/Desktop/ezapp/ez/frappe-bench/env/lib/python3.13/site-packages/redis/connection.py", line 1432, in get_connection
    connection.connect()
    ~~~~~~~~~~~~~~~~~~^^
  File "/Users/saimanikanta/Desktop/ezapp/ez/frappe-bench/env/lib/python3.13/site-packages/redis/connection.py", line 363, in connect
    raise ConnectionError(self._error_message(e))
redis.exceptions.ConnectionError: Error 61 connecting to 127.0.0.1:11000. Connection refused.
2025-02-10 15:02:00,891 ERROR scheduler Exception in Enqueue Events for Site mysite.test
Traceback (most recent call last):
  File "/Users/saimanikanta/Desktop/ezapp/ez/frappe-bench/env/lib/python3.13/site-packages/redis/connection.py", line 357, in connect
    sock = self.retry.call_with_retry(
        lambda: self._connect(), lambda error: self.disconnect(error)
    )
  File "/Users/saimanikanta/Desktop/ezapp/ez/frappe-bench/env/lib/python3.13/site-packages/redis/retry.py", line 62, in call_with_retry
    return do()
  File "/Users/saimanikanta/Desktop/ezapp/ez/frappe-bench/env/lib/python3.13/site-packages/redis/connection.py", line 358, in <lambda>
    lambda: self._connect(), lambda error: self.disconnect(error)
            ~~~~~~~~~~~~~^^
  File "/Users/saimanikanta/Desktop/ezapp/ez/frappe-bench/env/lib/python3.13/site-packages/redis/connection.py", line 730, in _connect
    raise err
  File "/Users/saimanikanta/Desktop/ezapp/ez/frappe-bench/env/lib/python3.13/site-packages/redis/connection.py", line 718, in _connect
    sock.connect(socket_address)
    ~~~~~~~~~~~~^^^^^^^^^^^^^^^^
ConnectionRefusedError: [Errno 61] Connection refused

During handling of the above exception, another exception occurred:

Traceback (most recent call last):
  File "/Users/saimanikanta/Desktop/ezapp/ez/frappe-bench/apps/frappe/frappe/utils/scheduler.py", line 108, in enqueue_events_for_site
    enqueue_events()
    ~~~~~~~~~~~~~~^^
  File "/Users/saimanikanta/Desktop/ezapp/ez/frappe-bench/apps/frappe/frappe/utils/scheduler.py", line 128, in enqueue_events
    if job_type.enqueue():
       ~~~~~~~~~~~~~~~~^^
  File "/Users/saimanikanta/Desktop/ezapp/ez/frappe-bench/apps/frappe/frappe/core/doctype/scheduled_job_type/scheduled_job_type.py", line 71, in enqueue
    if not self.is_job_in_queue():
           ~~~~~~~~~~~~~~~~~~~~^^
  File "/Users/saimanikanta/Desktop/ezapp/ez/frappe-bench/apps/frappe/frappe/core/doctype/scheduled_job_type/scheduled_job_type.py", line 93, in is_job_in_queue
    return is_job_enqueued(self.rq_job_id)
  File "/Users/saimanikanta/Desktop/ezapp/ez/frappe-bench/apps/frappe/frappe/utils/background_jobs.py", line 618, in is_job_enqueued
    return get_job_status(job_id) in (JobStatus.QUEUED, JobStatus.STARTED)
           ~~~~~~~~~~~~~~^^^^^^^^
  File "/Users/saimanikanta/Desktop/ezapp/ez/frappe-bench/apps/frappe/frappe/utils/background_jobs.py", line 623, in get_job_status
    if job := get_job(job_id):
              ~~~~~~~^^^^^^^^
  File "/Users/saimanikanta/Desktop/ezapp/ez/frappe-bench/apps/frappe/frappe/utils/background_jobs.py", line 629, in get_job
    return Job.fetch(create_job_id(job_id), connection=get_redis_conn())
           ~~~~~~~~~^^^^^^^^^^^^^^^^^^^^^^^^^^^^^^^^^^^^^^^^^^^^^^^^^^^^
  File "/Users/saimanikanta/Desktop/ezapp/ez/frappe-bench/env/lib/python3.13/site-packages/rq/job.py", line 591, in fetch
    job.refresh()
    ~~~~~~~~~~~^^
  File "/Users/saimanikanta/Desktop/ezapp/ez/frappe-bench/env/lib/python3.13/site-packages/rq/job.py", line 991, in refresh
    data = self.connection.hgetall(self.key)
  File "/Users/saimanikanta/Desktop/ezapp/ez/frappe-bench/env/lib/python3.13/site-packages/redis/commands/core.py", line 4978, in hgetall
    return self.execute_command("HGETALL", name, keys=[name])
           ~~~~~~~~~~~~~~~~~~~~^^^^^^^^^^^^^^^^^^^^^^^^^^^^^^
  File "/Users/saimanikanta/Desktop/ezapp/ez/frappe-bench/env/lib/python3.13/site-packages/redis/client.py", line 559, in execute_command
    return self._execute_command(*args, **options)
           ~~~~~~~~~~~~~~~~~~~~~^^^^^^^^^^^^^^^^^^
  File "/Users/saimanikanta/Desktop/ezapp/ez/frappe-bench/env/lib/python3.13/site-packages/redis/client.py", line 565, in _execute_command
    conn = self.connection or pool.get_connection(command_name, **options)
                              ~~~~~~~~~~~~~~~~~~~^^^^^^^^^^^^^^^^^^^^^^^^^
  File "/Users/saimanikanta/Desktop/ezapp/ez/frappe-bench/env/lib/python3.13/site-packages/redis/connection.py", line 1422, in get_connection
    connection.connect()
    ~~~~~~~~~~~~~~~~~~^^
  File "/Users/saimanikanta/Desktop/ezapp/ez/frappe-bench/env/lib/python3.13/site-packages/redis/connection.py", line 363, in connect
    raise ConnectionError(self._error_message(e))
redis.exceptions.ConnectionError: Error 61 connecting to 127.0.0.1:11000. Connection refused.
2025-02-10 15:06:01,065 ERROR scheduler Exception in Enqueue Events for Site mysite.test
Traceback (most recent call last):
  File "/Users/saimanikanta/Desktop/ezapp/ez/frappe-bench/env/lib/python3.13/site-packages/redis/connection.py", line 357, in connect
    sock = self.retry.call_with_retry(
        lambda: self._connect(), lambda error: self.disconnect(error)
    )
  File "/Users/saimanikanta/Desktop/ezapp/ez/frappe-bench/env/lib/python3.13/site-packages/redis/retry.py", line 62, in call_with_retry
    return do()
  File "/Users/saimanikanta/Desktop/ezapp/ez/frappe-bench/env/lib/python3.13/site-packages/redis/connection.py", line 358, in <lambda>
    lambda: self._connect(), lambda error: self.disconnect(error)
            ~~~~~~~~~~~~~^^
  File "/Users/saimanikanta/Desktop/ezapp/ez/frappe-bench/env/lib/python3.13/site-packages/redis/connection.py", line 730, in _connect
    raise err
  File "/Users/saimanikanta/Desktop/ezapp/ez/frappe-bench/env/lib/python3.13/site-packages/redis/connection.py", line 718, in _connect
    sock.connect(socket_address)
    ~~~~~~~~~~~~^^^^^^^^^^^^^^^^
ConnectionRefusedError: [Errno 61] Connection refused

During handling of the above exception, another exception occurred:

Traceback (most recent call last):
  File "/Users/saimanikanta/Desktop/ezapp/ez/frappe-bench/apps/frappe/frappe/utils/scheduler.py", line 108, in enqueue_events_for_site
    enqueue_events()
    ~~~~~~~~~~~~~~^^
  File "/Users/saimanikanta/Desktop/ezapp/ez/frappe-bench/apps/frappe/frappe/utils/scheduler.py", line 128, in enqueue_events
    if job_type.enqueue():
       ~~~~~~~~~~~~~~~~^^
  File "/Users/saimanikanta/Desktop/ezapp/ez/frappe-bench/apps/frappe/frappe/core/doctype/scheduled_job_type/scheduled_job_type.py", line 71, in enqueue
    if not self.is_job_in_queue():
           ~~~~~~~~~~~~~~~~~~~~^^
  File "/Users/saimanikanta/Desktop/ezapp/ez/frappe-bench/apps/frappe/frappe/core/doctype/scheduled_job_type/scheduled_job_type.py", line 93, in is_job_in_queue
    return is_job_enqueued(self.rq_job_id)
  File "/Users/saimanikanta/Desktop/ezapp/ez/frappe-bench/apps/frappe/frappe/utils/background_jobs.py", line 618, in is_job_enqueued
    return get_job_status(job_id) in (JobStatus.QUEUED, JobStatus.STARTED)
           ~~~~~~~~~~~~~~^^^^^^^^
  File "/Users/saimanikanta/Desktop/ezapp/ez/frappe-bench/apps/frappe/frappe/utils/background_jobs.py", line 623, in get_job_status
    if job := get_job(job_id):
              ~~~~~~~^^^^^^^^
  File "/Users/saimanikanta/Desktop/ezapp/ez/frappe-bench/apps/frappe/frappe/utils/background_jobs.py", line 629, in get_job
    return Job.fetch(create_job_id(job_id), connection=get_redis_conn())
           ~~~~~~~~~^^^^^^^^^^^^^^^^^^^^^^^^^^^^^^^^^^^^^^^^^^^^^^^^^^^^
  File "/Users/saimanikanta/Desktop/ezapp/ez/frappe-bench/env/lib/python3.13/site-packages/rq/job.py", line 591, in fetch
    job.refresh()
    ~~~~~~~~~~~^^
  File "/Users/saimanikanta/Desktop/ezapp/ez/frappe-bench/env/lib/python3.13/site-packages/rq/job.py", line 991, in refresh
    data = self.connection.hgetall(self.key)
  File "/Users/saimanikanta/Desktop/ezapp/ez/frappe-bench/env/lib/python3.13/site-packages/redis/commands/core.py", line 4978, in hgetall
    return self.execute_command("HGETALL", name, keys=[name])
           ~~~~~~~~~~~~~~~~~~~~^^^^^^^^^^^^^^^^^^^^^^^^^^^^^^
  File "/Users/saimanikanta/Desktop/ezapp/ez/frappe-bench/env/lib/python3.13/site-packages/redis/client.py", line 559, in execute_command
    return self._execute_command(*args, **options)
           ~~~~~~~~~~~~~~~~~~~~~^^^^^^^^^^^^^^^^^^
  File "/Users/saimanikanta/Desktop/ezapp/ez/frappe-bench/env/lib/python3.13/site-packages/redis/client.py", line 565, in _execute_command
    conn = self.connection or pool.get_connection(command_name, **options)
                              ~~~~~~~~~~~~~~~~~~~^^^^^^^^^^^^^^^^^^^^^^^^^
  File "/Users/saimanikanta/Desktop/ezapp/ez/frappe-bench/env/lib/python3.13/site-packages/redis/connection.py", line 1422, in get_connection
    connection.connect()
    ~~~~~~~~~~~~~~~~~~^^
  File "/Users/saimanikanta/Desktop/ezapp/ez/frappe-bench/env/lib/python3.13/site-packages/redis/connection.py", line 363, in connect
    raise ConnectionError(self._error_message(e))
redis.exceptions.ConnectionError: Error 61 connecting to 127.0.0.1:11000. Connection refused.
2025-02-10 15:10:00,267 ERROR scheduler Exception in Enqueue Events for Site mysite.test
Traceback (most recent call last):
  File "/Users/saimanikanta/Desktop/ezapp/ez/frappe-bench/env/lib/python3.13/site-packages/redis/connection.py", line 357, in connect
    sock = self.retry.call_with_retry(
        lambda: self._connect(), lambda error: self.disconnect(error)
    )
  File "/Users/saimanikanta/Desktop/ezapp/ez/frappe-bench/env/lib/python3.13/site-packages/redis/retry.py", line 62, in call_with_retry
    return do()
  File "/Users/saimanikanta/Desktop/ezapp/ez/frappe-bench/env/lib/python3.13/site-packages/redis/connection.py", line 358, in <lambda>
    lambda: self._connect(), lambda error: self.disconnect(error)
            ~~~~~~~~~~~~~^^
  File "/Users/saimanikanta/Desktop/ezapp/ez/frappe-bench/env/lib/python3.13/site-packages/redis/connection.py", line 730, in _connect
    raise err
  File "/Users/saimanikanta/Desktop/ezapp/ez/frappe-bench/env/lib/python3.13/site-packages/redis/connection.py", line 718, in _connect
    sock.connect(socket_address)
    ~~~~~~~~~~~~^^^^^^^^^^^^^^^^
ConnectionRefusedError: [Errno 61] Connection refused

During handling of the above exception, another exception occurred:

Traceback (most recent call last):
  File "/Users/saimanikanta/Desktop/ezapp/ez/frappe-bench/apps/frappe/frappe/utils/scheduler.py", line 108, in enqueue_events_for_site
    enqueue_events()
    ~~~~~~~~~~~~~~^^
  File "/Users/saimanikanta/Desktop/ezapp/ez/frappe-bench/apps/frappe/frappe/utils/scheduler.py", line 128, in enqueue_events
    if job_type.enqueue():
       ~~~~~~~~~~~~~~~~^^
  File "/Users/saimanikanta/Desktop/ezapp/ez/frappe-bench/apps/frappe/frappe/core/doctype/scheduled_job_type/scheduled_job_type.py", line 71, in enqueue
    if not self.is_job_in_queue():
           ~~~~~~~~~~~~~~~~~~~~^^
  File "/Users/saimanikanta/Desktop/ezapp/ez/frappe-bench/apps/frappe/frappe/core/doctype/scheduled_job_type/scheduled_job_type.py", line 93, in is_job_in_queue
    return is_job_enqueued(self.rq_job_id)
  File "/Users/saimanikanta/Desktop/ezapp/ez/frappe-bench/apps/frappe/frappe/utils/background_jobs.py", line 618, in is_job_enqueued
    return get_job_status(job_id) in (JobStatus.QUEUED, JobStatus.STARTED)
           ~~~~~~~~~~~~~~^^^^^^^^
  File "/Users/saimanikanta/Desktop/ezapp/ez/frappe-bench/apps/frappe/frappe/utils/background_jobs.py", line 623, in get_job_status
    if job := get_job(job_id):
              ~~~~~~~^^^^^^^^
  File "/Users/saimanikanta/Desktop/ezapp/ez/frappe-bench/apps/frappe/frappe/utils/background_jobs.py", line 629, in get_job
    return Job.fetch(create_job_id(job_id), connection=get_redis_conn())
           ~~~~~~~~~^^^^^^^^^^^^^^^^^^^^^^^^^^^^^^^^^^^^^^^^^^^^^^^^^^^^
  File "/Users/saimanikanta/Desktop/ezapp/ez/frappe-bench/env/lib/python3.13/site-packages/rq/job.py", line 591, in fetch
    job.refresh()
    ~~~~~~~~~~~^^
  File "/Users/saimanikanta/Desktop/ezapp/ez/frappe-bench/env/lib/python3.13/site-packages/rq/job.py", line 991, in refresh
    data = self.connection.hgetall(self.key)
  File "/Users/saimanikanta/Desktop/ezapp/ez/frappe-bench/env/lib/python3.13/site-packages/redis/commands/core.py", line 4978, in hgetall
    return self.execute_command("HGETALL", name, keys=[name])
           ~~~~~~~~~~~~~~~~~~~~^^^^^^^^^^^^^^^^^^^^^^^^^^^^^^
  File "/Users/saimanikanta/Desktop/ezapp/ez/frappe-bench/env/lib/python3.13/site-packages/redis/client.py", line 559, in execute_command
    return self._execute_command(*args, **options)
           ~~~~~~~~~~~~~~~~~~~~~^^^^^^^^^^^^^^^^^^
  File "/Users/saimanikanta/Desktop/ezapp/ez/frappe-bench/env/lib/python3.13/site-packages/redis/client.py", line 565, in _execute_command
    conn = self.connection or pool.get_connection(command_name, **options)
                              ~~~~~~~~~~~~~~~~~~~^^^^^^^^^^^^^^^^^^^^^^^^^
  File "/Users/saimanikanta/Desktop/ezapp/ez/frappe-bench/env/lib/python3.13/site-packages/redis/connection.py", line 1422, in get_connection
    connection.connect()
    ~~~~~~~~~~~~~~~~~~^^
  File "/Users/saimanikanta/Desktop/ezapp/ez/frappe-bench/env/lib/python3.13/site-packages/redis/connection.py", line 363, in connect
    raise ConnectionError(self._error_message(e))
redis.exceptions.ConnectionError: Error 61 connecting to 127.0.0.1:11000. Connection refused.
2025-02-10 15:14:00,549 ERROR scheduler Exception in Enqueue Events for Site mysite.test
Traceback (most recent call last):
  File "/Users/saimanikanta/Desktop/ezapp/ez/frappe-bench/env/lib/python3.13/site-packages/redis/connection.py", line 357, in connect
    sock = self.retry.call_with_retry(
        lambda: self._connect(), lambda error: self.disconnect(error)
    )
  File "/Users/saimanikanta/Desktop/ezapp/ez/frappe-bench/env/lib/python3.13/site-packages/redis/retry.py", line 62, in call_with_retry
    return do()
  File "/Users/saimanikanta/Desktop/ezapp/ez/frappe-bench/env/lib/python3.13/site-packages/redis/connection.py", line 358, in <lambda>
    lambda: self._connect(), lambda error: self.disconnect(error)
            ~~~~~~~~~~~~~^^
  File "/Users/saimanikanta/Desktop/ezapp/ez/frappe-bench/env/lib/python3.13/site-packages/redis/connection.py", line 730, in _connect
    raise err
  File "/Users/saimanikanta/Desktop/ezapp/ez/frappe-bench/env/lib/python3.13/site-packages/redis/connection.py", line 718, in _connect
    sock.connect(socket_address)
    ~~~~~~~~~~~~^^^^^^^^^^^^^^^^
ConnectionRefusedError: [Errno 61] Connection refused

During handling of the above exception, another exception occurred:

Traceback (most recent call last):
  File "/Users/saimanikanta/Desktop/ezapp/ez/frappe-bench/apps/frappe/frappe/utils/scheduler.py", line 108, in enqueue_events_for_site
    enqueue_events()
    ~~~~~~~~~~~~~~^^
  File "/Users/saimanikanta/Desktop/ezapp/ez/frappe-bench/apps/frappe/frappe/utils/scheduler.py", line 128, in enqueue_events
    if job_type.enqueue():
       ~~~~~~~~~~~~~~~~^^
  File "/Users/saimanikanta/Desktop/ezapp/ez/frappe-bench/apps/frappe/frappe/core/doctype/scheduled_job_type/scheduled_job_type.py", line 71, in enqueue
    if not self.is_job_in_queue():
           ~~~~~~~~~~~~~~~~~~~~^^
  File "/Users/saimanikanta/Desktop/ezapp/ez/frappe-bench/apps/frappe/frappe/core/doctype/scheduled_job_type/scheduled_job_type.py", line 93, in is_job_in_queue
    return is_job_enqueued(self.rq_job_id)
  File "/Users/saimanikanta/Desktop/ezapp/ez/frappe-bench/apps/frappe/frappe/utils/background_jobs.py", line 618, in is_job_enqueued
    return get_job_status(job_id) in (JobStatus.QUEUED, JobStatus.STARTED)
           ~~~~~~~~~~~~~~^^^^^^^^
  File "/Users/saimanikanta/Desktop/ezapp/ez/frappe-bench/apps/frappe/frappe/utils/background_jobs.py", line 623, in get_job_status
    if job := get_job(job_id):
              ~~~~~~~^^^^^^^^
  File "/Users/saimanikanta/Desktop/ezapp/ez/frappe-bench/apps/frappe/frappe/utils/background_jobs.py", line 629, in get_job
    return Job.fetch(create_job_id(job_id), connection=get_redis_conn())
           ~~~~~~~~~^^^^^^^^^^^^^^^^^^^^^^^^^^^^^^^^^^^^^^^^^^^^^^^^^^^^
  File "/Users/saimanikanta/Desktop/ezapp/ez/frappe-bench/env/lib/python3.13/site-packages/rq/job.py", line 591, in fetch
    job.refresh()
    ~~~~~~~~~~~^^
  File "/Users/saimanikanta/Desktop/ezapp/ez/frappe-bench/env/lib/python3.13/site-packages/rq/job.py", line 991, in refresh
    data = self.connection.hgetall(self.key)
  File "/Users/saimanikanta/Desktop/ezapp/ez/frappe-bench/env/lib/python3.13/site-packages/redis/commands/core.py", line 4978, in hgetall
    return self.execute_command("HGETALL", name, keys=[name])
           ~~~~~~~~~~~~~~~~~~~~^^^^^^^^^^^^^^^^^^^^^^^^^^^^^^
  File "/Users/saimanikanta/Desktop/ezapp/ez/frappe-bench/env/lib/python3.13/site-packages/redis/client.py", line 559, in execute_command
    return self._execute_command(*args, **options)
           ~~~~~~~~~~~~~~~~~~~~~^^^^^^^^^^^^^^^^^^
  File "/Users/saimanikanta/Desktop/ezapp/ez/frappe-bench/env/lib/python3.13/site-packages/redis/client.py", line 565, in _execute_command
    conn = self.connection or pool.get_connection(command_name, **options)
                              ~~~~~~~~~~~~~~~~~~~^^^^^^^^^^^^^^^^^^^^^^^^^
  File "/Users/saimanikanta/Desktop/ezapp/ez/frappe-bench/env/lib/python3.13/site-packages/redis/connection.py", line 1422, in get_connection
    connection.connect()
    ~~~~~~~~~~~~~~~~~~^^
  File "/Users/saimanikanta/Desktop/ezapp/ez/frappe-bench/env/lib/python3.13/site-packages/redis/connection.py", line 363, in connect
    raise ConnectionError(self._error_message(e))
redis.exceptions.ConnectionError: Error 61 connecting to 127.0.0.1:11000. Connection refused.
2025-02-10 15:18:00,773 ERROR scheduler Exception in Enqueue Events for Site mysite.test
Traceback (most recent call last):
  File "/Users/saimanikanta/Desktop/ezapp/ez/frappe-bench/env/lib/python3.13/site-packages/redis/connection.py", line 357, in connect
    sock = self.retry.call_with_retry(
        lambda: self._connect(), lambda error: self.disconnect(error)
    )
  File "/Users/saimanikanta/Desktop/ezapp/ez/frappe-bench/env/lib/python3.13/site-packages/redis/retry.py", line 62, in call_with_retry
    return do()
  File "/Users/saimanikanta/Desktop/ezapp/ez/frappe-bench/env/lib/python3.13/site-packages/redis/connection.py", line 358, in <lambda>
    lambda: self._connect(), lambda error: self.disconnect(error)
            ~~~~~~~~~~~~~^^
  File "/Users/saimanikanta/Desktop/ezapp/ez/frappe-bench/env/lib/python3.13/site-packages/redis/connection.py", line 730, in _connect
    raise err
  File "/Users/saimanikanta/Desktop/ezapp/ez/frappe-bench/env/lib/python3.13/site-packages/redis/connection.py", line 718, in _connect
    sock.connect(socket_address)
    ~~~~~~~~~~~~^^^^^^^^^^^^^^^^
ConnectionRefusedError: [Errno 61] Connection refused

During handling of the above exception, another exception occurred:

Traceback (most recent call last):
  File "/Users/saimanikanta/Desktop/ezapp/ez/frappe-bench/apps/frappe/frappe/utils/scheduler.py", line 108, in enqueue_events_for_site
    enqueue_events()
    ~~~~~~~~~~~~~~^^
  File "/Users/saimanikanta/Desktop/ezapp/ez/frappe-bench/apps/frappe/frappe/utils/scheduler.py", line 128, in enqueue_events
    if job_type.enqueue():
       ~~~~~~~~~~~~~~~~^^
  File "/Users/saimanikanta/Desktop/ezapp/ez/frappe-bench/apps/frappe/frappe/core/doctype/scheduled_job_type/scheduled_job_type.py", line 71, in enqueue
    if not self.is_job_in_queue():
           ~~~~~~~~~~~~~~~~~~~~^^
  File "/Users/saimanikanta/Desktop/ezapp/ez/frappe-bench/apps/frappe/frappe/core/doctype/scheduled_job_type/scheduled_job_type.py", line 93, in is_job_in_queue
    return is_job_enqueued(self.rq_job_id)
  File "/Users/saimanikanta/Desktop/ezapp/ez/frappe-bench/apps/frappe/frappe/utils/background_jobs.py", line 618, in is_job_enqueued
    return get_job_status(job_id) in (JobStatus.QUEUED, JobStatus.STARTED)
           ~~~~~~~~~~~~~~^^^^^^^^
  File "/Users/saimanikanta/Desktop/ezapp/ez/frappe-bench/apps/frappe/frappe/utils/background_jobs.py", line 623, in get_job_status
    if job := get_job(job_id):
              ~~~~~~~^^^^^^^^
  File "/Users/saimanikanta/Desktop/ezapp/ez/frappe-bench/apps/frappe/frappe/utils/background_jobs.py", line 629, in get_job
    return Job.fetch(create_job_id(job_id), connection=get_redis_conn())
           ~~~~~~~~~^^^^^^^^^^^^^^^^^^^^^^^^^^^^^^^^^^^^^^^^^^^^^^^^^^^^
  File "/Users/saimanikanta/Desktop/ezapp/ez/frappe-bench/env/lib/python3.13/site-packages/rq/job.py", line 591, in fetch
    job.refresh()
    ~~~~~~~~~~~^^
  File "/Users/saimanikanta/Desktop/ezapp/ez/frappe-bench/env/lib/python3.13/site-packages/rq/job.py", line 991, in refresh
    data = self.connection.hgetall(self.key)
  File "/Users/saimanikanta/Desktop/ezapp/ez/frappe-bench/env/lib/python3.13/site-packages/redis/commands/core.py", line 4978, in hgetall
    return self.execute_command("HGETALL", name, keys=[name])
           ~~~~~~~~~~~~~~~~~~~~^^^^^^^^^^^^^^^^^^^^^^^^^^^^^^
  File "/Users/saimanikanta/Desktop/ezapp/ez/frappe-bench/env/lib/python3.13/site-packages/redis/client.py", line 559, in execute_command
    return self._execute_command(*args, **options)
           ~~~~~~~~~~~~~~~~~~~~~^^^^^^^^^^^^^^^^^^
  File "/Users/saimanikanta/Desktop/ezapp/ez/frappe-bench/env/lib/python3.13/site-packages/redis/client.py", line 565, in _execute_command
    conn = self.connection or pool.get_connection(command_name, **options)
                              ~~~~~~~~~~~~~~~~~~~^^^^^^^^^^^^^^^^^^^^^^^^^
  File "/Users/saimanikanta/Desktop/ezapp/ez/frappe-bench/env/lib/python3.13/site-packages/redis/connection.py", line 1422, in get_connection
    connection.connect()
    ~~~~~~~~~~~~~~~~~~^^
  File "/Users/saimanikanta/Desktop/ezapp/ez/frappe-bench/env/lib/python3.13/site-packages/redis/connection.py", line 363, in connect
    raise ConnectionError(self._error_message(e))
redis.exceptions.ConnectionError: Error 61 connecting to 127.0.0.1:11000. Connection refused.
2025-02-10 15:22:01,339 ERROR scheduler Exception in Enqueue Events for Site mysite.test
Traceback (most recent call last):
  File "/Users/saimanikanta/Desktop/ezapp/ez/frappe-bench/env/lib/python3.13/site-packages/redis/connection.py", line 357, in connect
    sock = self.retry.call_with_retry(
        lambda: self._connect(), lambda error: self.disconnect(error)
    )
  File "/Users/saimanikanta/Desktop/ezapp/ez/frappe-bench/env/lib/python3.13/site-packages/redis/retry.py", line 62, in call_with_retry
    return do()
  File "/Users/saimanikanta/Desktop/ezapp/ez/frappe-bench/env/lib/python3.13/site-packages/redis/connection.py", line 358, in <lambda>
    lambda: self._connect(), lambda error: self.disconnect(error)
            ~~~~~~~~~~~~~^^
  File "/Users/saimanikanta/Desktop/ezapp/ez/frappe-bench/env/lib/python3.13/site-packages/redis/connection.py", line 730, in _connect
    raise err
  File "/Users/saimanikanta/Desktop/ezapp/ez/frappe-bench/env/lib/python3.13/site-packages/redis/connection.py", line 718, in _connect
    sock.connect(socket_address)
    ~~~~~~~~~~~~^^^^^^^^^^^^^^^^
ConnectionRefusedError: [Errno 61] Connection refused

During handling of the above exception, another exception occurred:

Traceback (most recent call last):
  File "/Users/saimanikanta/Desktop/ezapp/ez/frappe-bench/apps/frappe/frappe/utils/scheduler.py", line 108, in enqueue_events_for_site
    enqueue_events()
    ~~~~~~~~~~~~~~^^
  File "/Users/saimanikanta/Desktop/ezapp/ez/frappe-bench/apps/frappe/frappe/utils/scheduler.py", line 128, in enqueue_events
    if job_type.enqueue():
       ~~~~~~~~~~~~~~~~^^
  File "/Users/saimanikanta/Desktop/ezapp/ez/frappe-bench/apps/frappe/frappe/core/doctype/scheduled_job_type/scheduled_job_type.py", line 71, in enqueue
    if not self.is_job_in_queue():
           ~~~~~~~~~~~~~~~~~~~~^^
  File "/Users/saimanikanta/Desktop/ezapp/ez/frappe-bench/apps/frappe/frappe/core/doctype/scheduled_job_type/scheduled_job_type.py", line 93, in is_job_in_queue
    return is_job_enqueued(self.rq_job_id)
  File "/Users/saimanikanta/Desktop/ezapp/ez/frappe-bench/apps/frappe/frappe/utils/background_jobs.py", line 618, in is_job_enqueued
    return get_job_status(job_id) in (JobStatus.QUEUED, JobStatus.STARTED)
           ~~~~~~~~~~~~~~^^^^^^^^
  File "/Users/saimanikanta/Desktop/ezapp/ez/frappe-bench/apps/frappe/frappe/utils/background_jobs.py", line 623, in get_job_status
    if job := get_job(job_id):
              ~~~~~~~^^^^^^^^
  File "/Users/saimanikanta/Desktop/ezapp/ez/frappe-bench/apps/frappe/frappe/utils/background_jobs.py", line 629, in get_job
    return Job.fetch(create_job_id(job_id), connection=get_redis_conn())
           ~~~~~~~~~^^^^^^^^^^^^^^^^^^^^^^^^^^^^^^^^^^^^^^^^^^^^^^^^^^^^
  File "/Users/saimanikanta/Desktop/ezapp/ez/frappe-bench/env/lib/python3.13/site-packages/rq/job.py", line 591, in fetch
    job.refresh()
    ~~~~~~~~~~~^^
  File "/Users/saimanikanta/Desktop/ezapp/ez/frappe-bench/env/lib/python3.13/site-packages/rq/job.py", line 991, in refresh
    data = self.connection.hgetall(self.key)
  File "/Users/saimanikanta/Desktop/ezapp/ez/frappe-bench/env/lib/python3.13/site-packages/redis/commands/core.py", line 4978, in hgetall
    return self.execute_command("HGETALL", name, keys=[name])
           ~~~~~~~~~~~~~~~~~~~~^^^^^^^^^^^^^^^^^^^^^^^^^^^^^^
  File "/Users/saimanikanta/Desktop/ezapp/ez/frappe-bench/env/lib/python3.13/site-packages/redis/client.py", line 559, in execute_command
    return self._execute_command(*args, **options)
           ~~~~~~~~~~~~~~~~~~~~~^^^^^^^^^^^^^^^^^^
  File "/Users/saimanikanta/Desktop/ezapp/ez/frappe-bench/env/lib/python3.13/site-packages/redis/client.py", line 565, in _execute_command
    conn = self.connection or pool.get_connection(command_name, **options)
                              ~~~~~~~~~~~~~~~~~~~^^^^^^^^^^^^^^^^^^^^^^^^^
  File "/Users/saimanikanta/Desktop/ezapp/ez/frappe-bench/env/lib/python3.13/site-packages/redis/connection.py", line 1422, in get_connection
    connection.connect()
    ~~~~~~~~~~~~~~~~~~^^
  File "/Users/saimanikanta/Desktop/ezapp/ez/frappe-bench/env/lib/python3.13/site-packages/redis/connection.py", line 363, in connect
    raise ConnectionError(self._error_message(e))
redis.exceptions.ConnectionError: Error 61 connecting to 127.0.0.1:11000. Connection refused.
