2025-02-10 14:10:00,631 ERROR scheduler Exception in Enqueue Events for Site money.test
Traceback (most recent call last):
  File "/Users/saimanikanta/Desktop/ezapp/ez/frappe-bench/apps/frappe/frappe/utils/scheduler.py", line 105, in enqueue_events_for_site
    if is_scheduler_inactive():
       ~~~~~~~~~~~~~~~~~~~~~^^
  File "/Users/saimanikanta/Desktop/ezapp/ez/frappe-bench/apps/frappe/frappe/utils/scheduler.py", line 149, in is_scheduler_inactive
    if is_scheduler_disabled(verbose=verbose):
       ~~~~~~~~~~~~~~~~~~~~~^^^^^^^^^^^^^^^^^
  File "/Users/saimanikanta/Desktop/ezapp/ez/frappe-bench/apps/frappe/frappe/utils/scheduler.py", line 162, in is_scheduler_disabled
    frappe.db.get_single_value("System Settings", "enable_scheduler")
    ~~~~~~~~~~~~~~~~~~~~~~~~~~^^^^^^^^^^^^^^^^^^^^^^^^^^^^^^^^^^^^^^^
  File "/Users/saimanikanta/Desktop/ezapp/ez/frappe-bench/apps/frappe/frappe/database/database.py", line 869, in get_single_value
    ).run()
      ~~~^^
  File "/Users/saimanikanta/Desktop/ezapp/ez/frappe-bench/apps/frappe/frappe/query_builder/utils.py", line 84, in execute_query
    result = frappe.db.sql(query, params, *args, **kwargs)  # nosemgrep
  File "/Users/saimanikanta/Desktop/ezapp/ez/frappe-bench/apps/frappe/frappe/database/database.py", line 215, in sql
    self.connect()
    ~~~~~~~~~~~~^^
  File "/Users/saimanikanta/Desktop/ezapp/ez/frappe-bench/apps/frappe/frappe/database/database.py", line 120, in connect
    self._conn: MariadbConnection | PostgresConnection = self.get_connection()
                                                         ~~~~~~~~~~~~~~~~~~~^^
  File "/Users/saimanikanta/Desktop/ezapp/ez/frappe-bench/apps/frappe/frappe/database/mariadb/database.py", line 107, in get_connection
    conn = self._get_connection()
  File "/Users/saimanikanta/Desktop/ezapp/ez/frappe-bench/apps/frappe/frappe/database/mariadb/database.py", line 113, in _get_connection
    return self.create_connection()
           ~~~~~~~~~~~~~~~~~~~~~~^^
  File "/Users/saimanikanta/Desktop/ezapp/ez/frappe-bench/apps/frappe/frappe/database/mariadb/database.py", line 116, in create_connection
    return pymysql.connect(**self.get_connection_settings())
           ~~~~~~~~~~~~~~~^^^^^^^^^^^^^^^^^^^^^^^^^^^^^^^^^^
  File "/Users/saimanikanta/Desktop/ezapp/ez/frappe-bench/env/lib/python3.13/site-packages/pymysql/connections.py", line 361, in __init__
    self.connect()
    ~~~~~~~~~~~~^^
  File "/Users/saimanikanta/Desktop/ezapp/ez/frappe-bench/env/lib/python3.13/site-packages/pymysql/connections.py", line 669, in connect
    self._request_authentication()
    ~~~~~~~~~~~~~~~~~~~~~~~~~~~~^^
  File "/Users/saimanikanta/Desktop/ezapp/ez/frappe-bench/env/lib/python3.13/site-packages/pymysql/connections.py", line 957, in _request_authentication
    auth_packet = self._read_packet()
  File "/Users/saimanikanta/Desktop/ezapp/ez/frappe-bench/env/lib/python3.13/site-packages/pymysql/connections.py", line 775, in _read_packet
    packet.raise_for_error()
    ~~~~~~~~~~~~~~~~~~~~~~^^
  File "/Users/saimanikanta/Desktop/ezapp/ez/frappe-bench/env/lib/python3.13/site-packages/pymysql/protocol.py", line 219, in raise_for_error
    err.raise_mysql_exception(self._data)
    ~~~~~~~~~~~~~~~~~~~~~~~~~^^^^^^^^^^^^
  File "/Users/saimanikanta/Desktop/ezapp/ez/frappe-bench/env/lib/python3.13/site-packages/pymysql/err.py", line 150, in raise_mysql_exception
    raise errorclass(errno, errval)
pymysql.err.OperationalError: (1044, "Access denied for user '_7c5f4f77b0d74777'@'localhost' to database 'f77b0d74777_7c5f4'")
2025-02-10 14:14:00,645 ERROR scheduler Exception in Enqueue Events for Site money.test
Traceback (most recent call last):
  File "/Users/saimanikanta/Desktop/ezapp/ez/frappe-bench/apps/frappe/frappe/utils/scheduler.py", line 105, in enqueue_events_for_site
    if is_scheduler_inactive():
       ~~~~~~~~~~~~~~~~~~~~~^^
  File "/Users/saimanikanta/Desktop/ezapp/ez/frappe-bench/apps/frappe/frappe/utils/scheduler.py", line 149, in is_scheduler_inactive
    if is_scheduler_disabled(verbose=verbose):
       ~~~~~~~~~~~~~~~~~~~~~^^^^^^^^^^^^^^^^^
  File "/Users/saimanikanta/Desktop/ezapp/ez/frappe-bench/apps/frappe/frappe/utils/scheduler.py", line 162, in is_scheduler_disabled
    frappe.db.get_single_value("System Settings", "enable_scheduler")
    ~~~~~~~~~~~~~~~~~~~~~~~~~~^^^^^^^^^^^^^^^^^^^^^^^^^^^^^^^^^^^^^^^
  File "/Users/saimanikanta/Desktop/ezapp/ez/frappe-bench/apps/frappe/frappe/database/database.py", line 869, in get_single_value
    ).run()
      ~~~^^
  File "/Users/saimanikanta/Desktop/ezapp/ez/frappe-bench/apps/frappe/frappe/query_builder/utils.py", line 84, in execute_query
    result = frappe.db.sql(query, params, *args, **kwargs)  # nosemgrep
  File "/Users/saimanikanta/Desktop/ezapp/ez/frappe-bench/apps/frappe/frappe/database/database.py", line 215, in sql
    self.connect()
    ~~~~~~~~~~~~^^
  File "/Users/saimanikanta/Desktop/ezapp/ez/frappe-bench/apps/frappe/frappe/database/database.py", line 120, in connect
    self._conn: MariadbConnection | PostgresConnection = self.get_connection()
                                                         ~~~~~~~~~~~~~~~~~~~^^
  File "/Users/saimanikanta/Desktop/ezapp/ez/frappe-bench/apps/frappe/frappe/database/mariadb/database.py", line 107, in get_connection
    conn = self._get_connection()
  File "/Users/saimanikanta/Desktop/ezapp/ez/frappe-bench/apps/frappe/frappe/database/mariadb/database.py", line 113, in _get_connection
    return self.create_connection()
           ~~~~~~~~~~~~~~~~~~~~~~^^
  File "/Users/saimanikanta/Desktop/ezapp/ez/frappe-bench/apps/frappe/frappe/database/mariadb/database.py", line 116, in create_connection
    return pymysql.connect(**self.get_connection_settings())
           ~~~~~~~~~~~~~~~^^^^^^^^^^^^^^^^^^^^^^^^^^^^^^^^^^
  File "/Users/saimanikanta/Desktop/ezapp/ez/frappe-bench/env/lib/python3.13/site-packages/pymysql/connections.py", line 361, in __init__
    self.connect()
    ~~~~~~~~~~~~^^
  File "/Users/saimanikanta/Desktop/ezapp/ez/frappe-bench/env/lib/python3.13/site-packages/pymysql/connections.py", line 669, in connect
    self._request_authentication()
    ~~~~~~~~~~~~~~~~~~~~~~~~~~~~^^
  File "/Users/saimanikanta/Desktop/ezapp/ez/frappe-bench/env/lib/python3.13/site-packages/pymysql/connections.py", line 957, in _request_authentication
    auth_packet = self._read_packet()
  File "/Users/saimanikanta/Desktop/ezapp/ez/frappe-bench/env/lib/python3.13/site-packages/pymysql/connections.py", line 775, in _read_packet
    packet.raise_for_error()
    ~~~~~~~~~~~~~~~~~~~~~~^^
  File "/Users/saimanikanta/Desktop/ezapp/ez/frappe-bench/env/lib/python3.13/site-packages/pymysql/protocol.py", line 219, in raise_for_error
    err.raise_mysql_exception(self._data)
    ~~~~~~~~~~~~~~~~~~~~~~~~~^^^^^^^^^^^^
  File "/Users/saimanikanta/Desktop/ezapp/ez/frappe-bench/env/lib/python3.13/site-packages/pymysql/err.py", line 150, in raise_mysql_exception
    raise errorclass(errno, errval)
pymysql.err.OperationalError: (1044, "Access denied for user '_7c5f4f77b0d74777'@'localhost' to database 'f77b0d74777_7c5f4'")
2025-02-10 14:18:00,754 ERROR scheduler Exception in Enqueue Events for Site money.test
Traceback (most recent call last):
  File "/Users/saimanikanta/Desktop/ezapp/ez/frappe-bench/apps/frappe/frappe/utils/scheduler.py", line 105, in enqueue_events_for_site
    if is_scheduler_inactive():
       ~~~~~~~~~~~~~~~~~~~~~^^
  File "/Users/saimanikanta/Desktop/ezapp/ez/frappe-bench/apps/frappe/frappe/utils/scheduler.py", line 149, in is_scheduler_inactive
    if is_scheduler_disabled(verbose=verbose):
       ~~~~~~~~~~~~~~~~~~~~~^^^^^^^^^^^^^^^^^
  File "/Users/saimanikanta/Desktop/ezapp/ez/frappe-bench/apps/frappe/frappe/utils/scheduler.py", line 162, in is_scheduler_disabled
    frappe.db.get_single_value("System Settings", "enable_scheduler")
    ~~~~~~~~~~~~~~~~~~~~~~~~~~^^^^^^^^^^^^^^^^^^^^^^^^^^^^^^^^^^^^^^^
  File "/Users/saimanikanta/Desktop/ezapp/ez/frappe-bench/apps/frappe/frappe/database/database.py", line 869, in get_single_value
    ).run()
      ~~~^^
  File "/Users/saimanikanta/Desktop/ezapp/ez/frappe-bench/apps/frappe/frappe/query_builder/utils.py", line 84, in execute_query
    result = frappe.db.sql(query, params, *args, **kwargs)  # nosemgrep
  File "/Users/saimanikanta/Desktop/ezapp/ez/frappe-bench/apps/frappe/frappe/database/database.py", line 215, in sql
    self.connect()
    ~~~~~~~~~~~~^^
  File "/Users/saimanikanta/Desktop/ezapp/ez/frappe-bench/apps/frappe/frappe/database/database.py", line 120, in connect
    self._conn: MariadbConnection | PostgresConnection = self.get_connection()
                                                         ~~~~~~~~~~~~~~~~~~~^^
  File "/Users/saimanikanta/Desktop/ezapp/ez/frappe-bench/apps/frappe/frappe/database/mariadb/database.py", line 107, in get_connection
    conn = self._get_connection()
  File "/Users/saimanikanta/Desktop/ezapp/ez/frappe-bench/apps/frappe/frappe/database/mariadb/database.py", line 113, in _get_connection
    return self.create_connection()
           ~~~~~~~~~~~~~~~~~~~~~~^^
  File "/Users/saimanikanta/Desktop/ezapp/ez/frappe-bench/apps/frappe/frappe/database/mariadb/database.py", line 116, in create_connection
    return pymysql.connect(**self.get_connection_settings())
           ~~~~~~~~~~~~~~~^^^^^^^^^^^^^^^^^^^^^^^^^^^^^^^^^^
  File "/Users/saimanikanta/Desktop/ezapp/ez/frappe-bench/env/lib/python3.13/site-packages/pymysql/connections.py", line 361, in __init__
    self.connect()
    ~~~~~~~~~~~~^^
  File "/Users/saimanikanta/Desktop/ezapp/ez/frappe-bench/env/lib/python3.13/site-packages/pymysql/connections.py", line 669, in connect
    self._request_authentication()
    ~~~~~~~~~~~~~~~~~~~~~~~~~~~~^^
  File "/Users/saimanikanta/Desktop/ezapp/ez/frappe-bench/env/lib/python3.13/site-packages/pymysql/connections.py", line 957, in _request_authentication
    auth_packet = self._read_packet()
  File "/Users/saimanikanta/Desktop/ezapp/ez/frappe-bench/env/lib/python3.13/site-packages/pymysql/connections.py", line 775, in _read_packet
    packet.raise_for_error()
    ~~~~~~~~~~~~~~~~~~~~~~^^
  File "/Users/saimanikanta/Desktop/ezapp/ez/frappe-bench/env/lib/python3.13/site-packages/pymysql/protocol.py", line 219, in raise_for_error
    err.raise_mysql_exception(self._data)
    ~~~~~~~~~~~~~~~~~~~~~~~~~^^^^^^^^^^^^
  File "/Users/saimanikanta/Desktop/ezapp/ez/frappe-bench/env/lib/python3.13/site-packages/pymysql/err.py", line 150, in raise_mysql_exception
    raise errorclass(errno, errval)
pymysql.err.OperationalError: (1044, "Access denied for user '_7c5f4f77b0d74777'@'localhost' to database 'f77b0d74777_7c5f4'")
2025-02-10 14:22:00,827 ERROR scheduler Exception in Enqueue Events for Site money.test
Traceback (most recent call last):
  File "/Users/saimanikanta/Desktop/ezapp/ez/frappe-bench/apps/frappe/frappe/utils/scheduler.py", line 105, in enqueue_events_for_site
    if is_scheduler_inactive():
       ~~~~~~~~~~~~~~~~~~~~~^^
  File "/Users/saimanikanta/Desktop/ezapp/ez/frappe-bench/apps/frappe/frappe/utils/scheduler.py", line 149, in is_scheduler_inactive
    if is_scheduler_disabled(verbose=verbose):
       ~~~~~~~~~~~~~~~~~~~~~^^^^^^^^^^^^^^^^^
  File "/Users/saimanikanta/Desktop/ezapp/ez/frappe-bench/apps/frappe/frappe/utils/scheduler.py", line 162, in is_scheduler_disabled
    frappe.db.get_single_value("System Settings", "enable_scheduler")
    ~~~~~~~~~~~~~~~~~~~~~~~~~~^^^^^^^^^^^^^^^^^^^^^^^^^^^^^^^^^^^^^^^
  File "/Users/saimanikanta/Desktop/ezapp/ez/frappe-bench/apps/frappe/frappe/database/database.py", line 869, in get_single_value
    ).run()
      ~~~^^
  File "/Users/saimanikanta/Desktop/ezapp/ez/frappe-bench/apps/frappe/frappe/query_builder/utils.py", line 84, in execute_query
    result = frappe.db.sql(query, params, *args, **kwargs)  # nosemgrep
  File "/Users/saimanikanta/Desktop/ezapp/ez/frappe-bench/apps/frappe/frappe/database/database.py", line 215, in sql
    self.connect()
    ~~~~~~~~~~~~^^
  File "/Users/saimanikanta/Desktop/ezapp/ez/frappe-bench/apps/frappe/frappe/database/database.py", line 120, in connect
    self._conn: MariadbConnection | PostgresConnection = self.get_connection()
                                                         ~~~~~~~~~~~~~~~~~~~^^
  File "/Users/saimanikanta/Desktop/ezapp/ez/frappe-bench/apps/frappe/frappe/database/mariadb/database.py", line 107, in get_connection
    conn = self._get_connection()
  File "/Users/saimanikanta/Desktop/ezapp/ez/frappe-bench/apps/frappe/frappe/database/mariadb/database.py", line 113, in _get_connection
    return self.create_connection()
           ~~~~~~~~~~~~~~~~~~~~~~^^
  File "/Users/saimanikanta/Desktop/ezapp/ez/frappe-bench/apps/frappe/frappe/database/mariadb/database.py", line 116, in create_connection
    return pymysql.connect(**self.get_connection_settings())
           ~~~~~~~~~~~~~~~^^^^^^^^^^^^^^^^^^^^^^^^^^^^^^^^^^
  File "/Users/saimanikanta/Desktop/ezapp/ez/frappe-bench/env/lib/python3.13/site-packages/pymysql/connections.py", line 361, in __init__
    self.connect()
    ~~~~~~~~~~~~^^
  File "/Users/saimanikanta/Desktop/ezapp/ez/frappe-bench/env/lib/python3.13/site-packages/pymysql/connections.py", line 669, in connect
    self._request_authentication()
    ~~~~~~~~~~~~~~~~~~~~~~~~~~~~^^
  File "/Users/saimanikanta/Desktop/ezapp/ez/frappe-bench/env/lib/python3.13/site-packages/pymysql/connections.py", line 957, in _request_authentication
    auth_packet = self._read_packet()
  File "/Users/saimanikanta/Desktop/ezapp/ez/frappe-bench/env/lib/python3.13/site-packages/pymysql/connections.py", line 775, in _read_packet
    packet.raise_for_error()
    ~~~~~~~~~~~~~~~~~~~~~~^^
  File "/Users/saimanikanta/Desktop/ezapp/ez/frappe-bench/env/lib/python3.13/site-packages/pymysql/protocol.py", line 219, in raise_for_error
    err.raise_mysql_exception(self._data)
    ~~~~~~~~~~~~~~~~~~~~~~~~~^^^^^^^^^^^^
  File "/Users/saimanikanta/Desktop/ezapp/ez/frappe-bench/env/lib/python3.13/site-packages/pymysql/err.py", line 150, in raise_mysql_exception
    raise errorclass(errno, errval)
pymysql.err.OperationalError: (1044, "Access denied for user '_7c5f4f77b0d74777'@'localhost' to database 'f77b0d74777_7c5f4'")
2025-02-10 14:26:00,840 ERROR scheduler Exception in Enqueue Events for Site money.test
Traceback (most recent call last):
  File "/Users/saimanikanta/Desktop/ezapp/ez/frappe-bench/apps/frappe/frappe/utils/scheduler.py", line 105, in enqueue_events_for_site
    if is_scheduler_inactive():
       ~~~~~~~~~~~~~~~~~~~~~^^
  File "/Users/saimanikanta/Desktop/ezapp/ez/frappe-bench/apps/frappe/frappe/utils/scheduler.py", line 149, in is_scheduler_inactive
    if is_scheduler_disabled(verbose=verbose):
       ~~~~~~~~~~~~~~~~~~~~~^^^^^^^^^^^^^^^^^
  File "/Users/saimanikanta/Desktop/ezapp/ez/frappe-bench/apps/frappe/frappe/utils/scheduler.py", line 162, in is_scheduler_disabled
    frappe.db.get_single_value("System Settings", "enable_scheduler")
    ~~~~~~~~~~~~~~~~~~~~~~~~~~^^^^^^^^^^^^^^^^^^^^^^^^^^^^^^^^^^^^^^^
  File "/Users/saimanikanta/Desktop/ezapp/ez/frappe-bench/apps/frappe/frappe/database/database.py", line 869, in get_single_value
    ).run()
      ~~~^^
  File "/Users/saimanikanta/Desktop/ezapp/ez/frappe-bench/apps/frappe/frappe/query_builder/utils.py", line 84, in execute_query
    result = frappe.db.sql(query, params, *args, **kwargs)  # nosemgrep
  File "/Users/saimanikanta/Desktop/ezapp/ez/frappe-bench/apps/frappe/frappe/database/database.py", line 215, in sql
    self.connect()
    ~~~~~~~~~~~~^^
  File "/Users/saimanikanta/Desktop/ezapp/ez/frappe-bench/apps/frappe/frappe/database/database.py", line 120, in connect
    self._conn: MariadbConnection | PostgresConnection = self.get_connection()
                                                         ~~~~~~~~~~~~~~~~~~~^^
  File "/Users/saimanikanta/Desktop/ezapp/ez/frappe-bench/apps/frappe/frappe/database/mariadb/database.py", line 107, in get_connection
    conn = self._get_connection()
  File "/Users/saimanikanta/Desktop/ezapp/ez/frappe-bench/apps/frappe/frappe/database/mariadb/database.py", line 113, in _get_connection
    return self.create_connection()
           ~~~~~~~~~~~~~~~~~~~~~~^^
  File "/Users/saimanikanta/Desktop/ezapp/ez/frappe-bench/apps/frappe/frappe/database/mariadb/database.py", line 116, in create_connection
    return pymysql.connect(**self.get_connection_settings())
           ~~~~~~~~~~~~~~~^^^^^^^^^^^^^^^^^^^^^^^^^^^^^^^^^^
  File "/Users/saimanikanta/Desktop/ezapp/ez/frappe-bench/env/lib/python3.13/site-packages/pymysql/connections.py", line 361, in __init__
    self.connect()
    ~~~~~~~~~~~~^^
  File "/Users/saimanikanta/Desktop/ezapp/ez/frappe-bench/env/lib/python3.13/site-packages/pymysql/connections.py", line 669, in connect
    self._request_authentication()
    ~~~~~~~~~~~~~~~~~~~~~~~~~~~~^^
  File "/Users/saimanikanta/Desktop/ezapp/ez/frappe-bench/env/lib/python3.13/site-packages/pymysql/connections.py", line 957, in _request_authentication
    auth_packet = self._read_packet()
  File "/Users/saimanikanta/Desktop/ezapp/ez/frappe-bench/env/lib/python3.13/site-packages/pymysql/connections.py", line 775, in _read_packet
    packet.raise_for_error()
    ~~~~~~~~~~~~~~~~~~~~~~^^
  File "/Users/saimanikanta/Desktop/ezapp/ez/frappe-bench/env/lib/python3.13/site-packages/pymysql/protocol.py", line 219, in raise_for_error
    err.raise_mysql_exception(self._data)
    ~~~~~~~~~~~~~~~~~~~~~~~~~^^^^^^^^^^^^
  File "/Users/saimanikanta/Desktop/ezapp/ez/frappe-bench/env/lib/python3.13/site-packages/pymysql/err.py", line 150, in raise_mysql_exception
    raise errorclass(errno, errval)
pymysql.err.OperationalError: (1044, "Access denied for user '_7c5f4f77b0d74777'@'localhost' to database 'f77b0d74777_7c5f4'")
2025-02-10 14:30:00,901 ERROR scheduler Exception in Enqueue Events for Site money.test
Traceback (most recent call last):
  File "/Users/saimanikanta/Desktop/ezapp/ez/frappe-bench/apps/frappe/frappe/utils/scheduler.py", line 105, in enqueue_events_for_site
    if is_scheduler_inactive():
       ~~~~~~~~~~~~~~~~~~~~~^^
  File "/Users/saimanikanta/Desktop/ezapp/ez/frappe-bench/apps/frappe/frappe/utils/scheduler.py", line 149, in is_scheduler_inactive
    if is_scheduler_disabled(verbose=verbose):
       ~~~~~~~~~~~~~~~~~~~~~^^^^^^^^^^^^^^^^^
  File "/Users/saimanikanta/Desktop/ezapp/ez/frappe-bench/apps/frappe/frappe/utils/scheduler.py", line 162, in is_scheduler_disabled
    frappe.db.get_single_value("System Settings", "enable_scheduler")
    ~~~~~~~~~~~~~~~~~~~~~~~~~~^^^^^^^^^^^^^^^^^^^^^^^^^^^^^^^^^^^^^^^
  File "/Users/saimanikanta/Desktop/ezapp/ez/frappe-bench/apps/frappe/frappe/database/database.py", line 869, in get_single_value
    ).run()
      ~~~^^
  File "/Users/saimanikanta/Desktop/ezapp/ez/frappe-bench/apps/frappe/frappe/query_builder/utils.py", line 84, in execute_query
    result = frappe.db.sql(query, params, *args, **kwargs)  # nosemgrep
  File "/Users/saimanikanta/Desktop/ezapp/ez/frappe-bench/apps/frappe/frappe/database/database.py", line 215, in sql
    self.connect()
    ~~~~~~~~~~~~^^
  File "/Users/saimanikanta/Desktop/ezapp/ez/frappe-bench/apps/frappe/frappe/database/database.py", line 120, in connect
    self._conn: MariadbConnection | PostgresConnection = self.get_connection()
                                                         ~~~~~~~~~~~~~~~~~~~^^
  File "/Users/saimanikanta/Desktop/ezapp/ez/frappe-bench/apps/frappe/frappe/database/mariadb/database.py", line 107, in get_connection
    conn = self._get_connection()
  File "/Users/saimanikanta/Desktop/ezapp/ez/frappe-bench/apps/frappe/frappe/database/mariadb/database.py", line 113, in _get_connection
    return self.create_connection()
           ~~~~~~~~~~~~~~~~~~~~~~^^
  File "/Users/saimanikanta/Desktop/ezapp/ez/frappe-bench/apps/frappe/frappe/database/mariadb/database.py", line 116, in create_connection
    return pymysql.connect(**self.get_connection_settings())
           ~~~~~~~~~~~~~~~^^^^^^^^^^^^^^^^^^^^^^^^^^^^^^^^^^
  File "/Users/saimanikanta/Desktop/ezapp/ez/frappe-bench/env/lib/python3.13/site-packages/pymysql/connections.py", line 361, in __init__
    self.connect()
    ~~~~~~~~~~~~^^
  File "/Users/saimanikanta/Desktop/ezapp/ez/frappe-bench/env/lib/python3.13/site-packages/pymysql/connections.py", line 669, in connect
    self._request_authentication()
    ~~~~~~~~~~~~~~~~~~~~~~~~~~~~^^
  File "/Users/saimanikanta/Desktop/ezapp/ez/frappe-bench/env/lib/python3.13/site-packages/pymysql/connections.py", line 957, in _request_authentication
    auth_packet = self._read_packet()
  File "/Users/saimanikanta/Desktop/ezapp/ez/frappe-bench/env/lib/python3.13/site-packages/pymysql/connections.py", line 775, in _read_packet
    packet.raise_for_error()
    ~~~~~~~~~~~~~~~~~~~~~~^^
  File "/Users/saimanikanta/Desktop/ezapp/ez/frappe-bench/env/lib/python3.13/site-packages/pymysql/protocol.py", line 219, in raise_for_error
    err.raise_mysql_exception(self._data)
    ~~~~~~~~~~~~~~~~~~~~~~~~~^^^^^^^^^^^^
  File "/Users/saimanikanta/Desktop/ezapp/ez/frappe-bench/env/lib/python3.13/site-packages/pymysql/err.py", line 150, in raise_mysql_exception
    raise errorclass(errno, errval)
pymysql.err.OperationalError: (1044, "Access denied for user '_7c5f4f77b0d74777'@'localhost' to database 'f77b0d74777_7c5f4'")
2025-02-10 14:34:01,031 ERROR scheduler Exception in Enqueue Events for Site money.test
Traceback (most recent call last):
  File "/Users/saimanikanta/Desktop/ezapp/ez/frappe-bench/apps/frappe/frappe/utils/scheduler.py", line 105, in enqueue_events_for_site
    if is_scheduler_inactive():
       ~~~~~~~~~~~~~~~~~~~~~^^
  File "/Users/saimanikanta/Desktop/ezapp/ez/frappe-bench/apps/frappe/frappe/utils/scheduler.py", line 149, in is_scheduler_inactive
    if is_scheduler_disabled(verbose=verbose):
       ~~~~~~~~~~~~~~~~~~~~~^^^^^^^^^^^^^^^^^
  File "/Users/saimanikanta/Desktop/ezapp/ez/frappe-bench/apps/frappe/frappe/utils/scheduler.py", line 162, in is_scheduler_disabled
    frappe.db.get_single_value("System Settings", "enable_scheduler")
    ~~~~~~~~~~~~~~~~~~~~~~~~~~^^^^^^^^^^^^^^^^^^^^^^^^^^^^^^^^^^^^^^^
  File "/Users/saimanikanta/Desktop/ezapp/ez/frappe-bench/apps/frappe/frappe/database/database.py", line 869, in get_single_value
    ).run()
      ~~~^^
  File "/Users/saimanikanta/Desktop/ezapp/ez/frappe-bench/apps/frappe/frappe/query_builder/utils.py", line 84, in execute_query
    result = frappe.db.sql(query, params, *args, **kwargs)  # nosemgrep
  File "/Users/saimanikanta/Desktop/ezapp/ez/frappe-bench/apps/frappe/frappe/database/database.py", line 215, in sql
    self.connect()
    ~~~~~~~~~~~~^^
  File "/Users/saimanikanta/Desktop/ezapp/ez/frappe-bench/apps/frappe/frappe/database/database.py", line 120, in connect
    self._conn: MariadbConnection | PostgresConnection = self.get_connection()
                                                         ~~~~~~~~~~~~~~~~~~~^^
  File "/Users/saimanikanta/Desktop/ezapp/ez/frappe-bench/apps/frappe/frappe/database/mariadb/database.py", line 107, in get_connection
    conn = self._get_connection()
  File "/Users/saimanikanta/Desktop/ezapp/ez/frappe-bench/apps/frappe/frappe/database/mariadb/database.py", line 113, in _get_connection
    return self.create_connection()
           ~~~~~~~~~~~~~~~~~~~~~~^^
  File "/Users/saimanikanta/Desktop/ezapp/ez/frappe-bench/apps/frappe/frappe/database/mariadb/database.py", line 116, in create_connection
    return pymysql.connect(**self.get_connection_settings())
           ~~~~~~~~~~~~~~~^^^^^^^^^^^^^^^^^^^^^^^^^^^^^^^^^^
  File "/Users/saimanikanta/Desktop/ezapp/ez/frappe-bench/env/lib/python3.13/site-packages/pymysql/connections.py", line 361, in __init__
    self.connect()
    ~~~~~~~~~~~~^^
  File "/Users/saimanikanta/Desktop/ezapp/ez/frappe-bench/env/lib/python3.13/site-packages/pymysql/connections.py", line 669, in connect
    self._request_authentication()
    ~~~~~~~~~~~~~~~~~~~~~~~~~~~~^^
  File "/Users/saimanikanta/Desktop/ezapp/ez/frappe-bench/env/lib/python3.13/site-packages/pymysql/connections.py", line 957, in _request_authentication
    auth_packet = self._read_packet()
  File "/Users/saimanikanta/Desktop/ezapp/ez/frappe-bench/env/lib/python3.13/site-packages/pymysql/connections.py", line 775, in _read_packet
    packet.raise_for_error()
    ~~~~~~~~~~~~~~~~~~~~~~^^
  File "/Users/saimanikanta/Desktop/ezapp/ez/frappe-bench/env/lib/python3.13/site-packages/pymysql/protocol.py", line 219, in raise_for_error
    err.raise_mysql_exception(self._data)
    ~~~~~~~~~~~~~~~~~~~~~~~~~^^^^^^^^^^^^
  File "/Users/saimanikanta/Desktop/ezapp/ez/frappe-bench/env/lib/python3.13/site-packages/pymysql/err.py", line 150, in raise_mysql_exception
    raise errorclass(errno, errval)
pymysql.err.OperationalError: (1044, "Access denied for user '_7c5f4f77b0d74777'@'localhost' to database 'f77b0d74777_7c5f4'")
2025-02-10 14:38:00,109 ERROR scheduler Exception in Enqueue Events for Site money.test
Traceback (most recent call last):
  File "/Users/saimanikanta/Desktop/ezapp/ez/frappe-bench/apps/frappe/frappe/utils/scheduler.py", line 105, in enqueue_events_for_site
    if is_scheduler_inactive():
       ~~~~~~~~~~~~~~~~~~~~~^^
  File "/Users/saimanikanta/Desktop/ezapp/ez/frappe-bench/apps/frappe/frappe/utils/scheduler.py", line 149, in is_scheduler_inactive
    if is_scheduler_disabled(verbose=verbose):
       ~~~~~~~~~~~~~~~~~~~~~^^^^^^^^^^^^^^^^^
  File "/Users/saimanikanta/Desktop/ezapp/ez/frappe-bench/apps/frappe/frappe/utils/scheduler.py", line 162, in is_scheduler_disabled
    frappe.db.get_single_value("System Settings", "enable_scheduler")
    ~~~~~~~~~~~~~~~~~~~~~~~~~~^^^^^^^^^^^^^^^^^^^^^^^^^^^^^^^^^^^^^^^
  File "/Users/saimanikanta/Desktop/ezapp/ez/frappe-bench/apps/frappe/frappe/database/database.py", line 869, in get_single_value
    ).run()
      ~~~^^
  File "/Users/saimanikanta/Desktop/ezapp/ez/frappe-bench/apps/frappe/frappe/query_builder/utils.py", line 84, in execute_query
    result = frappe.db.sql(query, params, *args, **kwargs)  # nosemgrep
  File "/Users/saimanikanta/Desktop/ezapp/ez/frappe-bench/apps/frappe/frappe/database/database.py", line 215, in sql
    self.connect()
    ~~~~~~~~~~~~^^
  File "/Users/saimanikanta/Desktop/ezapp/ez/frappe-bench/apps/frappe/frappe/database/database.py", line 120, in connect
    self._conn: MariadbConnection | PostgresConnection = self.get_connection()
                                                         ~~~~~~~~~~~~~~~~~~~^^
  File "/Users/saimanikanta/Desktop/ezapp/ez/frappe-bench/apps/frappe/frappe/database/mariadb/database.py", line 107, in get_connection
    conn = self._get_connection()
  File "/Users/saimanikanta/Desktop/ezapp/ez/frappe-bench/apps/frappe/frappe/database/mariadb/database.py", line 113, in _get_connection
    return self.create_connection()
           ~~~~~~~~~~~~~~~~~~~~~~^^
  File "/Users/saimanikanta/Desktop/ezapp/ez/frappe-bench/apps/frappe/frappe/database/mariadb/database.py", line 116, in create_connection
    return pymysql.connect(**self.get_connection_settings())
           ~~~~~~~~~~~~~~~^^^^^^^^^^^^^^^^^^^^^^^^^^^^^^^^^^
  File "/Users/saimanikanta/Desktop/ezapp/ez/frappe-bench/env/lib/python3.13/site-packages/pymysql/connections.py", line 361, in __init__
    self.connect()
    ~~~~~~~~~~~~^^
  File "/Users/saimanikanta/Desktop/ezapp/ez/frappe-bench/env/lib/python3.13/site-packages/pymysql/connections.py", line 669, in connect
    self._request_authentication()
    ~~~~~~~~~~~~~~~~~~~~~~~~~~~~^^
  File "/Users/saimanikanta/Desktop/ezapp/ez/frappe-bench/env/lib/python3.13/site-packages/pymysql/connections.py", line 957, in _request_authentication
    auth_packet = self._read_packet()
  File "/Users/saimanikanta/Desktop/ezapp/ez/frappe-bench/env/lib/python3.13/site-packages/pymysql/connections.py", line 775, in _read_packet
    packet.raise_for_error()
    ~~~~~~~~~~~~~~~~~~~~~~^^
  File "/Users/saimanikanta/Desktop/ezapp/ez/frappe-bench/env/lib/python3.13/site-packages/pymysql/protocol.py", line 219, in raise_for_error
    err.raise_mysql_exception(self._data)
    ~~~~~~~~~~~~~~~~~~~~~~~~~^^^^^^^^^^^^
  File "/Users/saimanikanta/Desktop/ezapp/ez/frappe-bench/env/lib/python3.13/site-packages/pymysql/err.py", line 150, in raise_mysql_exception
    raise errorclass(errno, errval)
pymysql.err.OperationalError: (1044, "Access denied for user '_7c5f4f77b0d74777'@'localhost' to database 'f77b0d74777_7c5f4'")
2025-02-10 14:42:00,122 ERROR scheduler Exception in Enqueue Events for Site money.test
Traceback (most recent call last):
  File "/Users/saimanikanta/Desktop/ezapp/ez/frappe-bench/apps/frappe/frappe/utils/scheduler.py", line 105, in enqueue_events_for_site
    if is_scheduler_inactive():
       ~~~~~~~~~~~~~~~~~~~~~^^
  File "/Users/saimanikanta/Desktop/ezapp/ez/frappe-bench/apps/frappe/frappe/utils/scheduler.py", line 149, in is_scheduler_inactive
    if is_scheduler_disabled(verbose=verbose):
       ~~~~~~~~~~~~~~~~~~~~~^^^^^^^^^^^^^^^^^
  File "/Users/saimanikanta/Desktop/ezapp/ez/frappe-bench/apps/frappe/frappe/utils/scheduler.py", line 162, in is_scheduler_disabled
    frappe.db.get_single_value("System Settings", "enable_scheduler")
    ~~~~~~~~~~~~~~~~~~~~~~~~~~^^^^^^^^^^^^^^^^^^^^^^^^^^^^^^^^^^^^^^^
  File "/Users/saimanikanta/Desktop/ezapp/ez/frappe-bench/apps/frappe/frappe/database/database.py", line 869, in get_single_value
    ).run()
      ~~~^^
  File "/Users/saimanikanta/Desktop/ezapp/ez/frappe-bench/apps/frappe/frappe/query_builder/utils.py", line 84, in execute_query
    result = frappe.db.sql(query, params, *args, **kwargs)  # nosemgrep
  File "/Users/saimanikanta/Desktop/ezapp/ez/frappe-bench/apps/frappe/frappe/database/database.py", line 215, in sql
    self.connect()
    ~~~~~~~~~~~~^^
  File "/Users/saimanikanta/Desktop/ezapp/ez/frappe-bench/apps/frappe/frappe/database/database.py", line 120, in connect
    self._conn: MariadbConnection | PostgresConnection = self.get_connection()
                                                         ~~~~~~~~~~~~~~~~~~~^^
  File "/Users/saimanikanta/Desktop/ezapp/ez/frappe-bench/apps/frappe/frappe/database/mariadb/database.py", line 107, in get_connection
    conn = self._get_connection()
  File "/Users/saimanikanta/Desktop/ezapp/ez/frappe-bench/apps/frappe/frappe/database/mariadb/database.py", line 113, in _get_connection
    return self.create_connection()
           ~~~~~~~~~~~~~~~~~~~~~~^^
  File "/Users/saimanikanta/Desktop/ezapp/ez/frappe-bench/apps/frappe/frappe/database/mariadb/database.py", line 116, in create_connection
    return pymysql.connect(**self.get_connection_settings())
           ~~~~~~~~~~~~~~~^^^^^^^^^^^^^^^^^^^^^^^^^^^^^^^^^^
  File "/Users/saimanikanta/Desktop/ezapp/ez/frappe-bench/env/lib/python3.13/site-packages/pymysql/connections.py", line 361, in __init__
    self.connect()
    ~~~~~~~~~~~~^^
  File "/Users/saimanikanta/Desktop/ezapp/ez/frappe-bench/env/lib/python3.13/site-packages/pymysql/connections.py", line 669, in connect
    self._request_authentication()
    ~~~~~~~~~~~~~~~~~~~~~~~~~~~~^^
  File "/Users/saimanikanta/Desktop/ezapp/ez/frappe-bench/env/lib/python3.13/site-packages/pymysql/connections.py", line 957, in _request_authentication
    auth_packet = self._read_packet()
  File "/Users/saimanikanta/Desktop/ezapp/ez/frappe-bench/env/lib/python3.13/site-packages/pymysql/connections.py", line 775, in _read_packet
    packet.raise_for_error()
    ~~~~~~~~~~~~~~~~~~~~~~^^
  File "/Users/saimanikanta/Desktop/ezapp/ez/frappe-bench/env/lib/python3.13/site-packages/pymysql/protocol.py", line 219, in raise_for_error
    err.raise_mysql_exception(self._data)
    ~~~~~~~~~~~~~~~~~~~~~~~~~^^^^^^^^^^^^
  File "/Users/saimanikanta/Desktop/ezapp/ez/frappe-bench/env/lib/python3.13/site-packages/pymysql/err.py", line 150, in raise_mysql_exception
    raise errorclass(errno, errval)
pymysql.err.OperationalError: (1044, "Access denied for user '_7c5f4f77b0d74777'@'localhost' to database 'f77b0d74777_7c5f4'")
2025-02-10 14:46:00,192 ERROR scheduler Exception in Enqueue Events for Site money.test
Traceback (most recent call last):
  File "/Users/saimanikanta/Desktop/ezapp/ez/frappe-bench/apps/frappe/frappe/utils/scheduler.py", line 105, in enqueue_events_for_site
    if is_scheduler_inactive():
       ~~~~~~~~~~~~~~~~~~~~~^^
  File "/Users/saimanikanta/Desktop/ezapp/ez/frappe-bench/apps/frappe/frappe/utils/scheduler.py", line 149, in is_scheduler_inactive
    if is_scheduler_disabled(verbose=verbose):
       ~~~~~~~~~~~~~~~~~~~~~^^^^^^^^^^^^^^^^^
  File "/Users/saimanikanta/Desktop/ezapp/ez/frappe-bench/apps/frappe/frappe/utils/scheduler.py", line 162, in is_scheduler_disabled
    frappe.db.get_single_value("System Settings", "enable_scheduler")
    ~~~~~~~~~~~~~~~~~~~~~~~~~~^^^^^^^^^^^^^^^^^^^^^^^^^^^^^^^^^^^^^^^
  File "/Users/saimanikanta/Desktop/ezapp/ez/frappe-bench/apps/frappe/frappe/database/database.py", line 869, in get_single_value
    ).run()
      ~~~^^
  File "/Users/saimanikanta/Desktop/ezapp/ez/frappe-bench/apps/frappe/frappe/query_builder/utils.py", line 84, in execute_query
    result = frappe.db.sql(query, params, *args, **kwargs)  # nosemgrep
  File "/Users/saimanikanta/Desktop/ezapp/ez/frappe-bench/apps/frappe/frappe/database/database.py", line 215, in sql
    self.connect()
    ~~~~~~~~~~~~^^
  File "/Users/saimanikanta/Desktop/ezapp/ez/frappe-bench/apps/frappe/frappe/database/database.py", line 120, in connect
    self._conn: MariadbConnection | PostgresConnection = self.get_connection()
                                                         ~~~~~~~~~~~~~~~~~~~^^
  File "/Users/saimanikanta/Desktop/ezapp/ez/frappe-bench/apps/frappe/frappe/database/mariadb/database.py", line 107, in get_connection
    conn = self._get_connection()
  File "/Users/saimanikanta/Desktop/ezapp/ez/frappe-bench/apps/frappe/frappe/database/mariadb/database.py", line 113, in _get_connection
    return self.create_connection()
           ~~~~~~~~~~~~~~~~~~~~~~^^
  File "/Users/saimanikanta/Desktop/ezapp/ez/frappe-bench/apps/frappe/frappe/database/mariadb/database.py", line 116, in create_connection
    return pymysql.connect(**self.get_connection_settings())
           ~~~~~~~~~~~~~~~^^^^^^^^^^^^^^^^^^^^^^^^^^^^^^^^^^
  File "/Users/saimanikanta/Desktop/ezapp/ez/frappe-bench/env/lib/python3.13/site-packages/pymysql/connections.py", line 361, in __init__
    self.connect()
    ~~~~~~~~~~~~^^
  File "/Users/saimanikanta/Desktop/ezapp/ez/frappe-bench/env/lib/python3.13/site-packages/pymysql/connections.py", line 669, in connect
    self._request_authentication()
    ~~~~~~~~~~~~~~~~~~~~~~~~~~~~^^
  File "/Users/saimanikanta/Desktop/ezapp/ez/frappe-bench/env/lib/python3.13/site-packages/pymysql/connections.py", line 957, in _request_authentication
    auth_packet = self._read_packet()
  File "/Users/saimanikanta/Desktop/ezapp/ez/frappe-bench/env/lib/python3.13/site-packages/pymysql/connections.py", line 775, in _read_packet
    packet.raise_for_error()
    ~~~~~~~~~~~~~~~~~~~~~~^^
  File "/Users/saimanikanta/Desktop/ezapp/ez/frappe-bench/env/lib/python3.13/site-packages/pymysql/protocol.py", line 219, in raise_for_error
    err.raise_mysql_exception(self._data)
    ~~~~~~~~~~~~~~~~~~~~~~~~~^^^^^^^^^^^^
  File "/Users/saimanikanta/Desktop/ezapp/ez/frappe-bench/env/lib/python3.13/site-packages/pymysql/err.py", line 150, in raise_mysql_exception
    raise errorclass(errno, errval)
pymysql.err.OperationalError: (1044, "Access denied for user '_7c5f4f77b0d74777'@'localhost' to database 'f77b0d74777_7c5f4'")
2025-02-10 14:50:00,261 ERROR scheduler Exception in Enqueue Events for Site money.test
Traceback (most recent call last):
  File "/Users/saimanikanta/Desktop/ezapp/ez/frappe-bench/apps/frappe/frappe/utils/scheduler.py", line 105, in enqueue_events_for_site
    if is_scheduler_inactive():
       ~~~~~~~~~~~~~~~~~~~~~^^
  File "/Users/saimanikanta/Desktop/ezapp/ez/frappe-bench/apps/frappe/frappe/utils/scheduler.py", line 149, in is_scheduler_inactive
    if is_scheduler_disabled(verbose=verbose):
       ~~~~~~~~~~~~~~~~~~~~~^^^^^^^^^^^^^^^^^
  File "/Users/saimanikanta/Desktop/ezapp/ez/frappe-bench/apps/frappe/frappe/utils/scheduler.py", line 162, in is_scheduler_disabled
    frappe.db.get_single_value("System Settings", "enable_scheduler")
    ~~~~~~~~~~~~~~~~~~~~~~~~~~^^^^^^^^^^^^^^^^^^^^^^^^^^^^^^^^^^^^^^^
  File "/Users/saimanikanta/Desktop/ezapp/ez/frappe-bench/apps/frappe/frappe/database/database.py", line 869, in get_single_value
    ).run()
      ~~~^^
  File "/Users/saimanikanta/Desktop/ezapp/ez/frappe-bench/apps/frappe/frappe/query_builder/utils.py", line 84, in execute_query
    result = frappe.db.sql(query, params, *args, **kwargs)  # nosemgrep
  File "/Users/saimanikanta/Desktop/ezapp/ez/frappe-bench/apps/frappe/frappe/database/database.py", line 215, in sql
    self.connect()
    ~~~~~~~~~~~~^^
  File "/Users/saimanikanta/Desktop/ezapp/ez/frappe-bench/apps/frappe/frappe/database/database.py", line 120, in connect
    self._conn: MariadbConnection | PostgresConnection = self.get_connection()
                                                         ~~~~~~~~~~~~~~~~~~~^^
  File "/Users/saimanikanta/Desktop/ezapp/ez/frappe-bench/apps/frappe/frappe/database/mariadb/database.py", line 107, in get_connection
    conn = self._get_connection()
  File "/Users/saimanikanta/Desktop/ezapp/ez/frappe-bench/apps/frappe/frappe/database/mariadb/database.py", line 113, in _get_connection
    return self.create_connection()
           ~~~~~~~~~~~~~~~~~~~~~~^^
  File "/Users/saimanikanta/Desktop/ezapp/ez/frappe-bench/apps/frappe/frappe/database/mariadb/database.py", line 116, in create_connection
    return pymysql.connect(**self.get_connection_settings())
           ~~~~~~~~~~~~~~~^^^^^^^^^^^^^^^^^^^^^^^^^^^^^^^^^^
  File "/Users/saimanikanta/Desktop/ezapp/ez/frappe-bench/env/lib/python3.13/site-packages/pymysql/connections.py", line 361, in __init__
    self.connect()
    ~~~~~~~~~~~~^^
  File "/Users/saimanikanta/Desktop/ezapp/ez/frappe-bench/env/lib/python3.13/site-packages/pymysql/connections.py", line 669, in connect
    self._request_authentication()
    ~~~~~~~~~~~~~~~~~~~~~~~~~~~~^^
  File "/Users/saimanikanta/Desktop/ezapp/ez/frappe-bench/env/lib/python3.13/site-packages/pymysql/connections.py", line 957, in _request_authentication
    auth_packet = self._read_packet()
  File "/Users/saimanikanta/Desktop/ezapp/ez/frappe-bench/env/lib/python3.13/site-packages/pymysql/connections.py", line 775, in _read_packet
    packet.raise_for_error()
    ~~~~~~~~~~~~~~~~~~~~~~^^
  File "/Users/saimanikanta/Desktop/ezapp/ez/frappe-bench/env/lib/python3.13/site-packages/pymysql/protocol.py", line 219, in raise_for_error
    err.raise_mysql_exception(self._data)
    ~~~~~~~~~~~~~~~~~~~~~~~~~^^^^^^^^^^^^
  File "/Users/saimanikanta/Desktop/ezapp/ez/frappe-bench/env/lib/python3.13/site-packages/pymysql/err.py", line 150, in raise_mysql_exception
    raise errorclass(errno, errval)
pymysql.err.OperationalError: (1044, "Access denied for user '_7c5f4f77b0d74777'@'localhost' to database 'f77b0d74777_7c5f4'")
2025-02-10 14:54:00,593 ERROR scheduler Exception in Enqueue Events for Site money.test
Traceback (most recent call last):
  File "/Users/saimanikanta/Desktop/ezapp/ez/frappe-bench/apps/frappe/frappe/utils/scheduler.py", line 105, in enqueue_events_for_site
    if is_scheduler_inactive():
       ~~~~~~~~~~~~~~~~~~~~~^^
  File "/Users/saimanikanta/Desktop/ezapp/ez/frappe-bench/apps/frappe/frappe/utils/scheduler.py", line 149, in is_scheduler_inactive
    if is_scheduler_disabled(verbose=verbose):
       ~~~~~~~~~~~~~~~~~~~~~^^^^^^^^^^^^^^^^^
  File "/Users/saimanikanta/Desktop/ezapp/ez/frappe-bench/apps/frappe/frappe/utils/scheduler.py", line 162, in is_scheduler_disabled
    frappe.db.get_single_value("System Settings", "enable_scheduler")
    ~~~~~~~~~~~~~~~~~~~~~~~~~~^^^^^^^^^^^^^^^^^^^^^^^^^^^^^^^^^^^^^^^
  File "/Users/saimanikanta/Desktop/ezapp/ez/frappe-bench/apps/frappe/frappe/database/database.py", line 869, in get_single_value
    ).run()
      ~~~^^
  File "/Users/saimanikanta/Desktop/ezapp/ez/frappe-bench/apps/frappe/frappe/query_builder/utils.py", line 84, in execute_query
    result = frappe.db.sql(query, params, *args, **kwargs)  # nosemgrep
  File "/Users/saimanikanta/Desktop/ezapp/ez/frappe-bench/apps/frappe/frappe/database/database.py", line 215, in sql
    self.connect()
    ~~~~~~~~~~~~^^
  File "/Users/saimanikanta/Desktop/ezapp/ez/frappe-bench/apps/frappe/frappe/database/database.py", line 120, in connect
    self._conn: MariadbConnection | PostgresConnection = self.get_connection()
                                                         ~~~~~~~~~~~~~~~~~~~^^
  File "/Users/saimanikanta/Desktop/ezapp/ez/frappe-bench/apps/frappe/frappe/database/mariadb/database.py", line 107, in get_connection
    conn = self._get_connection()
  File "/Users/saimanikanta/Desktop/ezapp/ez/frappe-bench/apps/frappe/frappe/database/mariadb/database.py", line 113, in _get_connection
    return self.create_connection()
           ~~~~~~~~~~~~~~~~~~~~~~^^
  File "/Users/saimanikanta/Desktop/ezapp/ez/frappe-bench/apps/frappe/frappe/database/mariadb/database.py", line 116, in create_connection
    return pymysql.connect(**self.get_connection_settings())
           ~~~~~~~~~~~~~~~^^^^^^^^^^^^^^^^^^^^^^^^^^^^^^^^^^
  File "/Users/saimanikanta/Desktop/ezapp/ez/frappe-bench/env/lib/python3.13/site-packages/pymysql/connections.py", line 361, in __init__
    self.connect()
    ~~~~~~~~~~~~^^
  File "/Users/saimanikanta/Desktop/ezapp/ez/frappe-bench/env/lib/python3.13/site-packages/pymysql/connections.py", line 669, in connect
    self._request_authentication()
    ~~~~~~~~~~~~~~~~~~~~~~~~~~~~^^
  File "/Users/saimanikanta/Desktop/ezapp/ez/frappe-bench/env/lib/python3.13/site-packages/pymysql/connections.py", line 957, in _request_authentication
    auth_packet = self._read_packet()
  File "/Users/saimanikanta/Desktop/ezapp/ez/frappe-bench/env/lib/python3.13/site-packages/pymysql/connections.py", line 775, in _read_packet
    packet.raise_for_error()
    ~~~~~~~~~~~~~~~~~~~~~~^^
  File "/Users/saimanikanta/Desktop/ezapp/ez/frappe-bench/env/lib/python3.13/site-packages/pymysql/protocol.py", line 219, in raise_for_error
    err.raise_mysql_exception(self._data)
    ~~~~~~~~~~~~~~~~~~~~~~~~~^^^^^^^^^^^^
  File "/Users/saimanikanta/Desktop/ezapp/ez/frappe-bench/env/lib/python3.13/site-packages/pymysql/err.py", line 150, in raise_mysql_exception
    raise errorclass(errno, errval)
pymysql.err.OperationalError: (1044, "Access denied for user '_7c5f4f77b0d74777'@'localhost' to database 'f77b0d74777_7c5f4'")
2025-02-10 14:58:00,599 ERROR scheduler Exception in Enqueue Events for Site money.test
Traceback (most recent call last):
  File "/Users/saimanikanta/Desktop/ezapp/ez/frappe-bench/apps/frappe/frappe/utils/scheduler.py", line 105, in enqueue_events_for_site
    if is_scheduler_inactive():
       ~~~~~~~~~~~~~~~~~~~~~^^
  File "/Users/saimanikanta/Desktop/ezapp/ez/frappe-bench/apps/frappe/frappe/utils/scheduler.py", line 149, in is_scheduler_inactive
    if is_scheduler_disabled(verbose=verbose):
       ~~~~~~~~~~~~~~~~~~~~~^^^^^^^^^^^^^^^^^
  File "/Users/saimanikanta/Desktop/ezapp/ez/frappe-bench/apps/frappe/frappe/utils/scheduler.py", line 162, in is_scheduler_disabled
    frappe.db.get_single_value("System Settings", "enable_scheduler")
    ~~~~~~~~~~~~~~~~~~~~~~~~~~^^^^^^^^^^^^^^^^^^^^^^^^^^^^^^^^^^^^^^^
  File "/Users/saimanikanta/Desktop/ezapp/ez/frappe-bench/apps/frappe/frappe/database/database.py", line 869, in get_single_value
    ).run()
      ~~~^^
  File "/Users/saimanikanta/Desktop/ezapp/ez/frappe-bench/apps/frappe/frappe/query_builder/utils.py", line 84, in execute_query
    result = frappe.db.sql(query, params, *args, **kwargs)  # nosemgrep
  File "/Users/saimanikanta/Desktop/ezapp/ez/frappe-bench/apps/frappe/frappe/database/database.py", line 215, in sql
    self.connect()
    ~~~~~~~~~~~~^^
  File "/Users/saimanikanta/Desktop/ezapp/ez/frappe-bench/apps/frappe/frappe/database/database.py", line 120, in connect
    self._conn: MariadbConnection | PostgresConnection = self.get_connection()
                                                         ~~~~~~~~~~~~~~~~~~~^^
  File "/Users/saimanikanta/Desktop/ezapp/ez/frappe-bench/apps/frappe/frappe/database/mariadb/database.py", line 107, in get_connection
    conn = self._get_connection()
  File "/Users/saimanikanta/Desktop/ezapp/ez/frappe-bench/apps/frappe/frappe/database/mariadb/database.py", line 113, in _get_connection
    return self.create_connection()
           ~~~~~~~~~~~~~~~~~~~~~~^^
  File "/Users/saimanikanta/Desktop/ezapp/ez/frappe-bench/apps/frappe/frappe/database/mariadb/database.py", line 116, in create_connection
    return pymysql.connect(**self.get_connection_settings())
           ~~~~~~~~~~~~~~~^^^^^^^^^^^^^^^^^^^^^^^^^^^^^^^^^^
  File "/Users/saimanikanta/Desktop/ezapp/ez/frappe-bench/env/lib/python3.13/site-packages/pymysql/connections.py", line 361, in __init__
    self.connect()
    ~~~~~~~~~~~~^^
  File "/Users/saimanikanta/Desktop/ezapp/ez/frappe-bench/env/lib/python3.13/site-packages/pymysql/connections.py", line 669, in connect
    self._request_authentication()
    ~~~~~~~~~~~~~~~~~~~~~~~~~~~~^^
  File "/Users/saimanikanta/Desktop/ezapp/ez/frappe-bench/env/lib/python3.13/site-packages/pymysql/connections.py", line 957, in _request_authentication
    auth_packet = self._read_packet()
  File "/Users/saimanikanta/Desktop/ezapp/ez/frappe-bench/env/lib/python3.13/site-packages/pymysql/connections.py", line 775, in _read_packet
    packet.raise_for_error()
    ~~~~~~~~~~~~~~~~~~~~~~^^
  File "/Users/saimanikanta/Desktop/ezapp/ez/frappe-bench/env/lib/python3.13/site-packages/pymysql/protocol.py", line 219, in raise_for_error
    err.raise_mysql_exception(self._data)
    ~~~~~~~~~~~~~~~~~~~~~~~~~^^^^^^^^^^^^
  File "/Users/saimanikanta/Desktop/ezapp/ez/frappe-bench/env/lib/python3.13/site-packages/pymysql/err.py", line 150, in raise_mysql_exception
    raise errorclass(errno, errval)
pymysql.err.OperationalError: (1044, "Access denied for user '_7c5f4f77b0d74777'@'localhost' to database 'f77b0d74777_7c5f4'")
2025-02-10 15:02:00,628 ERROR scheduler Exception in Enqueue Events for Site money.test
Traceback (most recent call last):
  File "/Users/saimanikanta/Desktop/ezapp/ez/frappe-bench/apps/frappe/frappe/utils/scheduler.py", line 105, in enqueue_events_for_site
    if is_scheduler_inactive():
       ~~~~~~~~~~~~~~~~~~~~~^^
  File "/Users/saimanikanta/Desktop/ezapp/ez/frappe-bench/apps/frappe/frappe/utils/scheduler.py", line 149, in is_scheduler_inactive
    if is_scheduler_disabled(verbose=verbose):
       ~~~~~~~~~~~~~~~~~~~~~^^^^^^^^^^^^^^^^^
  File "/Users/saimanikanta/Desktop/ezapp/ez/frappe-bench/apps/frappe/frappe/utils/scheduler.py", line 162, in is_scheduler_disabled
    frappe.db.get_single_value("System Settings", "enable_scheduler")
    ~~~~~~~~~~~~~~~~~~~~~~~~~~^^^^^^^^^^^^^^^^^^^^^^^^^^^^^^^^^^^^^^^
  File "/Users/saimanikanta/Desktop/ezapp/ez/frappe-bench/apps/frappe/frappe/database/database.py", line 869, in get_single_value
    ).run()
      ~~~^^
  File "/Users/saimanikanta/Desktop/ezapp/ez/frappe-bench/apps/frappe/frappe/query_builder/utils.py", line 84, in execute_query
    result = frappe.db.sql(query, params, *args, **kwargs)  # nosemgrep
  File "/Users/saimanikanta/Desktop/ezapp/ez/frappe-bench/apps/frappe/frappe/database/database.py", line 215, in sql
    self.connect()
    ~~~~~~~~~~~~^^
  File "/Users/saimanikanta/Desktop/ezapp/ez/frappe-bench/apps/frappe/frappe/database/database.py", line 120, in connect
    self._conn: MariadbConnection | PostgresConnection = self.get_connection()
                                                         ~~~~~~~~~~~~~~~~~~~^^
  File "/Users/saimanikanta/Desktop/ezapp/ez/frappe-bench/apps/frappe/frappe/database/mariadb/database.py", line 107, in get_connection
    conn = self._get_connection()
  File "/Users/saimanikanta/Desktop/ezapp/ez/frappe-bench/apps/frappe/frappe/database/mariadb/database.py", line 113, in _get_connection
    return self.create_connection()
           ~~~~~~~~~~~~~~~~~~~~~~^^
  File "/Users/saimanikanta/Desktop/ezapp/ez/frappe-bench/apps/frappe/frappe/database/mariadb/database.py", line 116, in create_connection
    return pymysql.connect(**self.get_connection_settings())
           ~~~~~~~~~~~~~~~^^^^^^^^^^^^^^^^^^^^^^^^^^^^^^^^^^
  File "/Users/saimanikanta/Desktop/ezapp/ez/frappe-bench/env/lib/python3.13/site-packages/pymysql/connections.py", line 361, in __init__
    self.connect()
    ~~~~~~~~~~~~^^
  File "/Users/saimanikanta/Desktop/ezapp/ez/frappe-bench/env/lib/python3.13/site-packages/pymysql/connections.py", line 669, in connect
    self._request_authentication()
    ~~~~~~~~~~~~~~~~~~~~~~~~~~~~^^
  File "/Users/saimanikanta/Desktop/ezapp/ez/frappe-bench/env/lib/python3.13/site-packages/pymysql/connections.py", line 957, in _request_authentication
    auth_packet = self._read_packet()
  File "/Users/saimanikanta/Desktop/ezapp/ez/frappe-bench/env/lib/python3.13/site-packages/pymysql/connections.py", line 775, in _read_packet
    packet.raise_for_error()
    ~~~~~~~~~~~~~~~~~~~~~~^^
  File "/Users/saimanikanta/Desktop/ezapp/ez/frappe-bench/env/lib/python3.13/site-packages/pymysql/protocol.py", line 219, in raise_for_error
    err.raise_mysql_exception(self._data)
    ~~~~~~~~~~~~~~~~~~~~~~~~~^^^^^^^^^^^^
  File "/Users/saimanikanta/Desktop/ezapp/ez/frappe-bench/env/lib/python3.13/site-packages/pymysql/err.py", line 150, in raise_mysql_exception
    raise errorclass(errno, errval)
pymysql.err.OperationalError: (1044, "Access denied for user '_7c5f4f77b0d74777'@'localhost' to database 'f77b0d74777_7c5f4'")
2025-02-10 15:06:00,898 ERROR scheduler Exception in Enqueue Events for Site money.test
Traceback (most recent call last):
  File "/Users/saimanikanta/Desktop/ezapp/ez/frappe-bench/apps/frappe/frappe/utils/scheduler.py", line 105, in enqueue_events_for_site
    if is_scheduler_inactive():
       ~~~~~~~~~~~~~~~~~~~~~^^
  File "/Users/saimanikanta/Desktop/ezapp/ez/frappe-bench/apps/frappe/frappe/utils/scheduler.py", line 149, in is_scheduler_inactive
    if is_scheduler_disabled(verbose=verbose):
       ~~~~~~~~~~~~~~~~~~~~~^^^^^^^^^^^^^^^^^
  File "/Users/saimanikanta/Desktop/ezapp/ez/frappe-bench/apps/frappe/frappe/utils/scheduler.py", line 162, in is_scheduler_disabled
    frappe.db.get_single_value("System Settings", "enable_scheduler")
    ~~~~~~~~~~~~~~~~~~~~~~~~~~^^^^^^^^^^^^^^^^^^^^^^^^^^^^^^^^^^^^^^^
  File "/Users/saimanikanta/Desktop/ezapp/ez/frappe-bench/apps/frappe/frappe/database/database.py", line 869, in get_single_value
    ).run()
      ~~~^^
  File "/Users/saimanikanta/Desktop/ezapp/ez/frappe-bench/apps/frappe/frappe/query_builder/utils.py", line 84, in execute_query
    result = frappe.db.sql(query, params, *args, **kwargs)  # nosemgrep
  File "/Users/saimanikanta/Desktop/ezapp/ez/frappe-bench/apps/frappe/frappe/database/database.py", line 215, in sql
    self.connect()
    ~~~~~~~~~~~~^^
  File "/Users/saimanikanta/Desktop/ezapp/ez/frappe-bench/apps/frappe/frappe/database/database.py", line 120, in connect
    self._conn: MariadbConnection | PostgresConnection = self.get_connection()
                                                         ~~~~~~~~~~~~~~~~~~~^^
  File "/Users/saimanikanta/Desktop/ezapp/ez/frappe-bench/apps/frappe/frappe/database/mariadb/database.py", line 107, in get_connection
    conn = self._get_connection()
  File "/Users/saimanikanta/Desktop/ezapp/ez/frappe-bench/apps/frappe/frappe/database/mariadb/database.py", line 113, in _get_connection
    return self.create_connection()
           ~~~~~~~~~~~~~~~~~~~~~~^^
  File "/Users/saimanikanta/Desktop/ezapp/ez/frappe-bench/apps/frappe/frappe/database/mariadb/database.py", line 116, in create_connection
    return pymysql.connect(**self.get_connection_settings())
           ~~~~~~~~~~~~~~~^^^^^^^^^^^^^^^^^^^^^^^^^^^^^^^^^^
  File "/Users/saimanikanta/Desktop/ezapp/ez/frappe-bench/env/lib/python3.13/site-packages/pymysql/connections.py", line 361, in __init__
    self.connect()
    ~~~~~~~~~~~~^^
  File "/Users/saimanikanta/Desktop/ezapp/ez/frappe-bench/env/lib/python3.13/site-packages/pymysql/connections.py", line 669, in connect
    self._request_authentication()
    ~~~~~~~~~~~~~~~~~~~~~~~~~~~~^^
  File "/Users/saimanikanta/Desktop/ezapp/ez/frappe-bench/env/lib/python3.13/site-packages/pymysql/connections.py", line 957, in _request_authentication
    auth_packet = self._read_packet()
  File "/Users/saimanikanta/Desktop/ezapp/ez/frappe-bench/env/lib/python3.13/site-packages/pymysql/connections.py", line 775, in _read_packet
    packet.raise_for_error()
    ~~~~~~~~~~~~~~~~~~~~~~^^
  File "/Users/saimanikanta/Desktop/ezapp/ez/frappe-bench/env/lib/python3.13/site-packages/pymysql/protocol.py", line 219, in raise_for_error
    err.raise_mysql_exception(self._data)
    ~~~~~~~~~~~~~~~~~~~~~~~~~^^^^^^^^^^^^
  File "/Users/saimanikanta/Desktop/ezapp/ez/frappe-bench/env/lib/python3.13/site-packages/pymysql/err.py", line 150, in raise_mysql_exception
    raise errorclass(errno, errval)
pymysql.err.OperationalError: (1044, "Access denied for user '_7c5f4f77b0d74777'@'localhost' to database 'f77b0d74777_7c5f4'")
2025-02-10 15:10:00,159 ERROR scheduler Exception in Enqueue Events for Site money.test
Traceback (most recent call last):
  File "/Users/saimanikanta/Desktop/ezapp/ez/frappe-bench/apps/frappe/frappe/utils/scheduler.py", line 105, in enqueue_events_for_site
    if is_scheduler_inactive():
       ~~~~~~~~~~~~~~~~~~~~~^^
  File "/Users/saimanikanta/Desktop/ezapp/ez/frappe-bench/apps/frappe/frappe/utils/scheduler.py", line 149, in is_scheduler_inactive
    if is_scheduler_disabled(verbose=verbose):
       ~~~~~~~~~~~~~~~~~~~~~^^^^^^^^^^^^^^^^^
  File "/Users/saimanikanta/Desktop/ezapp/ez/frappe-bench/apps/frappe/frappe/utils/scheduler.py", line 162, in is_scheduler_disabled
    frappe.db.get_single_value("System Settings", "enable_scheduler")
    ~~~~~~~~~~~~~~~~~~~~~~~~~~^^^^^^^^^^^^^^^^^^^^^^^^^^^^^^^^^^^^^^^
  File "/Users/saimanikanta/Desktop/ezapp/ez/frappe-bench/apps/frappe/frappe/database/database.py", line 869, in get_single_value
    ).run()
      ~~~^^
  File "/Users/saimanikanta/Desktop/ezapp/ez/frappe-bench/apps/frappe/frappe/query_builder/utils.py", line 84, in execute_query
    result = frappe.db.sql(query, params, *args, **kwargs)  # nosemgrep
  File "/Users/saimanikanta/Desktop/ezapp/ez/frappe-bench/apps/frappe/frappe/database/database.py", line 215, in sql
    self.connect()
    ~~~~~~~~~~~~^^
  File "/Users/saimanikanta/Desktop/ezapp/ez/frappe-bench/apps/frappe/frappe/database/database.py", line 120, in connect
    self._conn: MariadbConnection | PostgresConnection = self.get_connection()
                                                         ~~~~~~~~~~~~~~~~~~~^^
  File "/Users/saimanikanta/Desktop/ezapp/ez/frappe-bench/apps/frappe/frappe/database/mariadb/database.py", line 107, in get_connection
    conn = self._get_connection()
  File "/Users/saimanikanta/Desktop/ezapp/ez/frappe-bench/apps/frappe/frappe/database/mariadb/database.py", line 113, in _get_connection
    return self.create_connection()
           ~~~~~~~~~~~~~~~~~~~~~~^^
  File "/Users/saimanikanta/Desktop/ezapp/ez/frappe-bench/apps/frappe/frappe/database/mariadb/database.py", line 116, in create_connection
    return pymysql.connect(**self.get_connection_settings())
           ~~~~~~~~~~~~~~~^^^^^^^^^^^^^^^^^^^^^^^^^^^^^^^^^^
  File "/Users/saimanikanta/Desktop/ezapp/ez/frappe-bench/env/lib/python3.13/site-packages/pymysql/connections.py", line 361, in __init__
    self.connect()
    ~~~~~~~~~~~~^^
  File "/Users/saimanikanta/Desktop/ezapp/ez/frappe-bench/env/lib/python3.13/site-packages/pymysql/connections.py", line 669, in connect
    self._request_authentication()
    ~~~~~~~~~~~~~~~~~~~~~~~~~~~~^^
  File "/Users/saimanikanta/Desktop/ezapp/ez/frappe-bench/env/lib/python3.13/site-packages/pymysql/connections.py", line 957, in _request_authentication
    auth_packet = self._read_packet()
  File "/Users/saimanikanta/Desktop/ezapp/ez/frappe-bench/env/lib/python3.13/site-packages/pymysql/connections.py", line 775, in _read_packet
    packet.raise_for_error()
    ~~~~~~~~~~~~~~~~~~~~~~^^
  File "/Users/saimanikanta/Desktop/ezapp/ez/frappe-bench/env/lib/python3.13/site-packages/pymysql/protocol.py", line 219, in raise_for_error
    err.raise_mysql_exception(self._data)
    ~~~~~~~~~~~~~~~~~~~~~~~~~^^^^^^^^^^^^
  File "/Users/saimanikanta/Desktop/ezapp/ez/frappe-bench/env/lib/python3.13/site-packages/pymysql/err.py", line 150, in raise_mysql_exception
    raise errorclass(errno, errval)
pymysql.err.OperationalError: (1044, "Access denied for user '_7c5f4f77b0d74777'@'localhost' to database 'f77b0d74777_7c5f4'")
2025-02-10 15:14:00,552 ERROR scheduler Exception in Enqueue Events for Site money.test
Traceback (most recent call last):
  File "/Users/saimanikanta/Desktop/ezapp/ez/frappe-bench/apps/frappe/frappe/utils/scheduler.py", line 105, in enqueue_events_for_site
    if is_scheduler_inactive():
       ~~~~~~~~~~~~~~~~~~~~~^^
  File "/Users/saimanikanta/Desktop/ezapp/ez/frappe-bench/apps/frappe/frappe/utils/scheduler.py", line 149, in is_scheduler_inactive
    if is_scheduler_disabled(verbose=verbose):
       ~~~~~~~~~~~~~~~~~~~~~^^^^^^^^^^^^^^^^^
  File "/Users/saimanikanta/Desktop/ezapp/ez/frappe-bench/apps/frappe/frappe/utils/scheduler.py", line 162, in is_scheduler_disabled
    frappe.db.get_single_value("System Settings", "enable_scheduler")
    ~~~~~~~~~~~~~~~~~~~~~~~~~~^^^^^^^^^^^^^^^^^^^^^^^^^^^^^^^^^^^^^^^
  File "/Users/saimanikanta/Desktop/ezapp/ez/frappe-bench/apps/frappe/frappe/database/database.py", line 869, in get_single_value
    ).run()
      ~~~^^
  File "/Users/saimanikanta/Desktop/ezapp/ez/frappe-bench/apps/frappe/frappe/query_builder/utils.py", line 84, in execute_query
    result = frappe.db.sql(query, params, *args, **kwargs)  # nosemgrep
  File "/Users/saimanikanta/Desktop/ezapp/ez/frappe-bench/apps/frappe/frappe/database/database.py", line 215, in sql
    self.connect()
    ~~~~~~~~~~~~^^
  File "/Users/saimanikanta/Desktop/ezapp/ez/frappe-bench/apps/frappe/frappe/database/database.py", line 120, in connect
    self._conn: MariadbConnection | PostgresConnection = self.get_connection()
                                                         ~~~~~~~~~~~~~~~~~~~^^
  File "/Users/saimanikanta/Desktop/ezapp/ez/frappe-bench/apps/frappe/frappe/database/mariadb/database.py", line 107, in get_connection
    conn = self._get_connection()
  File "/Users/saimanikanta/Desktop/ezapp/ez/frappe-bench/apps/frappe/frappe/database/mariadb/database.py", line 113, in _get_connection
    return self.create_connection()
           ~~~~~~~~~~~~~~~~~~~~~~^^
  File "/Users/saimanikanta/Desktop/ezapp/ez/frappe-bench/apps/frappe/frappe/database/mariadb/database.py", line 116, in create_connection
    return pymysql.connect(**self.get_connection_settings())
           ~~~~~~~~~~~~~~~^^^^^^^^^^^^^^^^^^^^^^^^^^^^^^^^^^
  File "/Users/saimanikanta/Desktop/ezapp/ez/frappe-bench/env/lib/python3.13/site-packages/pymysql/connections.py", line 361, in __init__
    self.connect()
    ~~~~~~~~~~~~^^
  File "/Users/saimanikanta/Desktop/ezapp/ez/frappe-bench/env/lib/python3.13/site-packages/pymysql/connections.py", line 669, in connect
    self._request_authentication()
    ~~~~~~~~~~~~~~~~~~~~~~~~~~~~^^
  File "/Users/saimanikanta/Desktop/ezapp/ez/frappe-bench/env/lib/python3.13/site-packages/pymysql/connections.py", line 957, in _request_authentication
    auth_packet = self._read_packet()
  File "/Users/saimanikanta/Desktop/ezapp/ez/frappe-bench/env/lib/python3.13/site-packages/pymysql/connections.py", line 775, in _read_packet
    packet.raise_for_error()
    ~~~~~~~~~~~~~~~~~~~~~~^^
  File "/Users/saimanikanta/Desktop/ezapp/ez/frappe-bench/env/lib/python3.13/site-packages/pymysql/protocol.py", line 219, in raise_for_error
    err.raise_mysql_exception(self._data)
    ~~~~~~~~~~~~~~~~~~~~~~~~~^^^^^^^^^^^^
  File "/Users/saimanikanta/Desktop/ezapp/ez/frappe-bench/env/lib/python3.13/site-packages/pymysql/err.py", line 150, in raise_mysql_exception
    raise errorclass(errno, errval)
pymysql.err.OperationalError: (1044, "Access denied for user '_7c5f4f77b0d74777'@'localhost' to database 'f77b0d74777_7c5f4'")
2025-02-10 15:18:00,936 ERROR scheduler Exception in Enqueue Events for Site money.test
Traceback (most recent call last):
  File "/Users/saimanikanta/Desktop/ezapp/ez/frappe-bench/apps/frappe/frappe/utils/scheduler.py", line 105, in enqueue_events_for_site
    if is_scheduler_inactive():
       ~~~~~~~~~~~~~~~~~~~~~^^
  File "/Users/saimanikanta/Desktop/ezapp/ez/frappe-bench/apps/frappe/frappe/utils/scheduler.py", line 149, in is_scheduler_inactive
    if is_scheduler_disabled(verbose=verbose):
       ~~~~~~~~~~~~~~~~~~~~~^^^^^^^^^^^^^^^^^
  File "/Users/saimanikanta/Desktop/ezapp/ez/frappe-bench/apps/frappe/frappe/utils/scheduler.py", line 162, in is_scheduler_disabled
    frappe.db.get_single_value("System Settings", "enable_scheduler")
    ~~~~~~~~~~~~~~~~~~~~~~~~~~^^^^^^^^^^^^^^^^^^^^^^^^^^^^^^^^^^^^^^^
  File "/Users/saimanikanta/Desktop/ezapp/ez/frappe-bench/apps/frappe/frappe/database/database.py", line 869, in get_single_value
    ).run()
      ~~~^^
  File "/Users/saimanikanta/Desktop/ezapp/ez/frappe-bench/apps/frappe/frappe/query_builder/utils.py", line 84, in execute_query
    result = frappe.db.sql(query, params, *args, **kwargs)  # nosemgrep
  File "/Users/saimanikanta/Desktop/ezapp/ez/frappe-bench/apps/frappe/frappe/database/database.py", line 215, in sql
    self.connect()
    ~~~~~~~~~~~~^^
  File "/Users/saimanikanta/Desktop/ezapp/ez/frappe-bench/apps/frappe/frappe/database/database.py", line 120, in connect
    self._conn: MariadbConnection | PostgresConnection = self.get_connection()
                                                         ~~~~~~~~~~~~~~~~~~~^^
  File "/Users/saimanikanta/Desktop/ezapp/ez/frappe-bench/apps/frappe/frappe/database/mariadb/database.py", line 107, in get_connection
    conn = self._get_connection()
  File "/Users/saimanikanta/Desktop/ezapp/ez/frappe-bench/apps/frappe/frappe/database/mariadb/database.py", line 113, in _get_connection
    return self.create_connection()
           ~~~~~~~~~~~~~~~~~~~~~~^^
  File "/Users/saimanikanta/Desktop/ezapp/ez/frappe-bench/apps/frappe/frappe/database/mariadb/database.py", line 116, in create_connection
    return pymysql.connect(**self.get_connection_settings())
           ~~~~~~~~~~~~~~~^^^^^^^^^^^^^^^^^^^^^^^^^^^^^^^^^^
  File "/Users/saimanikanta/Desktop/ezapp/ez/frappe-bench/env/lib/python3.13/site-packages/pymysql/connections.py", line 361, in __init__
    self.connect()
    ~~~~~~~~~~~~^^
  File "/Users/saimanikanta/Desktop/ezapp/ez/frappe-bench/env/lib/python3.13/site-packages/pymysql/connections.py", line 669, in connect
    self._request_authentication()
    ~~~~~~~~~~~~~~~~~~~~~~~~~~~~^^
  File "/Users/saimanikanta/Desktop/ezapp/ez/frappe-bench/env/lib/python3.13/site-packages/pymysql/connections.py", line 957, in _request_authentication
    auth_packet = self._read_packet()
  File "/Users/saimanikanta/Desktop/ezapp/ez/frappe-bench/env/lib/python3.13/site-packages/pymysql/connections.py", line 775, in _read_packet
    packet.raise_for_error()
    ~~~~~~~~~~~~~~~~~~~~~~^^
  File "/Users/saimanikanta/Desktop/ezapp/ez/frappe-bench/env/lib/python3.13/site-packages/pymysql/protocol.py", line 219, in raise_for_error
    err.raise_mysql_exception(self._data)
    ~~~~~~~~~~~~~~~~~~~~~~~~~^^^^^^^^^^^^
  File "/Users/saimanikanta/Desktop/ezapp/ez/frappe-bench/env/lib/python3.13/site-packages/pymysql/err.py", line 150, in raise_mysql_exception
    raise errorclass(errno, errval)
pymysql.err.OperationalError: (1044, "Access denied for user '_7c5f4f77b0d74777'@'localhost' to database 'f77b0d74777_7c5f4'")
2025-02-10 15:22:01,043 ERROR scheduler Exception in Enqueue Events for Site money.test
Traceback (most recent call last):
  File "/Users/saimanikanta/Desktop/ezapp/ez/frappe-bench/apps/frappe/frappe/utils/scheduler.py", line 105, in enqueue_events_for_site
    if is_scheduler_inactive():
       ~~~~~~~~~~~~~~~~~~~~~^^
  File "/Users/saimanikanta/Desktop/ezapp/ez/frappe-bench/apps/frappe/frappe/utils/scheduler.py", line 149, in is_scheduler_inactive
    if is_scheduler_disabled(verbose=verbose):
       ~~~~~~~~~~~~~~~~~~~~~^^^^^^^^^^^^^^^^^
  File "/Users/saimanikanta/Desktop/ezapp/ez/frappe-bench/apps/frappe/frappe/utils/scheduler.py", line 162, in is_scheduler_disabled
    frappe.db.get_single_value("System Settings", "enable_scheduler")
    ~~~~~~~~~~~~~~~~~~~~~~~~~~^^^^^^^^^^^^^^^^^^^^^^^^^^^^^^^^^^^^^^^
  File "/Users/saimanikanta/Desktop/ezapp/ez/frappe-bench/apps/frappe/frappe/database/database.py", line 869, in get_single_value
    ).run()
      ~~~^^
  File "/Users/saimanikanta/Desktop/ezapp/ez/frappe-bench/apps/frappe/frappe/query_builder/utils.py", line 84, in execute_query
    result = frappe.db.sql(query, params, *args, **kwargs)  # nosemgrep
  File "/Users/saimanikanta/Desktop/ezapp/ez/frappe-bench/apps/frappe/frappe/database/database.py", line 215, in sql
    self.connect()
    ~~~~~~~~~~~~^^
  File "/Users/saimanikanta/Desktop/ezapp/ez/frappe-bench/apps/frappe/frappe/database/database.py", line 120, in connect
    self._conn: MariadbConnection | PostgresConnection = self.get_connection()
                                                         ~~~~~~~~~~~~~~~~~~~^^
  File "/Users/saimanikanta/Desktop/ezapp/ez/frappe-bench/apps/frappe/frappe/database/mariadb/database.py", line 107, in get_connection
    conn = self._get_connection()
  File "/Users/saimanikanta/Desktop/ezapp/ez/frappe-bench/apps/frappe/frappe/database/mariadb/database.py", line 113, in _get_connection
    return self.create_connection()
           ~~~~~~~~~~~~~~~~~~~~~~^^
  File "/Users/saimanikanta/Desktop/ezapp/ez/frappe-bench/apps/frappe/frappe/database/mariadb/database.py", line 116, in create_connection
    return pymysql.connect(**self.get_connection_settings())
           ~~~~~~~~~~~~~~~^^^^^^^^^^^^^^^^^^^^^^^^^^^^^^^^^^
  File "/Users/saimanikanta/Desktop/ezapp/ez/frappe-bench/env/lib/python3.13/site-packages/pymysql/connections.py", line 361, in __init__
    self.connect()
    ~~~~~~~~~~~~^^
  File "/Users/saimanikanta/Desktop/ezapp/ez/frappe-bench/env/lib/python3.13/site-packages/pymysql/connections.py", line 669, in connect
    self._request_authentication()
    ~~~~~~~~~~~~~~~~~~~~~~~~~~~~^^
  File "/Users/saimanikanta/Desktop/ezapp/ez/frappe-bench/env/lib/python3.13/site-packages/pymysql/connections.py", line 957, in _request_authentication
    auth_packet = self._read_packet()
  File "/Users/saimanikanta/Desktop/ezapp/ez/frappe-bench/env/lib/python3.13/site-packages/pymysql/connections.py", line 775, in _read_packet
    packet.raise_for_error()
    ~~~~~~~~~~~~~~~~~~~~~~^^
  File "/Users/saimanikanta/Desktop/ezapp/ez/frappe-bench/env/lib/python3.13/site-packages/pymysql/protocol.py", line 219, in raise_for_error
    err.raise_mysql_exception(self._data)
    ~~~~~~~~~~~~~~~~~~~~~~~~~^^^^^^^^^^^^
  File "/Users/saimanikanta/Desktop/ezapp/ez/frappe-bench/env/lib/python3.13/site-packages/pymysql/err.py", line 150, in raise_mysql_exception
    raise errorclass(errno, errval)
pymysql.err.OperationalError: (1044, "Access denied for user '_7c5f4f77b0d74777'@'localhost' to database 'f77b0d74777_7c5f4'")
